Workbook

Sheet Multifamily
B2: MULTIFAMILY (STANDARD) - SUMMARY INCOME STATEMENT
B4: Units | D4: 300
B5: Period Ending | D5: 2019
B6: REVENUE
B7: Rental Revenue | C7: /Unit/Mo. | D7: Amount
B8: Market Rent | C8: =D8/$D$4/12 -> 2090.8169 | D8: =OpSt!W5 -> 7526941 | E8: Total market rent
B9: Loss-to-Lease | C9: =D9/$D$4/12 -> -28.745 | D9: =OpSt!W6 -> -103482 | E9: Difference between market rent and in-place rent
B10: Actual Vacancy & Credit Loss | C10: =D10/$D$4/12 -> -1560.879 | D10: =OpSt!W7 -> -5619164.5 | E10: Vacant space at market rent
B11: Concessions | C11: =D11/$D$4/12 -> -83.289994 | D11: =OpSt!W8 -> -299843.98 | E11: Concessed space (e.g. free rent) at in-place rent
B12: Total Rental Revenue | C12: =SUM(C8:C11) -> 417.90293 | D12: =SUM(D8:D11) -> 1504450.6 | E12: Actual rental Revenue in period
B14: Other Income
B15: RUBS | C15: =D15/$D$4/12 -> 14.169086 | D15: =OpSt!W12 -> 51008.71 | E15: Ratio Utility Billing; a method by which the landlord bills residents for the residents' pro rata share of utility costs
B16: Parking Income | C16: =D16/$D$4/12 -> 16.424708 | D16: =OpSt!W13 -> 59128.95 | E16: Net income derived from charging residents for parking
B17: Storage Income | C17: =D17/$D$4/12 -> 1.4020306 | D17: =OpSt!W14 -> 5047.31 | E17: Net income derived from renting on-site storage units
B18: Other Income | C18: =D18/$D$4/12 -> 45.432122 | D18: =OpSt!W15 -> 163555.64 | E18: Other income including pet rent, application fees, amenities fees, cable and internet income, etc.
B19: Total Other Income | C19: =SUM(C15:C18) -> 77.427947 | D19: =SUM(D15:D18) -> 278740.61 | E19: Actual other income
B21: Effective Gross Revenue
B22: Gross Revenue | C22: =D22/$D$4/12 -> 495.33088 | D22: =+D19+D12 -> 1783191.2 | E22: Sum of other income and rental revenue
B23: General Vacancy and Credit Loss | C23: =D23/$D$4/12 -> 0 | D23: 0 | E23: Additional vacancy taken on gross Revenue to account for unforeseen vacancy or credit loss; used in forecasted periods
B24: Total Effective Gross Revenue | C24: =SUM(C22:C23) -> 495.33088 | D24: =+D22+D23 -> 1783191.2 | E24: Gross revenue after adjusting for general vacancy and credit loss; commonly referred to as EGR
B25: OPERATING EXPENSES
B26: Operating Expenses | C26: /Unit/Yr.
B27: Repairs and Maintenance | C27: =D27/$D$4 -> 212.21687 | D27: =OpSt!W24 -> 63665.06 | E27: Expenses related to maintaining the general condition of the common areas
B28: Security | C28: =D28/$D$4 -> 6.8253333 | D28: =OpSt!W25 -> 2047.6 | E28: Expenses related to securing the premises
B29: Landscaping | C29: =D29/$D$4 -> 1.4557667 | D29: =OpSt!W26 -> 436.73 | E29: Expenses related to maintaining the landscaping in the common areas
B30: Administrative | C30: =D30/$D$4 -> 230.62193 | D30: =OpSt!W27 -> 69186.58 | E30: Expenses related to the administration of the property
B31: Property Management | C31: =D31/$D$4 -> 377.03333 | D31: =OpSt!W28 -> 113110 | E31: Fee paid to professional property management; generally a percentage of EGR
B32: Advertising/Marketing | C32: =D32/$D$4 -> 596.79393 | D32: =OpSt!W29 -> 179038.18 | E32: Expenses related to marketing and advertising the property; may include locator fees
B33: Payroll | C33: =D33/$D$4 -> 1729.1561 | D33: =OpSt!W30 -> 518746.83 | E33: Expenses related to salary and benefits for property management personnel
B34: Utilities | C34: =D34/$D$4 -> 682.67163 | D34: =OpSt!W31 -> 204801.49 | E34: Electricity, gas, water, sewer, internet, and other utilities; generally only related to the common areas
B35: Property Insurance | C35: =D35/$D$4 -> 39.869933 | D35: =OpSt!W32 -> 11960.98 | E35: Property and casualty insurance
B36: Real Estate Taxes | C36: =D36/$D$4 -> 85.340433 | D36: =OpSt!W33 -> 25602.13 | E36: Real estate taxes levied by the local government
B37: Total Operating Expenses | C37: =SUM(C27:C36) -> 3961.9853 | D37: =SUM(D27:D36) -> 1188595.6 | E37: Sum of operating expenses; commonly referred to as OpEx
B39: NET OPERATING INCOME | D39: =+D24-D37 -> 594595.59 | E39: Effective gross income minus total operating expenses; commonly referred to as NOI
B40: CAPITAL EXPENDITURES
B41: Capital Improvements | C41: =D41/$D$4 -> 0 | D41: =OpSt!W38 -> 0 | E41: Expenditures with a depreciable life greater than one year (e.g. roof repair, structural repairs, etc)
B42: Capital Reserve | C42: =D42/$D$4 -> 0 | D42: =OpSt!W39 -> 0 | E42: Amount set aside for future capital improvements and/or leasing costs
B43: Total Capital Expenditures | C43: =SUM(C41:C42) -> 0 | D43: =SUM(D41:D42) -> 0
B45: CASH FLOW FROM OPERATIONS | D45: =+D39-D43 -> 594595.59 | E45: Net operating income minus total capital expenditures; commonly referred to as CFO
B47: Debt Service | E47: Payment to lender(s); payment is principal + interest unless loan is interest-only; commonly referred to as DS
...

Sheet OpSt
A1: Jellystone Apartments | B1: Jellystone Apartments
A2: Statement (12 months) | B2: STATEMENT (12 MONTHS)
A3: Period = Dec 2018-Oct 2019 | B3: Period = Dec 2018 through Oct 2019; Book = Accrual
C4: 43435 | D4: 43466 | E4: 43497 | F4: 43525 | G4: 43556 | H4: 43586 | I4: 43617 | J4: 43647 | K4: 43678 | L4: 43709 | M4: 43739 | N4: Total | O4: T1 | P4: T3 | Q4: T6 | R4: Label | U4: Label | V4: Rental Revenue | W4: Amount | X4: T1 | Y4: T3 | Z4: T6 | AA4: Error Check
A5: 4100-0010 | B5: Gross Potential Mkt Rent | C5: 678055 | D5: 678055 | E5: 678055 | F5: 686597 | G5: 686597 | H5: 686597 | I5: 686597 | J5: 686597 | K5: 686597 | L5: 686597 | M5: 686597 | N5: 7526941 | O5: =IF($N$5="","",M5*12) -> 8239164 | P5: =IF($N$5="","",SUM(K5:M5)*4) -> 8239164 | Q5: =IF($N$5="","",SUM(H5:M5)*2) -> 8239164 | R5: RENT | U5: RENT | V5: Market Rent | W5: =SUMIF($R$5:$R$263,$U5,N$5:N$263) -> 7526941 | X5: =SUMIF($R$5:$R$263,$U5,O$5:O$263) -> 8239164 | Y5: =SUMIF($R$5:$R$263,$U5,P$5:P$263) -> 8239164 | Z5: =SUMIF($R$5:$R$263,$U5,Q$5:Q$263) -> 8239164
A6: 4100-0030 | B6: Loss to Lease | C6: -2590 | D6: -1158 | E6: -2041 | F6: -4581 | G6: -5800 | H6: -7372 | I6: -9334 | J6: -13830 | K6: -16809 | L6: -19517 | M6: -20450 | N6: -103482 | O6: =IF($N$5="","",M6*12) -> -245400 | P6: =IF($N$5="","",SUM(K6:M6)*4) -> -227104 | Q6: =IF($N$5="","",SUM(H6:M6)*2) -> -174624 | R6: L2L | U6: L2L | V6: Loss-to-Lease | W6: =SUMIF($R$5:$R$263,$U6,N$5:N$263) -> -103482 | X6: =SUMIF($R$5:$R$263,$U6,O$5:O$263) -> -245400 | Y6: =SUMIF($R$5:$R$263,$U6,P$5:P$263) -> -227104 | Z6: =SUMIF($R$5:$R$263,$U6,Q$5:Q$263) -> -174624
A7: 4100-0055 | B7: Actual Potential Rent | C7: 675465 | D7: 676897 | E7: 676014 | F7: 682016 | G7: 680797 | H7: 679225 | I7: 677263 | J7: 672767 | K7: 669788 | L7: 667080 | M7: 666147 | N7: 7423459 | O7: =IF($N$5="","",M7*12) -> 7993764 | P7: =IF($N$5="","",SUM(K7:M7)*4) -> 8012060 | Q7: =IF($N$5="","",SUM(H7:M7)*2) -> 8064540 | U7: ACTVAC | V7: Actual Vacancy & Credit Loss | W7: =SUMIF($R$5:$R$263,$U7,N$5:N$263) -> -5619164.5 | X7: =SUMIF($R$5:$R$263,$U7,O$5:O$263) -> -3051387.5 | Y7: =SUMIF($R$5:$R$263,$U7,P$5:P$263) -> -3719700.2 | Z7: =SUMIF($R$5:$R$263,$U7,Q$5:Q$263) -> -4847017.4
A8: 4100-0060 | B8: Vacancy Loss | C8: -670605 | D8: -657652.11 | E8: -640847.17 | F8: -612927.63 | G8: -575232.23 | H8: -540221.89 | I8: -491103.12 | J8: -425980.43 | K8: -363138.66 | L8: -296985.82 | M8: -246702.19 | N8: -5521396.2 | O8: =IF($N$5="","",M8*12) -> -2960426.3 | P8: =IF($N$5="","",SUM(K8:M8)*4) -> -3627306.7 | Q8: =IF($N$5="","",SUM(H8:M8)*2) -> -4728264.2 | R8: ACTVAC | U8: CONC | V8: Concessions | W8: =SUMIF($R$5:$R$263,$U8,N$5:N$263) -> -299843.98 | X8: =SUMIF($R$5:$R$263,$U8,O$5:O$263) -> -486204 | Y8: =SUMIF($R$5:$R$263,$U8,P$5:P$263) -> -490800.48 | Z8: =SUMIF($R$5:$R$263,$U8,Q$5:Q$263) -> -434467.14
B9: Non Rev Producing Units | C9: -4860 | D9: -8154.35 | E9: -1297.5 | F9: -8422.5 | G9: -9602.7 | H9: -10115.1 | I9: -10115.1 | J9: -7580.1 | K9: -7580.1 | L9: -7580.1 | M9: -7580.1 | N9: -82887.65 | O9: =IF($N$5="","",M9*12) -> -90961.2 | P9: =IF($N$5="","",SUM(K9:M9)*4) -> -90961.2 | Q9: =IF($N$5="","",SUM(H9:M9)*2) -> -101101.2 | R9: ACTVAC | V9: Total Rental Revenue | W9: =SUM(W5:W8) -> 1504450.6 | X9: =SUM(X5:X8) -> 4456172.5 | Y9: =SUM(Y5:Y8) -> 3801559.3 | Z9: =SUM(Z5:Z8) -> 2783055.4
A10: 4100-0100 | B10: Employee Units | C10: -1350 | D10: 0 | E10: -7125 | F10: 0 | G10: 0 | H10: 0 | I10: 0 | J10: 0 | K10: 0 | L10: 0 | M10: 0 | N10: -8475 | O10: =IF($N$5="","",M10*12) -> 0 | P10: =IF($N$5="","",SUM(K10:M10)*4) -> 0 | Q10: =IF($N$5="","",SUM(H10:M10)*2) -> 0 | R10: ACTVAC
A11: 4100-0150 | B11: Rental Concessions | C11: 0 | D11: -10222.5 | E11: -20272.5 | F11: -21453.75 | G11: -30661.66 | H11: -25113.66 | I11: -43684.02 | J11: -25735.77 | K11: -37623.5 | L11: -44559.62 | M11: -40517 | N11: -299843.98 | O11: =IF($N$5="","",M11*12) -> -486204 | P11: =IF($N$5="","",SUM(K11:M11)*4) -> -490800.48 | Q11: =IF($N$5="","",SUM(H11:M11)*2) -> -434467.14 | R11: CONC | V11: Other Income
A12: 4100-0240 | B12: Other Month Rent/Past Due | C12: 0 | D12: 51.61 | E12: 0 | F12: 2439.56 | G12: -70.72 | H12: 159.8 | I12: 0 | J12: -12.4 | K12: 0 | L12: 358.08 | M12: 0 | N12: 2925.93 | O12: =IF($N$5="","",M12*12) -> 0 | P12: =IF($N$5="","",SUM(K12:M12)*4) -> 1432.32 | Q12: =IF($N$5="","",SUM(H12:M12)*2) -> 1010.96 | R12: ACTVAC | U12: RUBS | V12: RUBS | W12: =SUMIF($R$5:$R$263,$U12,N$5:N$263) -> 51008.71 | X12: =SUMIF($R$5:$R$263,$U12,O$5:O$263) -> 167265.48 | Y12: =SUMIF($R$5:$R$263,$U12,P$5:P$263) -> 130625.68 | Z12: =SUMIF($R$5:$R$263,$U12,Q$5:Q$263) -> 95777.4
A13: 4100-0320 | B13: Bad Debt Expense | C13: 0 | D13: 0 | E13: 0 | F13: 0 | G13: 0 | H13: -6769.04 | I13: -1846.29 | J13: 0 | K13: 0 | L13: -716.16 | M13: 0 | N13: -9331.49 | O13: =IF($N$5="","",M13*12) -> 0 | P13: =IF($N$5="","",SUM(K13:M13)*4) -> -2864.64 | Q13: =IF($N$5="","",SUM(H13:M13)*2) -> -18662.98 | R13: ACTVAC | U13: PARK | V13: Parking Income | W13: =SUMIF($R$5:$R$263,$U13,N$5:N$263) -> 59128.95 | X13: =SUMIF($R$5:$R$263,$U13,O$5:O$263) -> 179659.44 | Y13: =SUMIF($R$5:$R$263,$U13,P$5:P$263) -> 152795.48 | Z13: =SUMIF($R$5:$R$263,$U13,Q$5:Q$263) -> 107948.34
A14: 4199-9999 | B14: Total Gross Potential Mkt Rent | C14: -1350 | D14: 919.65 | E14: 6471.83 | F14: 41651.68 | G14: 65229.69 | H14: 97165.11 | I14: 130514.47 | J14: 213458.3 | K14: 261445.74 | L14: 317596.38 | M14: 371347.71 | N14: 1504450.6 | O14: =IF($N$5="","",M14*12) -> 4456172.5 | P14: =IF($N$5="","",SUM(K14:M14)*4) -> 3801559.3 | Q14: =IF($N$5="","",SUM(H14:M14)*2) -> 2783055.4 | U14: STORAGE | V14: Storage Income | W14: =SUMIF($R$5:$R$263,$U14,N$5:N$263) -> 5047.31 | X14: =SUMIF($R$5:$R$263,$U14,O$5:O$263) -> 15772.08 | Y14: =SUMIF($R$5:$R$263,$U14,P$5:P$263) -> 13499.68 | Z14: =SUMIF($R$5:$R$263,$U14,Q$5:Q$263) -> 9430.66
O15: =IF($N$5="","",M15*12) -> 0 | P15: =IF($N$5="","",SUM(K15:M15)*4) -> 0 | Q15: =IF($N$5="","",SUM(H15:M15)*2) -> 0 | U15: OI | V15: Other Income | W15: =SUMIF($R$5:$R$263,$U15,N$5:N$263) -> 163555.64 | X15: =SUMIF($R$5:$R$263,$U15,O$5:O$263) -> 329736.48 | Y15: =SUMIF($R$5:$R$263,$U15,P$5:P$263) -> 281372.48 | Z15: =SUMIF($R$5:$R$263,$U15,Q$5:Q$263) -> 230061.32
A16: 4200-0000 | B16: Other Income | O16: =IF($N$5="","",M16*12) -> 0 | P16: =IF($N$5="","",SUM(K16:M16)*4) -> 0 | Q16: =IF($N$5="","",SUM(H16:M16)*2) -> 0 | V16: Total Other Income | W16: =SUM(W12:W15) -> 278740.61 | X16: =SUM(X12:X15) -> 692433.48 | Y16: =SUM(Y12:Y15) -> 578293.32 | Z16: =SUM(Z12:Z15) -> 443217.72
O17: =IF($N$5="","",M17*12) -> 0 | P17: =IF($N$5="","",SUM(K17:M17)*4) -> 0 | Q17: =IF($N$5="","",SUM(H17:M17)*2) -> 0
A18: 4200-0001 | B18: Other Income | O18: =IF($N$5="","",M18*12) -> 0 | P18: =IF($N$5="","",SUM(K18:M18)*4) -> 0 | Q18: =IF($N$5="","",SUM(H18:M18)*2) -> 0 | V18: Effective Gross Revenue
A19: 4200-0050 | B19: Resident Fees | C19: 0 | D19: 3600 | E19: 10000 | F19: 10100 | G19: 6040 | H19: 6000 | I19: 5300 | J19: 5100 | K19: 8200 | L19: 3200 | M19: 3000 | N19: 60540 | O19: =IF($N$5="","",M19*12) -> 36000 | P19: =IF($N$5="","",SUM(K19:M19)*4) -> 57600 | Q19: =IF($N$5="","",SUM(H19:M19)*2) -> 61600 | R19: OI | V19: Gross Revenue | W19: =+W16+W9 -> 1783191.2 | X19: =+X16+X9 -> 5148606 | Y19: =+Y16+Y9 -> 4379852.6 | Z19: =+Z16+Z9 -> 3226273.1
A20: 4200-0060 | B20: Application Fees | C20: 120 | D20: 2185 | E20: 2370 | F20: 3835 | G20: 2720 | H20: 3900 | I20: 4260 | J20: 4080 | K20: 4275 | L20: 3405 | M20: 3240 | N20: 34390 | O20: =IF($N$5="","",M20*12) -> 38880 | P20: =IF($N$5="","",SUM(K20:M20)*4) -> 43680 | Q20: =IF($N$5="","",SUM(H20:M20)*2) -> 46320 | R20: OI | V20: General Vacancy and Credit Loss | W20: 0 | X20: 0 | Y20: 0 | Z20: 0
A21: 4200-0110 | B21: Garage Income | C21: 0 | D21: 304.84 | E21: 637.49 | F21: 1021.48 | G21: 3190.97 | H21: 3596.13 | I21: 4731.93 | J21: 7447.24 | K21: 10364.51 | L21: 12862.74 | M21: 14971.62 | N21: 59128.95 | O21: =IF($N$5="","",M21*12) -> 179659.44 | P21: =IF($N$5="","",SUM(K21:M21)*4) -> 152795.48 | Q21: =IF($N$5="","",SUM(H21:M21)*2) -> 107948.34 | R21: PARK | V21: Total Effective Gross Revenue | W21: =+W19+W20 -> 1783191.2 | X21: =+X19+X20 -> 5148606 | Y21: =+Y19+Y20 -> 4379852.6 | Z21: =+Z19+Z20 -> 3226273.1 | AA21: =N52 -> 1783191.2 | AB21: =O52 -> 5148606 | AC21: =P52 -> 4379852.6 | AD21: =Q52 -> 3226273.1
A22: 4200-0160 | B22: Storage Income | C22: 0 | D22: 0 | E22: 32.14 | F22: 87.1 | G22: 224.84 | H22: 317.02 | I22: 300 | J22: 723.39 | K22: 1012.9 | L22: 1059.78 | M22: 1314.34 | N22: 5071.51 | O22: =IF($N$5="","",M22*12) -> 15772.08 | P22: =IF($N$5="","",SUM(K22:M22)*4) -> 13548.08 | Q22: =IF($N$5="","",SUM(H22:M22)*2) -> 9454.86 | R22: STORAGE | V22: OPERATING EXPENSES
A23: 4200-0170 | B23: Storage Concession | C23: 0 | D23: 0 | E23: 0 | F23: -12.1 | G23: 0 | H23: 0 | I23: 0 | J23: 0 | K23: 0 | L23: -12.1 | M23: 0 | N23: -24.2 | O23: =IF($N$5="","",M23*12) -> 0 | P23: =IF($N$5="","",SUM(K23:M23)*4) -> -48.4 | Q23: =IF($N$5="","",SUM(H23:M23)*2) -> -24.2 | R23: STORAGE | V23: Operating Expenses
A24: 4200-0180 | B24: Damage Fees | C24: 0 | D24: 0 | E24: 150 | F24: 0 | G24: 0 | H24: 540 | I24: 0 | J24: 110 | K24: 839 | L24: -147 | M24: 3767.77 | N24: 5259.77 | O24: =IF($N$5="","",M24*12) -> 45213.24 | P24: =IF($N$5="","",SUM(K24:M24)*4) -> 17839.08 | Q24: =IF($N$5="","",SUM(H24:M24)*2) -> 10219.54 | R24: OI | U24: RM | V24: Repairs and Maintenance | W24: =SUMIF($R$5:$R$263,$U24,N$5:N$263) -> 63665.06 | X24: =SUMIF($R$5:$R$263,$U24,O$5:O$263) -> 137846.4 | Y24: =SUMIF($R$5:$R$263,$U24,P$5:P$263) -> 149230.92 | Z24: =SUMIF($R$5:$R$263,$U24,Q$5:Q$263) -> 112242.98
A25: 4200-0230 | B25: Termination Fees | C25: 0 | D25: 0 | E25: 0 | F25: 0 | G25: 0 | H25: 0 | I25: 0 | J25: 0 | K25: 3700 | L25: -1430 | M25: 10243.09 | N25: 12513.09 | O25: =IF($N$5="","",M25*12) -> 122917.08 | P25: =IF($N$5="","",SUM(K25:M25)*4) -> 50052.36 | Q25: =IF($N$5="","",SUM(H25:M25)*2) -> 25026.18 | R25: OI | U25: SEC | V25: Security | W25: =SUMIF($R$5:$R$263,$U25,N$5:N$263) -> 2047.6 | X25: =SUMIF($R$5:$R$263,$U25,O$5:O$263) -> 0 | Y25: =SUMIF($R$5:$R$263,$U25,P$5:P$263) -> 2094 | Z25: =SUMIF($R$5:$R$263,$U25,Q$5:Q$263) -> 4005.2
A26: 4200-0270 | B26: MTM Premium | C26: 0 | D26: 0 | E26: 0 | F26: 0 | G26: 0 | H26: 0 | I26: 0 | J26: 0 | K26: 0 | L26: 760 | M26: 241.94 | N26: 1001.94 | O26: =IF($N$5="","",M26*12) -> 2903.28 | P26: =IF($N$5="","",SUM(K26:M26)*4) -> 4007.76 | Q26: =IF($N$5="","",SUM(H26:M26)*2) -> 2003.88 | R26: OI | U26: LAND | V26: Landscaping | W26: =SUMIF($R$5:$R$263,$U26,N$5:N$263) -> 436.73 | X26: =SUMIF($R$5:$R$263,$U26,O$5:O$263) -> 5240.76 | Y26: =SUMIF($R$5:$R$263,$U26,P$5:P$263) -> 1746.92 | Z26: =SUMIF($R$5:$R$263,$U26,Q$5:Q$263) -> 873.46
A27: 4200-0280 | B27: Short Term Lease Premium | C27: 0 | D27: 0 | E27: 0 | F27: 0 | G27: 0 | H27: 0 | I27: 0 | J27: 0 | K27: 0 | L27: 0 | M27: 541.94 | N27: 541.94 | O27: =IF($N$5="","",M27*12) -> 6503.28 | P27: =IF($N$5="","",SUM(K27:M27)*4) -> 2167.76 | Q27: =IF($N$5="","",SUM(H27:M27)*2) -> 1083.88 | R27: OI | U27: ADMIN | V27: Administrative | W27: =SUMIF($R$5:$R$263,$U27,N$5:N$263) -> 69186.58 | X27: =SUMIF($R$5:$R$263,$U27,O$5:O$263) -> 72994.68 | Y27: =SUMIF($R$5:$R$263,$U27,P$5:P$263) -> 79125.2 | Z27: =SUMIF($R$5:$R$263,$U27,Q$5:Q$263) -> 79953.58
A28: 4200-0300 | B28: Transfer Fees | C28: 0 | D28: 0 | E28: 0 | F28: 0 | G28: 0 | H28: 0 | I28: 0 | J28: 0 | K28: 0 | L28: 500 | M28: 0 | N28: 500 | O28: =IF($N$5="","",M28*12) -> 0 | P28: =IF($N$5="","",SUM(K28:M28)*4) -> 2000 | Q28: =IF($N$5="","",SUM(H28:M28)*2) -> 1000 | R28: OI | U28: PM | V28: Property Management | W28: =SUMIF($R$5:$R$263,$U28,N$5:N$263) -> 113110 | X28: =SUMIF($R$5:$R$263,$U28,O$5:O$263) -> 147612 | Y28: =SUMIF($R$5:$R$263,$U28,P$5:P$263) -> 132440 | Z28: =SUMIF($R$5:$R$263,$U28,Q$5:Q$263) -> 126220
A29: 4200-0340 | B29: Pet Rent | C29: 0 | D29: 635.48 | E29: 1025.54 | F29: 1126.5 | G29: 1911.46 | H29: 2029.36 | I29: 3394.5 | J29: 4597.42 | K29: 4795.16 | L29: 4860.46 | M29: 4889.7 | N29: 29265.58 | O29: =IF($N$5="","",M29*12) -> 58676.4 | P29: =IF($N$5="","",SUM(K29:M29)*4) -> 58181.28 | Q29: =IF($N$5="","",SUM(H29:M29)*2) -> 49133.2 | R29: OI | U29: MARK | V29: Advertising/Marketing | W29: =SUMIF($R$5:$R$263,$U29,N$5:N$263) -> 179038.18 | X29: =SUMIF($R$5:$R$263,$U29,O$5:O$263) -> 181175.28 | Y29: =SUMIF($R$5:$R$263,$U29,P$5:P$263) -> 194429.72 | Z29: =SUMIF($R$5:$R$263,$U29,Q$5:Q$263) -> 238100.82
A30: 4200-0360 | B30: Amenity Fees | C30: 150 | D30: 20 | E30: 670 | F30: 700 | G30: 706 | H30: -158.33 | I30: 1098 | J30: 662 | K30: -150 | L30: 1030.6 | M30: 1534.9 | N30: 6263.17 | O30: =IF($N$5="","",M30*12) -> 18418.8 | P30: =IF($N$5="","",SUM(K30:M30)*4) -> 9662 | Q30: =IF($N$5="","",SUM(H30:M30)*2) -> 8034.34 | R30: OI | U30: P | V30: Payroll | W30: =SUMIF($R$5:$R$263,$U30,N$5:N$263) -> 518746.83 | X30: =SUMIF($R$5:$R$263,$U30,O$5:O$263) -> 521369.4 | Y30: =SUMIF($R$5:$R$263,$U30,P$5:P$263) -> 739625.16 | Z30: =SUMIF($R$5:$R$263,$U30,Q$5:Q$263) -> 691009.9
A31: 4200-0370 | B31: Late Fees | C31: 0 | D31: 0 | E31: 0 | F31: 0 | G31: 0 | H31: 0 | I31: 0 | J31: 0 | K31: 503.8 | L31: 0 | M31: -503.8 | N31: 0 | O31: =IF($N$5="","",M31*12) -> -6045.6 | P31: =IF($N$5="","",SUM(K31:M31)*4) -> 0 | Q31: =IF($N$5="","",SUM(H31:M31)*2) -> 0 | R31: OI | U31: U | V31: Utilities | W31: =SUMIF($R$5:$R$263,$U31,N$5:N$263) -> 204801.49 | X31: =SUMIF($R$5:$R$263,$U31,O$5:O$263) -> 410916.36 | Y31: =SUMIF($R$5:$R$263,$U31,P$5:P$263) -> 270746.96 | Z31: =SUMIF($R$5:$R$263,$U31,Q$5:Q$263) -> 334543.72
A32: 4200-0380 | B32: Administrative Fees | C32: 200 | D32: 0 | E32: 0 | F32: 0 | G32: 0 | H32: 0 | I32: 0 | J32: 0 | K32: 0 | L32: 0 | M32: 0 | N32: 200 | O32: =IF($N$5="","",M32*12) -> 0 | P32: =IF($N$5="","",SUM(K32:M32)*4) -> 0 | Q32: =IF($N$5="","",SUM(H32:M32)*2) -> 0 | R32: OI | U32: I | V32: Property Insurance | W32: =SUMIF($R$5:$R$263,$U32,N$5:N$263) -> 11960.98 | X32: =SUMIF($R$5:$R$263,$U32,O$5:O$263) -> 0 | Y32: =SUMIF($R$5:$R$263,$U32,P$5:P$263) -> 11739.44 | Z32: =SUMIF($R$5:$R$263,$U32,Q$5:Q$263) -> 14832
A33: 4200-0400 | B33: Forfeited Deposit | C33: 0 | D33: 0 | E33: 0 | F33: 0 | G33: 0 | H33: 2000 | I33: 0 | J33: 0 | K33: 0 | L33: 0 | M33: 0 | N33: 2000 | O33: =IF($N$5="","",M33*12) -> 0 | P33: =IF($N$5="","",SUM(K33:M33)*4) -> 0 | Q33: =IF($N$5="","",SUM(H33:M33)*2) -> 4000 | R33: OI | U33: RET | V33: Real Estate Taxes | W33: =SUMIF($R$5:$R$263,$U33,N$5:N$263) -> 25602.13 | X33: =SUMIF($R$5:$R$263,$U33,O$5:O$263) -> 0 | Y33: =SUMIF($R$5:$R$263,$U33,P$5:P$263) -> 40050.96 | Z33: =SUMIF($R$5:$R$263,$U33,Q$5:Q$263) -> 39681.92
A34: 4299-9999 | B34: Total Other Income | C34: 470 | D34: 6745.32 | E34: 14885.17 | F34: 16857.98 | G34: 14793.27 | H34: 18224.18 | I34: 19084.43 | J34: 22720.05 | K34: 33540.37 | L34: 26089.48 | M34: 43241.5 | N34: 216651.75 | O34: =IF($N$5="","",M34*12) -> 518898 | P34: =IF($N$5="","",SUM(K34:M34)*4) -> 411485.4 | Q34: =IF($N$5="","",SUM(H34:M34)*2) -> 325800.02 | V34: Total Operating Expenses | W34: =SUM(W24:W33) -> 1188595.6 | X34: =SUM(X24:X33) -> 1477154.9 | Y34: =SUM(Y24:Y33) -> 1621229.3 | Z34: =SUM(Z24:Z33) -> 1641463.6 | AA34: =N261 -> 1188595.6 | AB34: =O261 -> 1477154.9 | AC34: =P261 -> 1621229.3 | AD34: =Q261 -> 1641463.6
O35: =IF($N$5="","",M35*12) -> 0 | P35: =IF($N$5="","",SUM(K35:M35)*4) -> 0 | Q35: =IF($N$5="","",SUM(H35:M35)*2) -> 0
A36: 4300-0000 | B36: Miscellaneous Income | O36: =IF($N$5="","",M36*12) -> 0 | P36: =IF($N$5="","",SUM(K36:M36)*4) -> 0 | Q36: =IF($N$5="","",SUM(H36:M36)*2) -> 0 | V36: NET OPERATING INCOME | W36: =+W21-W34 -> 594595.59 | X36: =+X21-X34 -> 3671451.1 | Y36: =+Y21-Y34 -> 2758623.4 | Z36: =+Z21-Z34 -> 1584809.6 | AA36: =N263 -> 594595.59 | AB36: =O263 -> 3671451.1 | AC36: =P263 -> 2758623.4 | AD36: =Q263 -> 1584809.6
A37: 4300-0010 | B37: Miscellaneous Income | C37: 0 | D37: 0 | E37: 0 | F37: 0 | G37: 260 | H37: 201.07 | I37: 146.04 | J37: 244.69 | K37: 400 | L37: 20 | M37: 0 | N37: 1271.8 | O37: =IF($N$5="","",M37*12) -> 0 | P37: =IF($N$5="","",SUM(K37:M37)*4) -> 1680 | Q37: =IF($N$5="","",SUM(H37:M37)*2) -> 2023.6
A38: 4300-0030 | B38: Clubhouse Income | C38: 0 | D38: 0 | E38: 0 | F38: 0 | G38: 0 | H38: 0 | I38: 0 | J38: 1200 | K38: 125 | L38: 0 | M38: 0 | N38: 1325 | O38: =IF($N$5="","",M38*12) -> 0 | P38: =IF($N$5="","",SUM(K38:M38)*4) -> 500 | Q38: =IF($N$5="","",SUM(H38:M38)*2) -> 2650
A39: 4300-0120 | B39: Cable Income | C39: 0 | D39: 0 | E39: 0 | F39: 0 | G39: 0 | H39: -17.21 | I39: 0 | J39: 0 | K39: 290.73 | L39: 0 | M39: 625 | N39: 898.52 | O39: =IF($N$5="","",M39*12) -> 7500 | P39: =IF($N$5="","",SUM(K39:M39)*4) -> 3662.92 | Q39: =IF($N$5="","",SUM(H39:M39)*2) -> 1797.04
A40: 4300-0130 | B40: Collection Income | C40: 0 | D40: 0 | E40: 0 | F40: 0 | G40: 0 | H40: 0 | I40: 0 | J40: 0 | K40: 2092.42 | L40: 5594.91 | M40: -102.5 | N40: 7584.83 | O40: =IF($N$5="","",M40*12) -> -1230 | P40: =IF($N$5="","",SUM(K40:M40)*4) -> 30339.32 | Q40: =IF($N$5="","",SUM(H40:M40)*2) -> 15169.66
...
