Workbook

Sheet Office
B2: OFFICE - SUMMARY INCOME STATEMENT
B4: Net Rentable Area | D4: 200000
B5: Period Ending | D5: 2019
B6: REVENUE
B7: Rental Revenue | C7: PSF | D7: Amount
B8: Potential Base Rent | C8: =+D8/$D$4 -> 12.53235 | D8: ='Office Detailed OpSt'!H4 -> 2506470 | E8: Sum of all contract rent plus vacant space at market rent; concessed space at contract rate
B9: Actual Vacancy | C9: =+D9/$D$4 -> 0 | D9: ='Office Detailed OpSt'!H5 -> 0 | E9: Vacant space at market rent
B10: Actual Credit Loss | C10: =+D10/$D$4 -> 0 | D10: ='Office Detailed OpSt'!H6 -> 0 | E10: Loss due to tenants' nonpayment of rental obligations
B11: Concessions | C11: =+D11/$D$4 -> 0 | D11: ='Office Detailed OpSt'!H7 -> 0 | E11: Concessed space (e.g. free rent) at contract rate
B12: Total Rental Revenue | C12: =+D12/$D$4 -> 12.53235 | D12: =SUM(D8:D11) -> 2506470 | E12: Actual rental Revenue in period
B14: Other Income
B15: CAM Reimbursement | C15: =+D15/$D$4 -> 1.933925 | D15: ='Office Detailed OpSt'!H11 -> 386785 | E15: Actual tenant reimbursement of common area maintenance (security, repairs and maintenance, landscaping, etc)
B16: Utility Reimbursement | C16: =+D16/$D$4 -> 0.301915 | D16: ='Office Detailed OpSt'!H12 -> 60383 | E16: Actual tenant reimbursement of utility expenses
B17: Real Estate Tax Reimbursement | C17: =+D17/$D$4 -> 0 | D17: ='Office Detailed OpSt'!H13 -> 0 | E17: Actual tenant reimbursement of real estate taxes
B18: Parking Income | C18: =+D18/$D$4 -> 0.096 | D18: ='Office Detailed OpSt'!H14 -> 19200 | E18: Actual income from parking
B19: Other Income | C19: =+D19/$D$4 -> 0.047465 | D19: ='Office Detailed OpSt'!H15 -> 9493 | E19: Actual other income; such as telecom income, amenity fees, conference room rental, fitness center, misc income, etc
B20: Total Other Income | C20: =+D20/$D$4 -> 2.379305 | D20: =SUM(D15:D19) -> 475861 | E20: Actual other Revenue
B22: Effective Gross Revenue
B23: Gross Revenue | C23: =+D23/$D$4 -> 14.911655 | D23: =+D20+D12 -> 2982331 | E23: Sum of other income and rental revenue
B24: General Vacancy and Credit Loss | C24: =+D24/$D$4 -> 0 | D24: 0 | E24: Additional vacancy taken on gross Revenue to account for unforeseen vacancy or credit loss; used in forecasted periods
B25: Total Effective Gross Revenue | C25: =+D25/$D$4 -> 14.911655 | D25: =+D23+D24 -> 2982331 | E25: Gross revenue after adjusting for general vacancy and credit loss; commonly referred to as EGR
B26: OPERATING EXPENSES
B27: Reimbursable Operating Expenses | E27: Operating expenses incurred by landlord that tenants have agreed to reimburse
B28: Variable Operating Expenses | E28: Expenses that fluctuate based on occupancy
B29: Cleaning | C29: =+D29/$D$4 -> 0.586825 | D29: ='Office Detailed OpSt'!H25 -> 117365 | E29: Expenses related to cleaning the common areas
B30: Repairs and Maintenance | C30: =+D30/$D$4 -> 1.311595 | D30: ='Office Detailed OpSt'!H26 -> 262319 | E30: Expenses related to maintaining the general condition of the common areas
B31: Security | C31: =+D31/$D$4 -> 0.96415 | D31: ='Office Detailed OpSt'!H27 -> 192830 | E31: Expenses related to securing the premises
B32: Landscaping | C32: =+D32/$D$4 -> 0.16409 | D32: ='Office Detailed OpSt'!H28 -> 32818 | E32: Expenses related to maintaining the landscaping in the common areas
B33: Utilities | C33: =+D33/$D$4 -> 0.92587 | D33: ='Office Detailed OpSt'!H29 -> 185174 | E33: Electricity, gas, water, sewer, internet, and other utilities related to the common areas
B34: Payroll | C34: =+D34/$D$4 -> 0.932475 | D34: ='Office Detailed OpSt'!H30 -> 186495
B35: Property Management | C35: =+D35/$D$4 -> 0 | D35: ='Office Detailed OpSt'!H31 -> 0 | E35: Fee paid to professional property management
B36: Marketing | C36: =+D36/$D$4 -> 0 | D36: ='Office Detailed OpSt'!H32 -> 0 | E36: Costs related to marketing the property; does NOT include leasing commissions
B37: Other Variable Expenses | C37: =+D37/$D$4 -> 1.426885 | D37: ='Office Detailed OpSt'!H33 -> 285377 | E37: Other variable expenses that are reimbursable
B38: Total Variable Expenses | C38: =+D38/$D$4 -> 6.31189 | D38: =SUM(D29:D37) -> 1262378
B39: Fixed Expenses | E39: Expense that are fixed regardless of occupancy
B40: Real Estate Taxes | C40: =+D40/$D$4 -> 6.245525 | D40: ='Office Detailed OpSt'!H36 -> 1249105 | E40: Real estate taxes levied by the local government
B41: Insurance | C41: =+D41/$D$4 -> 0.03832 | D41: ='Office Detailed OpSt'!H37 -> 7664 | E41: Property and casualty insurance
B42: Total Fixed Operating Expenses | C42: =+D42/$D$4 -> 6.283845 | D42: =SUM(D40:D41) -> 1256769
B44: Total Reimbursable OpEx | C44: =+D44/$D$4 -> 12.595735 | D44: =+D42+D38 -> 2519147 | E44: Total operating expenses that are reimbursable
B46: Non-Reimbursable Operating Expenses | E46: Operating expenses incurred by landlord that tenants are not obligated to reimburse
...

Sheet Office Detailed OpSt
A1: Office Park
A2: YTD Operating Statement
C3: EOY 2019 | D3: Label | F3: Label | G3: Rental Revenue | H3: Amount | I3: Error Check
A4: Income | F4: RENT | G4: Potential Base Rent | H4: =SUMIF($D$4:$D$90,$F4,$C$4:$C$90) -> 2506470
A5: Rental Income | F5: VAC | G5: Actual Vacancy | H5: =SUMIF($D$4:$D$90,$F5,$C$4:$C$90) -> 0
A6: Base Rent | C6: 2325327 | D6: RENT | F6: CREDIT | G6: Actual Credit Loss | H6: =SUMIF($D$4:$D$90,$F6,$C$4:$C$90) -> 0
A7: Escalations | C7: 181142.97 | D7: RENT | F7: CONC | G7: Concessions | H7: =SUMIF($D$4:$D$90,$F7,$C$4:$C$90) -> 0
A8: Free Rent | C8: 0 | G8: Total Rental Revenue | H8: =SUM(H4:H7) -> 2506470
A9: Total Rental Income | C9: 2506470
A10: CAM Expense Recoveries | G10: Other Income
A11: CAM Expense Recovery | C11: 386785 | F11: CAM | G11: CAM Reimbursement | H11: =SUMIF($D$4:$D$90,$F11,$C$4:$C$90) -> 386785
A12: Total CAM Expense Recoveries | C12: 386785 | D12: CAM | F12: UR | G12: Utility Reimbursement | H12: =SUMIF($D$4:$D$90,$F12,$C$4:$C$90) -> 60383
A13: Utility Recoveries | F13: RETR | G13: Real Estate Tax Reimbursement | H13: =SUMIF($D$4:$D$90,$F13,$C$4:$C$90) -> 0
A14: Utility Recovery | C14: 60383 | F14: PARK | G14: Parking Income | H14: =SUMIF($D$4:$D$90,$F14,$C$4:$C$90) -> 19200
A15: Total Utility Recoveries | C15: 60383 | D15: UR | F15: OI | G15: Other Income | H15: =SUMIF($D$4:$D$90,$F15,$C$4:$C$90) -> 9493
A16: Other Income-Building Related | G16: Total Other Income | H16: =SUM(H11:H15) -> 475861
A17: Parking Rent | C17: 19200 | D17: PARK
A18: Late Fees | C18: 1738 | D18: OI | G18: Effective Gross Revenue
A19: Other Reimbursements | C19: 3625 | D19: OI | G19: Gross Revenue | H19: =+H16+H8 -> 2982331
A20: Tenant Work Orders | C20: 405 | D20: OI | G20: General Vacancy and Credit Loss | H20: 0
A21: Other Income | C21: 505 | D21: OI | G21: Total Effective Gross Revenue | H21: =+H19+H20 -> 2982331 | I21: =C25 -> 2982331
A22: Telecom/Antenna | C22: 1350 | D22: OI | G22: OPERATING EXPENSES
A23: Building Amenity Income | C23: 1870 | D23: OI | G23: Reimbursable Operating Expenses
A24: Total Other Income | C24: 28693 | G24: Variable Operating Expenses
A25: Total Income | C25: 2982331 | F25: CLEAN | G25: Cleaning | H25: =SUMIF($D$4:$D$90,$F25,$C$4:$C$90) -> 117365
A26: Operating Expenses | F26: RM | G26: Repairs and Maintenance | H26: =SUMIF($D$4:$D$90,$F26,$C$4:$C$90) -> 262319
A27: Recoverable Expenses | F27: SEC | G27: Security | H27: =SUMIF($D$4:$D$90,$F27,$C$4:$C$90) -> 192830
A28: Utilities | F28: LAND | G28: Landscaping | H28: =SUMIF($D$4:$D$90,$F28,$C$4:$C$90) -> 32818
A29: Utilities-Water/Sewer | C29: 23491 | F29: U | G29: Utilities | H29: =SUMIF($D$4:$D$90,$F29,$C$4:$C$90) -> 185174
A30: Utilities-Electric | C30: 161683 | F30: PR | G30: Payroll | H30: =SUMIF($D$4:$D$90,$F30,$C$4:$C$90) -> 186495
A31: Tenant Reimb-Sub-Meter | C31: 0 | F31: PM | G31: Property Management | H31: =SUMIF($D$4:$D$90,$F31,$C$4:$C$90) -> 0
A32: Total Utilities | C32: 185174 | D32: U | F32: MARK | G32: Marketing | H32: =SUMIF($D$4:$D$90,$F32,$C$4:$C$90) -> 0
A33: Repairs & Maintenance | F33: OVE | G33: Other Variable Expenses | H33: =SUMIF($D$4:$D$90,$F33,$C$4:$C$90) -> 285377
A34: Payroll & Related | C34: 186495 | D34: PR | G34: Total Variable Expenses | H34: =SUM(H25:H33) -> 1262378
A35: HVAC | C35: 5579 | D35: RM | G35: Fixed Expenses
A36: Elevator | C36: 14673 | D36: RM | F36: RET | G36: Real Estate Taxes | H36: =SUMIF($D$4:$D$90,$F36,$C$4:$C$90) -> 1249105
A37: Janitorial | C37: 117365 | D37: CLEAN | F37: I | G37: Insurance | H37: =SUMIF($D$4:$D$90,$F37,$C$4:$C$90) -> 7664
A38: Grounds | C38: 32818 | D38: LAND | G38: Total Fixed Operating Expenses | H38: =SUM(H36:H37) -> 1256769
A39: Garage/Parking | C39: 11898 | D39: RM
A40: Fire/Life Safety | C40: 6076 | D40: SEC | G40: Total Reimbursable OpEx | H40: =+H38+H34 -> 2519147
...
