Workbook
Name GLA: Summary!$N$4

Sheet Summary
B2: INVESTMENT SUMMARY | N2: SINGLE-TENANT ACQUISITION MODEL
B3: LOCATION | I3: Physical Description
B4: Property Name | G4: Bronze Gym 10000 Fitness | I4: Gross Leasable Area (GLA) | N4: 41376
B5: Address | G5: 10000 Fitness | I5: Buildings | K5: 1 | L5: Floors | N5: 2
B6: City | G6: Everytown | I6: Year Built | K6: 2008 | L6: Year Renovated | N6: NA
B7: State/Province | D7: NA | E7: Zip Code | G7: 0 | I7: Parking Stalls | K7: 180 | L7: Parking Ratio | N7: =K7/(N4/1000) -> 4.350348
B8: Country | G8: USA | I8: Lot Size | N8: =2*43560 -> 87120
B9: INVESTMENT ASSUMPTIONS | I9: TENANT DESCRIPTION
B10: Analysis Start Date | G10: 43525 | I10: Tenant Name | N10: Bronze Gym Corporation
B11: Analysis Period | G11: 10 | I11: Lease Length (Yrs) | K11: 15 | L11: Years Remaining | N11: 14
B12: Reversion Year Ending | G12: 11 | I12: Current Rent/SF | K12: =Acquisition!H6 -> 8.87471 | L12: Reversion Rent/SF | N12: =Reversion!F6/GLA -> 10.818228
I13: Ann. Revenue ($M) | K13: 500 | L13: Credit Rating | N13: BBB
I14: Year 1 Default Prob | K14: 0 | L14: Reversion Default Prob | N14: 0.05
B15: VALUATION SUMMARY | F15: Acquisition | G15: Reversion | I15: PROPERTY-LEVEL RISK AND RETURN METRICS
B16: Total Rental Revenue | F16: =Acquisition!I8 -> 367200 | G16: =Reversion!I8 -> 556058.84 | I16: UNLEVERED | L16: LEVERED
B17: Total Other Income | F17: =Acquisition!I14 -> 355345 | G17: =Reversion!I14 -> 433163.57 | I17: IRR | K17: ='Property Returns'!F26 -> 0.070179858 | L17: IRR | N17: ='Property Returns'!F48 -> 0.11151217
B18: Gross Revenue | F18: =SUM(F16:F17) -> 722545 | G18: =SUM(G16:G17) -> 989222.41 | I18: Equity Multiple | K18: ='Property Returns'!F27 -> 1.7229052 | L18: Equity Multiple | N18: ='Property Returns'!F49 -> 2.2839728
B19: General Vacancy & Credit Loss | F19: =Acquisition!I18 -> 0 | G19: =Reversion!I18 -> -98922.241 | I19: Avg. Free and Clear | K19: =AVERAGE('Property Returns'!G17:P17) -> 0.067989725 | L19: Avg.Cash-on-Cash | N19: =AVERAGE('Property Returns'!G40:P40) -> 0.088723749
B20: Total Effective Gross Revenue | F20: =SUM(F18:F19) -> 722545 | G20: =SUM(G18:G19) -> 890300.17 | I20: Avg. Rate of Return | K20: ='Property Returns'!F28/Summary!$G$11/SUM('Property Returns'!F9:P9) -> 0.072290518 | L20: Avg. Rate of Return | N20: ='Property Returns'!$F$50/Summary!$G$11/SUM('Property Returns'!F34:P34) -> 0.12839728
B21: Total Variable Expenses | F21: =Acquisition!I32 -> 288859 | G21: =Reversion!I32 -> 352117.51 | I21: DEBT METRICS
B22: Total Fixed Expenses | F22: =Acquisition!I36 -> 66486 | G22: =Reversion!I36 -> 81046.063 | I22: Min. DSCR | K22: =MIN('Perm. Debt'!H10:Q10) -> 1.5114428 | L22: Min. Debt Yield | N22: =MIN('Perm. Debt'!H11:Q11) -> 0.071793535
B23: Total Operating Expenses | F23: =SUM(F21:F22) -> 355345 | G23: =SUM(G21:G22) -> 433163.57 | I23: Avg. DSCR | K23: =AVERAGE('Perm. Debt'!H10:Q10) -> 1.6945011 | L23: Avg. Debt Yield | N23: =AVERAGE('Perm. Debt'!H11:Q11) -> 0.097613819
B24: Net Operating Income | F24: =F20-F23 -> 367200 | G24: =G20-G23 -> 457136.6
B25: Cap Rate | F25: =Acquisition!I42 -> 0.067007299 | G25: =Reversion!I42 -> 0.072007299 | I25: PARTNERSHIP-LEVEL RETURN METRICS
B26: Direct Cap Value | F26: =F24/F25 -> 5480000 | G26: =G24/G25 -> 6348475.8 | I26: GENERAL PARTNER | L26: LIMITED PARTNER
B27: Adjustment | F27: 0 | G27: =Reversion!I46 -> -413760 | I27: IRR | K27: ='Partnership Returns'!F25 -> 0.14330673 | L27: IRR | N27: ='Partnership Returns'!F18 -> 0.10733889
B28: Property Value | F28: =SUM(F26:F27) -> 5480000 | G28: =SUM(G26:G27) -> 5934715.8 | I28: Equity Multiple | K28: ='Partnership Returns'!F26 -> 2.9797629 | L28: Equity Multiple | N28: ='Partnership Returns'!F19 -> 2.2066628
I29: Avg. Rate of Return | K29: ='Partnership Returns'!F24/Summary!G11/'Partnership Returns'!F22 -> 0.19797629 | L29: Avg. Rate of Return | N29: ='Partnership Returns'!F17/Summary!G11/'Partnership Returns'!F15 -> 0.12066628
B30: OPERATING CASH FLOW SUMMARY
B32: 1 | C32: =B32+1 -> 2 | D32: =C32+1 -> 3 | E32: =D32+1 -> 4 | F32: =E32+1 -> 5 | G32: =F32+1 -> 6 | H32: =G32+1 -> 7 | I32: =H32+1 -> 8 | J32: =I32+1 -> 9 | K32: =J32+1 -> 10
B33: ='10-Yr OpSt'!F42 -> 275400 | C33: ='10-Yr OpSt'!G42 -> 370859.02 | D33: ='10-Yr OpSt'!H42 -> 374517.64 | E33: ='10-Yr OpSt'!I42 -> 378174.44 | F33: ='10-Yr OpSt'!J42 -> 381826.88 | G33: ='10-Yr OpSt'!K42 -> 385474.31 | H33: ='10-Yr OpSt'!L42 -> 389115.9 | I33: ='10-Yr OpSt'!M42 -> 392747.82 | ... K33: ='10-Yr OpSt'!O42 -> 399980.13

Sheet Acquisition
B2: ACQUISITION ASSUMPTIONS
B3: ACQUISITION PRO FORMA | J3: NOTES
B4: REVENUE
B5: Rental Revenue | F5: Broker | H5: PSF | I5: Pro Forma
B6: Potential Base Rent | F6: 367200 | H6: =I6/GLA -> 8.87471 | I6: =F6 -> 367200
B7: Concessions | F7: 0 | H7: =I7/GLA -> 0 | I7: =F7 -> 0 | J7: 3 months free rent remaining: excluded from Pro Forma
B8: Total Rental Revenue | F8: =SUM(F6:F7) -> 367200 | H8: =I8/GLA -> 8.87471 | I8: =SUM(I6:I7) -> 367200
B10: Other Income
B11: Expense Reimbursement | F11: 355345 | H11: =I11/GLA -> 8.5881912 | I11: =F11 -> 355345
B12: Parking Income | F12: 0 | H12: =I12/GLA -> 0 | I12: =F12 -> 0
B13: Other Income | F13: 0 | H13: =I13/GLA -> 0 | I13: =F13 -> 0
B14: Total Other Income | F14: =SUM(F11:F13) -> 355345 | H14: =I14/GLA -> 8.5881912 | I14: =SUM(I11:I13) -> 355345
B16: Effective Gross Revenue
B17: Gross Revenue | F17: =+F14+F8 -> 722545 | H17: =I17/GLA -> 17.462901 | I17: =+I14+I8 -> 722545
B18: General Vacancy & Credit Loss | F18: 0 | H18: =I18/GLA -> 0 | I18: =F18 -> 0
B19: Total Effective Gross Revenue | F19: =SUM(F17:F18) -> 722545 | H19: =I19/GLA -> 17.462901 | I19: =SUM(I17:I18) -> 722545
B21: OPERATING EXPENSES
B22: Variable Operating Expenses
B23: Cleaning | F23: 0 | H23: =I23/GLA -> 0 | I23: =F23 -> 0
B24: Repairs and Maintenance | F24: =166583+5140 -> 171723 | H24: =I24/GLA -> 4.1503045 | I24: =F24 -> 171723
B25: Security | F25: 0 | H25: =I25/GLA -> 0 | I25: =F25 -> 0
B26: Landscaping | F26: 7615 | H26: =I26/GLA -> 0.18404389 | I26: =F26 -> 7615
B27: Utilities | F27: =36527+14850+4188+15804+1523 -> 72892 | H27: =I27/GLA -> 1.7616976 | I27: =F27 -> 72892
B28: Payroll & Administration | F28: 22275 | H28: =I28/GLA -> 0.53835557 | I28: =F28 -> 22275
B29: Property Management | F29: 14354 | H29: =I29/GLA -> 0.34691609 | I29: =F29 -> 14354
B30: Marketing | F30: 0 | H30: =I30/GLA -> 0 | I30: =F30 -> 0
B31: Other Variable Expenses | F31: 0 | H31: =I31/GLA -> 0 | I31: =F31 -> 0
B32: Total Variable Expenses | F32: =SUM(F23:F31) -> 288859 | H32: =I32/GLA -> 6.9813177 | I32: =SUM(I23:I31) -> 288859
B33: Fixed Expenses
B34: Real Estate Taxes | F34: 60280 | H34: =I34/GLA -> 1.4568832 | I34: =F34 -> 60280
B35: Insurance | F35: 6206 | H35: =I35/GLA -> 0.14999033 | I35: =F35 -> 6206
B36: Total Fixed Operating Expenses | F36: =SUM(F34:F35) -> 66486 | H36: =I36/GLA -> 1.6068735 | I36: =SUM(I34:I35) -> 66486
B38: Total Operating Expenses | F38: =+F36+F32 -> 355345 | H38: =I38/GLA -> 8.5881912 | I38: =+I36+I32 -> 355345
B40: Net Operating Income | F40: =F19-F38 -> 367200 | H40: =I40/GLA -> 8.87471 | I40: =I19-I38 -> 367200
B42: Going-in Cap Rate | F42: =F40/F43 -> 0.067007299 | H42: =I42/GLA -> 1.6194726e-06 | I42: =I40/I43 -> 0.067007299
B43: Purchase Price | F43: 5480000 | H43: =I43/GLA -> 132.44393 | I43: =F43 -> 5480000
B44: ACQUISITION COSTS | J44: NOTES
B45: Purchase Price | I45: =I43 -> 5480000
B46: Due Diligence | I46: 0
B47: Closing Cost (Excluding Financing Cost) | I47: =I45*0.005 -> 27400 | J47: 0.5% of Purchase Price
...

Sheet 10-Yr OpSt
B2: 10-YEAR OPERATING STATEMENT
B3: OPERATING CASH FLOW
E4: Year | F4: 1 | G4: =+F4+1 -> 2 | H4: =+G4+1 -> 3 | I4: =+H4+1 -> 4 | J4: =+I4+1 -> 5 | K4: =+J4+1 -> 6 | L4: =+K4+1 -> 7 | M4: =+L4+1 -> 8 | N4: =+M4+1 -> 9 | ... P4: =+O4+1 -> 11
E5: Month Ending | F5: =EOMONTH(Summary!G10,11) -> 43890 | G5: =EOMONTH(F5,12) -> 44255 | H5: =EOMONTH(G5,12) -> 44620 | I5: =EOMONTH(H5,12) -> 44985 | J5: =EOMONTH(I5,12) -> 45351 | K5: =EOMONTH(J5,12) -> 45716 | L5: =EOMONTH(K5,12) -> 46081 | M5: =EOMONTH(L5,12) -> 46446 | N5: =EOMONTH(M5,12) -> 46812 | ... P5: =EOMONTH(O5,12) -> 47542
B6: REVENUE
B7: Rental Revenue
B8: Potential Base Rent | F8: =Acquisition!F6 -> 367200 | G8: 374544 | H8: 382035 | I8: 389676 | J8: 397469 | K8: 405418 | L8: 413527 | M8: 421797 | N8: 430233 | O8: 438838 | P8: 447615
B9: Concessions | F9: =-F8*0.25 -> -91800 | G9: 0 | H9: 0 | I9: 0 | J9: 0 | K9: 0 | L9: 0 | M9: 0 | N9: 0 | O9: 0 | P9: 0
B10: Total Rental Revenue | F10: =SUM(F8:F9) -> 275400 | G10: =SUM(G8:G9) -> 374544 | H10: =SUM(H8:H9) -> 382035 | I10: =SUM(I8:I9) -> 389676 | J10: =SUM(J8:J9) -> 397469 | K10: =SUM(K8:K9) -> 405418 | L10: =SUM(L8:L9) -> 413527 | M10: =SUM(M8:M9) -> 421797 | ... P10: =SUM(P8:P9) -> 447615
B12: Other Income | E12: Reimb. % | F12: =F13/F40 -> 1 | G12: 1 | H12: 1 | I12: 1 | J12: 1 | K12: 1 | L12: 1 | M12: 1 | N12: 1 | O12: 1 | P12: 1
B13: Expense Reimbursement | F13: =Acquisition!F11 -> 355345 | G13: =G12*G40 -> 362451.9 | H13: =H12*H40 -> 369700.94 | I13: =I12*I40 -> 377094.96 | J13: =J12*J40 -> 384636.86 | K13: =K12*K40 -> 392329.59 | L13: =L12*L40 -> 400176.18 | M13: =M12*M40 -> 408179.71 | N13: =N12*N40 -> 416343.3 | ... P13: =P12*P40 -> 433163.57
B14: Parking Income | E14: 0.02 | F14: 0 | G14: =$F$14*(1+$E14)^(G$4-1) -> 0 | H14: =$F$14*(1+$E14)^(H$4-1) -> 0 | I14: =$F$14*(1+$E14)^(I$4-1) -> 0 | J14: =$F$14*(1+$E14)^(J$4-1) -> 0 | K14: =$F$14*(1+$E14)^(K$4-1) -> 0 | L14: =$F$14*(1+$E14)^(L$4-1) -> 0 | M14: =$F$14*(1+$E14)^(M$4-1) -> 0 | N14: =$F$14*(1+$E14)^(N$4-1) -> 0 | ... P14: =$F$14*(1+$E14)^(P$4-1) -> 0
B15: Other Income | E15: 0.02 | F15: 0 | G15: =$F$15*(1+$E15)^(G$4-1) -> 0 | H15: =$F$15*(1+$E15)^(H$4-1) -> 0 | I15: =$F$15*(1+$E15)^(I$4-1) -> 0 | J15: =$F$15*(1+$E15)^(J$4-1) -> 0 | K15: =$F$15*(1+$E15)^(K$4-1) -> 0 | L15: =$F$15*(1+$E15)^(L$4-1) -> 0 | M15: =$F$15*(1+$E15)^(M$4-1) -> 0 | N15: =$F$15*(1+$E15)^(N$4-1) -> 0 | ... P15: =$F$15*(1+$E15)^(P$4-1) -> 0
B16: Total Other Income | F16: =SUM(F13:F15) -> 355345 | G16: =SUM(G13:G15) -> 362451.9 | H16: =SUM(H13:H15) -> 369700.94 | I16: =SUM(I13:I15) -> 377094.96 | J16: =SUM(J13:J15) -> 384636.86 | K16: =SUM(K13:K15) -> 392329.59 | L16: =SUM(L13:L15) -> 400176.18 | M16: =SUM(M13:M15) -> 408179.71 | ... P16: =SUM(P13:P15) -> 433163.57
B18: Effective Gross Revenue | E18: Default Risk | F18: ='10-Yr OpSt'!K14+((Summary!$N$14-Summary!$K$14)/Summary!$G$11)*('10-Yr OpSt'!F4-1) -> 0 | G18: ='10-Yr OpSt'!L14+((Summary!$N$14-Summary!$K$14)/Summary!$G$11)*('10-Yr OpSt'!G4-1) -> 0.005 | H18: ='10-Yr OpSt'!M14+((Summary!$N$14-Summary!$K$14)/Summary!$G$11)*('10-Yr OpSt'!H4-1) -> 0.01 | I18: ='10-Yr OpSt'!N14+((Summary!$N$14-Summary!$K$14)/Summary!$G$11)*('10-Yr OpSt'!I4-1) -> 0.015 | J18: ='10-Yr OpSt'!O14+((Summary!$N$14-Summary!$K$14)/Summary!$G$11)*('10-Yr OpSt'!J4-1) -> 0.02 | K18: ='10-Yr OpSt'!P14+((Summary!$N$14-Summary!$K$14)/Summary!$G$11)*('10-Yr OpSt'!K4-1) -> 0.025 | L18: ='10-Yr OpSt'!Q14+((Summary!$N$14-Summary!$K$14)/Summary!$G$11)*('10-Yr OpSt'!L4-1) -> 0.03 | M18: ='10-Yr OpSt'!R14+((Summary!$N$14-Summary!$K$14)/Summary!$G$11)*('10-Yr OpSt'!M4-1) -> 0.035 | ... P18: ='10-Yr OpSt'!U14+((Summary!$N$14-Summary!$K$14)/Summary!$G$11)*('10-Yr OpSt'!P4-1) -> 0.05
B19: Gross Revenue | F19: =F16+F10 -> 630745 | G19: =G16+G10 -> 736995.9 | H19: =H16+H10 -> 751735.94 | I19: =I16+I10 -> 766770.96 | J19: =J16+J10 -> 782105.86 | K19: =K16+K10 -> 797747.59 | L19: =L16+L10 -> 813703.18 | M19: =M16+M10 -> 829976.71 | ... P19: =P16+P10 -> 880778.57
B20: General Vacancy & Credit Loss | F20: =-F18*F19 -> 0 | G20: =-G18*G19 -> -3684.9795 | H20: =-H18*H19 -> -7517.3594 | I20: =-I18*I19 -> -11501.564 | J20: =-J18*J19 -> -15642.117 | K20: =-K18*K19 -> -19943.69 | L20: =-L18*L19 -> -24411.096 | M20: =-M18*M19 -> -29049.185 | ... P20: =-P18*P19 -> -44038.929
B21: Total Effective Gross Revenue | F21: =SUM(F19:F20) -> 630745 | G21: =SUM(G19:G20) -> 733310.92 | H21: =SUM(H19:H20) -> 744218.58 | I21: =SUM(I19:I20) -> 755269.39 | J21: =SUM(J19:J20) -> 766463.74 | K21: =SUM(K19:K20) -> 777803.9 | L21: =SUM(L19:L20) -> 789292.09 | M21: =SUM(M19:M20) -> 800927.52 | ... P21: =SUM(P19:P20) -> 836739.64
B23: OPERATING EXPENSES | E23: Expense Growth % | F23: NA | G23: 0.02 | H23: 0.02 | I23: 0.02 | J23: 0.02 | K23: 0.02 | L23: 0.02 | M23: 0.02 | N23: 0.02 | O23: 0.02 | P23: 0.02
B24: Variable Operating Expenses
B25: Cleaning | F25: =Acquisition!F23 -> 0 | G25: =F25*(1+G$23) -> 0 | H25: =G25*(1+H$23) -> 0 | I25: =H25*(1+I$23) -> 0 | J25: =I25*(1+J$23) -> 0 | K25: =J25*(1+K$23) -> 0 | L25: =K25*(1+L$23) -> 0 | M25: =L25*(1+M$23) -> 0 | N25: =M25*(1+N$23) -> 0 | ... P25: =O25*(1+P$23) -> 0
B26: Repairs and Maintenance | F26: =Acquisition!F24 -> 171723 | G26: =F26*(1+G$23) -> 175157.46 | H26: =G26*(1+H$23) -> 178660.61 | I26: =H26*(1+I$23) -> 182233.82 | J26: =I26*(1+J$23) -> 185878.5 | K26: =J26*(1+K$23) -> 189596.07 | L26: =K26*(1+L$23) -> 193387.99 | M26: =L26*(1+M$23) -> 197255.75 | N26: =M26*(1+N$23) -> 201200.86 | ... P26: =O26*(1+P$23) -> 209329.38
B27: Security | F27: =Acquisition!F25 -> 0 | G27: =F27*(1+G$23) -> 0 | H27: =G27*(1+H$23) -> 0 | I27: =H27*(1+I$23) -> 0 | J27: =I27*(1+J$23) -> 0 | K27: =J27*(1+K$23) -> 0 | L27: =K27*(1+L$23) -> 0 | M27: =L27*(1+M$23) -> 0 | N27: =M27*(1+N$23) -> 0 | ... P27: =O27*(1+P$23) -> 0
B28: Landscaping | F28: =Acquisition!F26 -> 7615 | G28: =F28*(1+G$23) -> 7767.3 | H28: =G28*(1+H$23) -> 7922.646 | I28: =H28*(1+I$23) -> 8081.0989 | J28: =I28*(1+J$23) -> 8242.7209 | K28: =J28*(1+K$23) -> 8407.5753 | L28: =K28*(1+L$23) -> 8575.7268 | M28: =L28*(1+M$23) -> 8747.2414 | N28: =M28*(1+N$23) -> 8922.1862 | ... P28: =O28*(1+P$23) -> 9282.6425
B29: Utilities | F29: =Acquisition!F27 -> 72892 | G29: =F29*(1+G$23) -> 74349.84 | H29: =G29*(1+H$23) -> 75836.837 | I29: =H29*(1+I$23) -> 77353.574 | J29: =I29*(1+J$23) -> 78900.645 | K29: =J29*(1+K$23) -> 80478.658 | L29: =K29*(1+L$23) -> 82088.231 | M29: =L29*(1+M$23) -> 83729.996 | N29: =M29*(1+N$23) -> 85404.596 | ... P29: =O29*(1+P$23) -> 88854.941
B30: Payroll & Administration | F30: =Acquisition!F28 -> 22275 | G30: =F30*(1+G$23) -> 22720.5 | H30: =G30*(1+H$23) -> 23174.91 | I30: =H30*(1+I$23) -> 23638.408 | J30: =I30*(1+J$23) -> 24111.176 | K30: =J30*(1+K$23) -> 24593.4 | L30: =K30*(1+L$23) -> 25085.268 | M30: =L30*(1+M$23) -> 25586.973 | N30: =M30*(1+N$23) -> 26098.713 | ... P30: =O30*(1+P$23) -> 27153.101
B31: Property Management | F31: =Acquisition!F29 -> 14354 | G31: =F31*(1+G$23) -> 14641.08 | H31: =G31*(1+H$23) -> 14933.902 | I31: =H31*(1+I$23) -> 15232.58 | J31: =I31*(1+J$23) -> 15537.231 | K31: =J31*(1+K$23) -> 15847.976 | L31: =K31*(1+L$23) -> 16164.935 | M31: =L31*(1+M$23) -> 16488.234 | N31: =M31*(1+N$23) -> 16817.999 | ... P31: =O31*(1+P$23) -> 17497.446
B32: Marketing | F32: =Acquisition!F30 -> 0 | G32: =F32*(1+G$23) -> 0 | H32: =G32*(1+H$23) -> 0 | I32: =H32*(1+I$23) -> 0 | J32: =I32*(1+J$23) -> 0 | K32: =J32*(1+K$23) -> 0 | L32: =K32*(1+L$23) -> 0 | M32: =L32*(1+M$23) -> 0 | N32: =M32*(1+N$23) -> 0 | ... P32: =O32*(1+P$23) -> 0
B33: Other Variable Expenses | F33: =Acquisition!F31 -> 0 | G33: =F33*(1+G$23) -> 0 | H33: =G33*(1+H$23) -> 0 | I33: =H33*(1+I$23) -> 0 | J33: =I33*(1+J$23) -> 0 | K33: =J33*(1+K$23) -> 0 | L33: =K33*(1+L$23) -> 0 | M33: =L33*(1+M$23) -> 0 | N33: =M33*(1+N$23) -> 0 | ... P33: =O33*(1+P$23) -> 0
B34: Total Variable Expenses | F34: =SUM(F25:F33) -> 288859 | G34: =SUM(G25:G33) -> 294636.18 | H34: =SUM(H25:H33) -> 300528.9 | I34: =SUM(I25:I33) -> 306539.48 | J34: =SUM(J25:J33) -> 312670.27 | K34: =SUM(K25:K33) -> 318923.68 | L34: =SUM(L25:L33) -> 325302.15 | M34: =SUM(M25:M33) -> 331808.19 | ... P34: =SUM(P25:P33) -> 352117.51
B35: Fixed Expenses
B36: Real Estate Taxes | F36: =Acquisition!F34 -> 60280 | G36: =F36*(1+G$23) -> 61485.6 | H36: =G36*(1+H$23) -> 62715.312 | I36: =H36*(1+I$23) -> 63969.618 | J36: =I36*(1+J$23) -> 65249.011 | K36: =J36*(1+K$23) -> 66553.991 | L36: =K36*(1+L$23) -> 67885.071 | M36: =L36*(1+M$23) -> 69242.772 | N36: =M36*(1+N$23) -> 70627.627 | ... P36: =O36*(1+P$23) -> 73480.984
B37: Insurance | F37: =Acquisition!F35 -> 6206 | G37: =F37*(1+G$23) -> 6330.12 | H37: =G37*(1+H$23) -> 6456.7224 | I37: =H37*(1+I$23) -> 6585.8568 | J37: =I37*(1+J$23) -> 6717.574 | K37: =J37*(1+K$23) -> 6851.9255 | L37: =K37*(1+L$23) -> 6988.964 | M37: =L37*(1+M$23) -> 7128.7433 | N37: =M37*(1+N$23) -> 7271.3181 | ... P37: =O37*(1+P$23) -> 7565.0794
B38: Total Fixed Operating Income | F38: =SUM(F36:F37) -> 66486 | G38: =SUM(G36:G37) -> 67815.72 | H38: =SUM(H36:H37) -> 69172.034 | I38: =SUM(I36:I37) -> 70555.475 | J38: =SUM(J36:J37) -> 71966.585 | K38: =SUM(K36:K37) -> 73405.916 | L38: =SUM(L36:L37) -> 74874.035 | M38: =SUM(M36:M37) -> 76371.515 | ... P38: =SUM(P36:P37) -> 81046.063
B40: Total Operating Expenses | F40: =F38+F34 -> 355345 | G40: =G38+G34 -> 362451.9 | H40: =H38+H34 -> 369700.94 | I40: =I38+I34 -> 377094.96 | J40: =J38+J34 -> 384636.86 | K40: =K38+K34 -> 392329.59 | L40: =L38+L34 -> 400176.18 | M40: =M38+M34 -> 408179.71 | ... P40: =P38+P34 -> 433163.57
B42: Net Operating Income | F42: =F21-F40 -> 275400 | G42: =G21-G40 -> 370859.02 | H42: =H21-H40 -> 374517.64 | I42: =I21-I40 -> 378174.44 | J42: =J21-J40 -> 381826.88 | K42: =K21-K40 -> 385474.31 | L42: =L21-L40 -> 389115.9 | M42: =M21-M40 -> 392747.82 | ... P42: =P21-P40 -> 403576.07
B44: Leasing Costs | F44: 0 | G44: 0 | H44: 0 | I44: 0 | J44: 0 | K44: 0 | L44: 0 | M44: 0 | N44: 0 | O44: 0
B45: Other Closing Costs | F45: 0 | G45: 0 | H45: 0 | I45: 0 | J45: 0 | K45: 0 | L45: 0 | M45: 0 | N45: 0 | O45: 0
B46: Total Capital Expenditures | F46: =SUM(F44:F45) -> 0 | G46: =SUM(G44:G45) -> 0 | H46: =SUM(H44:H45) -> 0 | I46: =SUM(I44:I45) -> 0 | J46: =SUM(J44:J45) -> 0 | K46: =SUM(K44:K45) -> 0 | L46: =SUM(L44:L45) -> 0 | M46: =SUM(M44:M45) -> 0 | ... O46: =SUM(O44:O45) -> 0
B48: Cash Flow from Operations | F48: =F42-F46 -> 275400 | G48: =G42-G46 -> 370859.02 | H48: =H42-H46 -> 374517.64 | I48: =I42-I46 -> 378174.44 | J48: =J42-J46 -> 381826.88 | K48: =K42-K46 -> 385474.31 | L48: =L42-L46 -> 389115.9 | M48: =M42-M46 -> 392747.82 | ... O48: =O42-O46 -> 399980.13
...

Sheet Perm. Debt
B2: PERMANENT DEBT
B3: LOAN ASSUMPTIONS | H3: DEBT SERVICE PAYOFF
B4: Loan Amount | D4: 0.7 | E4: =D4*Acquisition!I43 -> 3836000 | H4: 1 | I4: =H4+1 -> 2 | J4: =I4+1 -> 3 | K4: =J4+1 -> 4 | L4: =K4+1 -> 5 | M4: =L4+1 -> 6 | N4: =M4+1 -> 7 | O4: =N4+1 -> 8 | P4: =O4+1 -> 9 | Q4: =P4+1 -> 10
B5: Loan Fees | D5: 0.01 | E5: =-D5*E4 -> -38360 | H5: ='10-Yr OpSt'!F5 -> 43890 | I5: ='10-Yr OpSt'!G5 -> 44255 | J5: ='10-Yr OpSt'!H5 -> 44620 | K5: ='10-Yr OpSt'!I5 -> 44985 | L5: ='10-Yr OpSt'!J5 -> 45351 | M5: ='10-Yr OpSt'!K5 -> 45716 | N5: ='10-Yr OpSt'!L5 -> 46081 | O5: ='10-Yr OpSt'!M5 -> 46446 | ... Q5: ='10-Yr OpSt'!O5 -> 47177
B6: Loan Proceeds | E6: =SUM(E4:E5) -> 3797640 | G6: Debt Service | H6: =(H4<=$E$10)*$E$12*12+(H4>$E$10)*$E$11*12 -> 182210 | I6: =(I4<=$E$10)*$E$12*12+(I4>$E$10)*$E$11*12 -> 182210 | J6: =(J4<=$E$10)*$E$12*12+(J4>$E$10)*$E$11*12 -> 182210 | K6: =(K4<=$E$10)*$E$12*12+(K4>$E$10)*$E$11*12 -> 240124.7 | L6: =(L4<=$E$10)*$E$12*12+(L4>$E$10)*$E$11*12 -> 240124.7 | M6: =(M4<=$E$10)*$E$12*12+(M4>$E$10)*$E$11*12 -> 240124.7 | N6: =(N4<=$E$10)*$E$12*12+(N4>$E$10)*$E$11*12 -> 240124.7 | O6: =(O4<=$E$10)*$E$12*12+(O4>$E$10)*$E$11*12 -> 240124.7 | ... Q6: =(Q4<=$E$10)*$E$12*12+(Q4>$E$10)*$E$11*12 -> 240124.7
G7: Loan Payoff | H7: =PV($E$8/12,$E$9*12-H4*12+MIN(H4,$E$10)*12,-$E$11) -> 3836000 | I7: =PV($E$8/12,$E$9*12-I4*12+MIN(I4,$E$10)*12,-$E$11) -> 3836000 | J7: =PV($E$8/12,$E$9*12-J4*12+MIN(J4,$E$10)*12,-$E$11) -> 3836000 | K7: =PV($E$8/12,$E$9*12-K4*12+MIN(K4,$E$10)*12,-$E$11) -> 3776807.7 | L7: =PV($E$8/12,$E$9*12-L4*12+MIN(L4,$E$10)*12,-$E$11) -> 3714741.7 | M7: =PV($E$8/12,$E$9*12-M4*12+MIN(M4,$E$10)*12,-$E$11) -> 3649662.5 | N7: =PV($E$8/12,$E$9*12-N4*12+MIN(N4,$E$10)*12,-$E$11) -> 3581423.9 | O7: =PV($E$8/12,$E$9*12-O4*12+MIN(O4,$E$10)*12,-$E$11) -> 3509872.4 | ... Q7: =PV($E$8/12,$E$9*12-Q4*12+MIN(Q4,$E$10)*12,-$E$11) -> 3356179.8
B8: Interest Rate | E8: 0.0475
B9: Loan Amortization (Years) | E9: 30 | G9: NOI | H9: ='10-Yr OpSt'!F42 -> 275400 | I9: ='10-Yr OpSt'!G42 -> 370859.02 | J9: ='10-Yr OpSt'!H42 -> 374517.64 | K9: ='10-Yr OpSt'!I42 -> 378174.44 | L9: ='10-Yr OpSt'!J42 -> 381826.88 | M9: ='10-Yr OpSt'!K42 -> 385474.31 | N9: ='10-Yr OpSt'!L42 -> 389115.9 | O9: ='10-Yr OpSt'!M42 -> 392747.82 | ... Q9: ='10-Yr OpSt'!O42 -> 399980.13
B10: Interest Only (Years) | E10: 3 | G10: DSCR | H10: =H9/H6 -> 1.5114428 | I10: =I9/I6 -> 2.0353385 | J10: =J9/J6 -> 2.0554176 | K10: =K9/K6 -> 1.5749085 | L10: =L9/L6 -> 1.5901191 | M10: =M9/M6 -> 1.6053089 | N10: =N9/N6 -> 1.6204743 | O10: =O9/O6 -> 1.6355994 | ... Q10: =Q9/Q6 -> 1.6657184
B11: Amortizing Pmt (Monthly) | E11: =PMT(E8/12,E9*12,-E4) -> 20010.392 | G11: Debt Yield | H11: =H9/$E$4 -> 0.071793535 | I11: =I9/$E$4 -> 0.096678577 | J11: =J9/$E$4 -> 0.097632336 | K11: =K9/$E$4 -> 0.098585619 | L11: =L9/$E$4 -> 0.099537769 | M11: =M9/$E$4 -> 0.10048861 | N11: =N9/$E$4 -> 0.10143793 | O11: =O9/$E$4 -> 0.10238473 | ... Q11: =Q9/$E$4 -> 0.10427011
B12: Interest-Only Pmt (Monthly) | E12: =E8/12*E4 -> 15184.167

Sheet Reversion
B2: REVERSION ASSUMPTIONS
B3: REVERSION PRO FORMA | J3: NOTES | M3: Year Ending | N3: ='10-Yr OpSt'!P5 -> 47542
B4: REVENUE | F4: Projected | I4: Reversion
B5: Rental Revenue | F5: Year 11 | H5: PSF | I5: Pro Forma
B6: Potential Base Rent | F6: ='10-Yr OpSt'!P8 -> 447615 | H6: =I6/GLA -> 13.439164 | I6: =10*GLA*1.03^10 -> 556058.84 | J6: Assuming market rent at $10 today, grown by 3%
B7: Concessions | F7: ='10-Yr OpSt'!P9 -> 0 | H7: =I7/GLA -> 0 | I7: =F7 -> 0
B8: Total Rental Revenue | F8: =SUM(F6:F7) -> 447615 | H8: =I8/GLA -> 13.439164 | I8: =SUM(I6:I7) -> 556058.84
B10: Other Income
B11: Expense Reimbursement | F11: ='10-Yr OpSt'!P13 -> 433163.57 | H11: =I11/GLA -> 10.468957 | I11: =F11 -> 433163.57 | J11: Assuming 100% reimbursement
B12: Parking Income | F12: ='10-Yr OpSt'!P14 -> 0 | H12: =I12/GLA -> 0 | I12: =F12 -> 0
B13: Other Income | F13: ='10-Yr OpSt'!P15 -> 0 | H13: =I13/GLA -> 0 | I13: =F13 -> 0
B14: Total Other Income | F14: =SUM(F11:F13) -> 433163.57 | H14: =I14/GLA -> 10.468957 | I14: =SUM(I11:I13) -> 433163.57
B16: Effective Gross Revenue
B17: Gross Revenue | F17: =+F14+F8 -> 880778.57 | H17: =I17/GLA -> 23.908121 | I17: =+I14+I8 -> 989222.41
B18: General Vacancy & Credit Loss | F18: ='10-Yr OpSt'!P20 -> -44038.929 | H18: =I18/GLA -> -2.3908121 | I18: =I17*-10% -> -98922.241 | J18: Credit risk + 6/10 years are speculative; assuming 10% vacancy
B19: Total Effective Gross Revenue | F19: =SUM(F17:F18) -> 836739.64 | H19: =I19/GLA -> 21.517309 | I19: =SUM(I17:I18) -> 890300.17
B21: OPERATING EXPENSES
B22: Variable Operating Expenses
B23: Cleaning | F23: ='10-Yr OpSt'!P25 -> 0 | H23: =I23/GLA -> 0 | I23: =F23 -> 0
B24: Repairs and Maintenance | F24: ='10-Yr OpSt'!P26 -> 209329.38 | H24: =I24/GLA -> 5.0591981 | I24: =F24 -> 209329.38
B25: Security | F25: ='10-Yr OpSt'!P27 -> 0 | H25: =I25/GLA -> 0 | I25: =F25 -> 0
B26: Landscaping | F26: ='10-Yr OpSt'!P28 -> 9282.6425 | H26: =I26/GLA -> 0.22434848 | I26: =F26 -> 9282.6425
B27: Utilities | F27: ='10-Yr OpSt'!P29 -> 88854.941 | H27: =I27/GLA -> 2.1474995 | I27: =F27 -> 88854.941
B28: Payroll & Administration | F28: ='10-Yr OpSt'!P30 -> 27153.101 | H28: =I28/GLA -> 0.65625243 | I28: =F28 -> 27153.101
B29: Property Management | F29: ='10-Yr OpSt'!P31 -> 17497.446 | H29: =I29/GLA -> 0.42288877 | I29: =F29 -> 17497.446
B30: Marketing | F30: ='10-Yr OpSt'!P32 -> 0 | H30: =I30/GLA -> 0 | I30: =F30 -> 0
B31: Other Variable Expenses | F31: ='10-Yr OpSt'!P33 -> 0 | H31: =I31/GLA -> 0 | I31: =F31 -> 0
B32: Total Variable Expenses | F32: =SUM(F23:F31) -> 352117.51 | H32: =I32/GLA -> 8.5101873 | I32: =SUM(I23:I31) -> 352117.51
B33: Fixed Expenses
B34: Real Estate Taxes | F34: ='10-Yr OpSt'!P36 -> 73480.984 | H34: =I34/GLA -> 1.7759325 | I34: =F34 -> 73480.984
B35: Insurance | F35: ='10-Yr OpSt'!P37 -> 7565.0794 | H35: =I35/GLA -> 0.18283738 | I35: =F35 -> 7565.0794
B36: Total Fixed Operating Expenses | F36: =SUM(F34:F35) -> 81046.063 | H36: =I36/GLA -> 1.9587699 | I36: =SUM(I34:I35) -> 81046.063
B38: Total Operating Expenses | F38: =+F36+F32 -> 433163.57 | H38: =I38/GLA -> 10.468957 | I38: =+I36+I32 -> 433163.57
B40: Net Operating Income | F40: =F19-F38 -> 403576.07 | H40: =I40/GLA -> 11.048352 | I40: =I19-I38 -> 457136.6
B42: Reversion Cap Rate | I42: =+Acquisition!I42+0.5% -> 0.072007299 | J42: Grow cap rate by 5 bps per year
B43: Reversion Value | H43: =I43/GLA -> 153.43377 | I43: =I40/I42 -> 6348475.8
B44: REVERSION PRO FORMA | J44: NOTES
B45: Reversion Value | I45: =I43 -> 6348475.8
B46: -Adustment to Reversion Value | I46: =GLA*-10 -> -413760 | J46: Adjustment for leasing costs of $10/SF during hold
B47: -Selling Costs | H47: 0.0320915 | I47: =H47*-(I45+I46) -> -190453.93
...

Sheet Property Returns
B2: PROPERTY-LEVEL RETURNS
B3: UNLEVERED RETURNS | F3: 0 | G3: =F3+1 -> 1 | H3: =G3+1 -> 2 | I3: =H3+1 -> 3 | J3: =I3+1 -> 4 | K3: =J3+1 -> 5 | L3: =K3+1 -> 6 | M3: =L3+1 -> 7 | N3: =M3+1 -> 8 | ... P3: =O3+1 -> 10
B4: INVESTMENT CASH FLOWS
B5: Purchase Price | F5: =(F$3=0)*Acquisition!$I45 -> 5480000 | G5: =(G$3=0)*Acquisition!$I45 -> 0 | H5: =(H$3=0)*Acquisition!$I45 -> 0 | I5: =(I$3=0)*Acquisition!$I45 -> 0 | J5: =(J$3=0)*Acquisition!$I45 -> 0 | K5: =(K$3=0)*Acquisition!$I45 -> 0 | L5: =(L$3=0)*Acquisition!$I45 -> 0 | M5: =(M$3=0)*Acquisition!$I45 -> 0 | ... P5: =(P$3=0)*Acquisition!$I45 -> 0
B6: Due Diligence Cost | F6: =(F$3=0)*Acquisition!$I46 -> 0 | G6: =(G$3=0)*Acquisition!$I46 -> 0 | H6: =(H$3=0)*Acquisition!$I46 -> 0 | I6: =(I$3=0)*Acquisition!$I46 -> 0 | J6: =(J$3=0)*Acquisition!$I46 -> 0 | K6: =(K$3=0)*Acquisition!$I46 -> 0 | L6: =(L$3=0)*Acquisition!$I46 -> 0 | M6: =(M$3=0)*Acquisition!$I46 -> 0 | ... P6: =(P$3=0)*Acquisition!$I46 -> 0
B7: Closing Cost (Excluding Financing Cost) | F7: =(F$3=0)*Acquisition!$I47 -> 27400 | G7: =(G$3=0)*Acquisition!$I47 -> 0 | H7: =(H$3=0)*Acquisition!$I47 -> 0 | I7: =(I$3=0)*Acquisition!$I47 -> 0 | J7: =(J$3=0)*Acquisition!$I47 -> 0 | K7: =(K$3=0)*Acquisition!$I47 -> 0 | L7: =(L$3=0)*Acquisition!$I47 -> 0 | M7: =(M$3=0)*Acquisition!$I47 -> 0 | ... P7: =(P$3=0)*Acquisition!$I47 -> 0
B8: Other Acquisition Cost | F8: =(F$3=0)*Acquisition!$I48 -> 0 | G8: =(G$3=0)*Acquisition!$I48 -> 0 | H8: =(H$3=0)*Acquisition!$I48 -> 0 | I8: =(I$3=0)*Acquisition!$I48 -> 0 | J8: =(J$3=0)*Acquisition!$I48 -> 0 | K8: =(K$3=0)*Acquisition!$I48 -> 0 | L8: =(L$3=0)*Acquisition!$I48 -> 0 | M8: =(M$3=0)*Acquisition!$I48 -> 0 | ... P8: =(P$3=0)*Acquisition!$I48 -> 0
B9: Total Acquisition Cost | F9: =SUM(F5:F8) -> 5507400
B11: OPERATING CASH FLOWS
B12: Effective Gross Revenue | F12: 0 | G12: ='10-Yr OpSt'!F21 -> 630745 | H12: ='10-Yr OpSt'!G21 -> 733310.92 | I12: ='10-Yr OpSt'!H21 -> 744218.58 | J12: ='10-Yr OpSt'!I21 -> 755269.39 | K12: ='10-Yr OpSt'!J21 -> 766463.74 | L12: ='10-Yr OpSt'!K21 -> 777803.9 | M12: ='10-Yr OpSt'!L21 -> 789292.09 | N12: ='10-Yr OpSt'!M21 -> 800927.52 | ... P12: ='10-Yr OpSt'!O21 -> 824650.3
B13: Operating Expenses | F13: 0 | G13: =-'10-Yr OpSt'!F40 -> -355345 | H13: =-'10-Yr OpSt'!G40 -> -362451.9 | I13: =-'10-Yr OpSt'!H40 -> -369700.94 | J13: =-'10-Yr OpSt'!I40 -> -377094.96 | K13: =-'10-Yr OpSt'!J40 -> -384636.86 | L13: =-'10-Yr OpSt'!K40 -> -392329.59 | M13: =-'10-Yr OpSt'!L40 -> -400176.18 | N13: =-'10-Yr OpSt'!M40 -> -408179.71 | ... P13: =-'10-Yr OpSt'!O40 -> -424670.17
B14: Net Operating Income | F14: 0 | G14: =SUM(G12:G13) -> 275400 | H14: =SUM(H12:H13) -> 370859.02 | I14: =SUM(I12:I13) -> 374517.64 | J14: =SUM(J12:J13) -> 378174.44 | K14: =SUM(K12:K13) -> 381826.88 | L14: =SUM(L12:L13) -> 385474.31 | M14: =SUM(M12:M13) -> 389115.9 | N14: =SUM(N12:N13) -> 392747.82 | ... P14: =SUM(P12:P13) -> 399980.13
B15: Capital Expenditures | F15: 0 | G15: =-'10-Yr OpSt'!F46 -> 0 | H15: =-'10-Yr OpSt'!G46 -> 0 | I15: =-'10-Yr OpSt'!H46 -> 0 | J15: =-'10-Yr OpSt'!I46 -> 0 | K15: =-'10-Yr OpSt'!J46 -> 0 | L15: =-'10-Yr OpSt'!K46 -> 0 | M15: =-'10-Yr OpSt'!L46 -> 0 | N15: =-'10-Yr OpSt'!M46 -> 0 | ... P15: =-'10-Yr OpSt'!O46 -> 0
B16: Cash Flow from Operations | F16: 0 | G16: =SUM(G14:G15) -> 275400 | H16: =SUM(H14:H15) -> 370859.02 | I16: =SUM(I14:I15) -> 374517.64 | J16: =SUM(J14:J15) -> 378174.44 | K16: =SUM(K14:K15) -> 381826.88 | L16: =SUM(L14:L15) -> 385474.31 | M16: =SUM(M14:M15) -> 389115.9 | N16: =SUM(N14:N15) -> 392747.82 | ... P16: =SUM(P14:P15) -> 399980.13
F17: Free and Clear Return | G17: =G16/SUM($F$9:G9) -> 0.050005447 | H17: =H16/SUM($F$9:H9) -> 0.067338312 | I17: =I16/SUM($F$9:I9) -> 0.068002622 | J17: =J16/SUM($F$9:J9) -> 0.068666601 | K17: =K16/SUM($F$9:K9) -> 0.06932979 | L17: =L16/SUM($F$9:L9) -> 0.069992067 | M17: =M16/SUM($F$9:M9) -> 0.070653285 | N17: =N16/SUM($F$9:N9) -> 0.071312746 | ... P17: =P16/SUM($F$9:P9) -> 0.072625946
B19: REVERSION CASH FLOWS
B20: Reversion Value | F20: =(F$3=Summary!$G$11)*Reversion!$I45 -> 0 | G20: =(G$3=Summary!$G$11)*Reversion!$I45 -> 0 | H20: =(H$3=Summary!$G$11)*Reversion!$I45 -> 0 | I20: =(I$3=Summary!$G$11)*Reversion!$I45 -> 0 | J20: =(J$3=Summary!$G$11)*Reversion!$I45 -> 0 | K20: =(K$3=Summary!$G$11)*Reversion!$I45 -> 0 | L20: =(L$3=Summary!$G$11)*Reversion!$I45 -> 0 | M20: =(M$3=Summary!$G$11)*Reversion!$I45 -> 0 | ... P20: =(P$3=Summary!$G$11)*Reversion!$I45 -> 6348475.8
B21: Adjustment to Reversion Value | F21: =(F$3=Summary!$G$11)*Reversion!$I46 -> 0 | G21: =(G$3=Summary!$G$11)*Reversion!$I46 -> 0 | H21: =(H$3=Summary!$G$11)*Reversion!$I46 -> 0 | I21: =(I$3=Summary!$G$11)*Reversion!$I46 -> 0 | J21: =(J$3=Summary!$G$11)*Reversion!$I46 -> 0 | K21: =(K$3=Summary!$G$11)*Reversion!$I46 -> 0 | L21: =(L$3=Summary!$G$11)*Reversion!$I46 -> 0 | M21: =(M$3=Summary!$G$11)*Reversion!$I46 -> 0 | ... P21: =(P$3=Summary!$G$11)*Reversion!$I46 -> -413760
B22: Selling Costs | F22: =(F$3=Summary!$G$11)*Reversion!$I47 -> 0 | G22: =(G$3=Summary!$G$11)*Reversion!$I47 -> 0 | H22: =(H$3=Summary!$G$11)*Reversion!$I47 -> 0 | I22: =(I$3=Summary!$G$11)*Reversion!$I47 -> 0 | J22: =(J$3=Summary!$G$11)*Reversion!$I47 -> 0 | K22: =(K$3=Summary!$G$11)*Reversion!$I47 -> 0 | L22: =(L$3=Summary!$G$11)*Reversion!$I47 -> 0 | M22: =(M$3=Summary!$G$11)*Reversion!$I47 -> 0 | ... P22: =(P$3=Summary!$G$11)*Reversion!$I47 -> -190453.93
B23: Net from Reversion | F23: =SUM(F20:F22) -> 0 | G23: =SUM(G20:G22) -> 0 | H23: =SUM(H20:H22) -> 0 | I23: =SUM(I20:I22) -> 0 | J23: =SUM(J20:J22) -> 0 | K23: =SUM(K20:K22) -> 0 | L23: =SUM(L20:L22) -> 0 | M23: =SUM(M20:M22) -> 0 | ... P23: =SUM(P20:P22) -> 5744261.9
B25: NET UNLEVERED CASH FLOW | F25: =-F9+F16+F23 -> -5507400 | G25: =-G9+G16+G23 -> 275400 | H25: =-H9+H16+H23 -> 370859.02 | I25: =-I9+I16+I23 -> 374517.64 | J25: =-J9+J16+J23 -> 378174.44 | K25: =-K9+K16+K23 -> 381826.88 | L25: =-L9+L16+L23 -> 385474.31 | M25: =-M9+M16+M23 -> 389115.9 | ... P25: =-P9+P16+P23 -> 6144242
B26: Unlevered IRR | F26: =IRR(F25:P25) -> 0.070179858
B27: Unlevered Equity Multiple | F27: =SUMIF(F25:P25,">0")/-SUMIF(F25:P25,"<0") -> 1.7229052
B28: Net Profit | F28: =SUM(F25:P25) -> 3981328
B30: LEVERED RETURNS | F30: 0 | G30: =F30+1 -> 1 | H30: =G30+1 -> 2 | I30: =H30+1 -> 3 | J30: =I30+1 -> 4 | K30: =J30+1 -> 5 | L30: =K30+1 -> 6 | M30: =L30+1 -> 7 | N30: =M30+1 -> 8 | ... P30: =O30+1 -> 10
B31: INVESTMENT CASH FLOWS
B32: Total Acquisition Cost | F32: =F9 -> 5507400 | G32: =G9 -> 0 | H32: =H9 -> 0 | I32: =I9 -> 0 | J32: =J9 -> 0 | K32: =K9 -> 0 | L32: =L9 -> 0 | M32: =M9 -> 0 | ... P32: =P9 -> 0
B33: Loan Proceeds | F33: =(F30=0)*-'Perm. Debt'!$E$6 -> -3797640 | G33: =(G30=0)*-'Perm. Debt'!$E$6 -> 0 | H33: =(H30=0)*-'Perm. Debt'!$E$6 -> 0 | I33: =(I30=0)*-'Perm. Debt'!$E$6 -> 0 | J33: =(J30=0)*-'Perm. Debt'!$E$6 -> 0 | K33: =(K30=0)*-'Perm. Debt'!$E$6 -> 0 | L33: =(L30=0)*-'Perm. Debt'!$E$6 -> 0 | M33: =(M30=0)*-'Perm. Debt'!$E$6 -> 0 | ... P33: =(P30=0)*-'Perm. Debt'!$E$6 -> 0
B34: Equity Required | F34: =SUM(F32:F33) -> 1709760 | G34: =SUM(G32:G33) -> 0 | H34: =SUM(H32:H33) -> 0 | I34: =SUM(I32:I33) -> 0 | J34: =SUM(J32:J33) -> 0 | K34: =SUM(K32:K33) -> 0 | L34: =SUM(L32:L33) -> 0 | M34: =SUM(M32:M33) -> 0 | ... P34: =SUM(P32:P33) -> 0
B36: OPERATING CASH FLOWS
B37: Cash Flow from Operations | F37: =F16 -> 0 | G37: =G16 -> 275400 | H37: =H16 -> 370859.02 | I37: =I16 -> 374517.64 | J37: =J16 -> 378174.44 | K37: =K16 -> 381826.88 | L37: =L16 -> 385474.31 | M37: =M16 -> 389115.9 | ... P37: =P16 -> 399980.13
B38: Debt Service | F38: =-'10-Yr OpSt'!E50 -> 0 | G38: =-'10-Yr OpSt'!F50 -> -182210 | H38: =-'10-Yr OpSt'!G50 -> -182210 | I38: =-'10-Yr OpSt'!H50 -> -182210 | J38: =-'10-Yr OpSt'!I50 -> -240124.7 | K38: =-'10-Yr OpSt'!J50 -> -240124.7 | L38: =-'10-Yr OpSt'!K50 -> -240124.7 | M38: =-'10-Yr OpSt'!L50 -> -240124.7 | ... P38: =-'10-Yr OpSt'!O50 -> -240124.7
B39: Cash Flow after Financing | F39: =SUM(F37:F38) -> 0 | G39: =SUM(G37:G38) -> 93190 | H39: =SUM(H37:H38) -> 188649.02 | I39: =SUM(I37:I38) -> 192307.64 | J39: =SUM(J37:J38) -> 138049.73 | K39: =SUM(K37:K38) -> 141702.18 | L39: =SUM(L37:L38) -> 145349.61 | M39: =SUM(M37:M38) -> 148991.2 | ... P39: =SUM(P37:P38) -> 159855.43
F40: Cash-on-Cash Return | G40: =G39/SUM($F$34:G34) -> 0.054504726 | H40: =H39/SUM($F$34:H34) -> 0.11033655 | I40: =I39/SUM($F$34:I34) -> 0.11247639 | J40: =J39/SUM($F$34:J34) -> 0.080742171 | K40: =K39/SUM($F$34:K34) -> 0.082878405 | L40: =L39/SUM($F$34:L34) -> 0.085011702 | M40: =M39/SUM($F$34:M34) -> 0.087141589 | N40: =N39/SUM($F$34:N34) -> 0.089265811 | ... P40: =P39/SUM($F$34:P34) -> 0.09349583
B42: REVERSION CASH FLOWS
B43: Net from Revesion | F43: 0 | G43: =G23 -> 0 | H43: =H23 -> 0 | I43: =I23 -> 0 | J43: =J23 -> 0 | K43: =K23 -> 0 | L43: =L23 -> 0 | M43: =M23 -> 0 | N43: =N23 -> 0 | ... P43: =P23 -> 5744261.9
B44: Loan Payoff | F44: 0 | G44: =(G30=Summary!$G$11)*-'Perm. Debt'!H7 -> 0 | H44: =(H30=Summary!$G$11)*-'Perm. Debt'!I7 -> 0 | I44: =(I30=Summary!$G$11)*-'Perm. Debt'!J7 -> 0 | J44: =(J30=Summary!$G$11)*-'Perm. Debt'!K7 -> 0 | K44: =(K30=Summary!$G$11)*-'Perm. Debt'!L7 -> 0 | L44: =(L30=Summary!$G$11)*-'Perm. Debt'!M7 -> 0 | M44: =(M30=Summary!$G$11)*-'Perm. Debt'!N7 -> 0 | N44: =(N30=Summary!$G$11)*-'Perm. Debt'!O7 -> 0 | ... P44: =(P30=Summary!$G$11)*-'Perm. Debt'!Q7 -> -3356179.8
B45: Net Proceeds from Sale | F45: 0 | G45: =SUM(G43:G44) -> 0 | H45: =SUM(H43:H44) -> 0 | I45: =SUM(I43:I44) -> 0 | J45: =SUM(J43:J44) -> 0 | K45: =SUM(K43:K44) -> 0 | L45: =SUM(L43:L44) -> 0 | M45: =SUM(M43:M44) -> 0 | N45: =SUM(N43:N44) -> 0 | ... P45: =SUM(P43:P44) -> 2388082.1
B47: NET LEVERED CASH FLOW | F47: =-F34+F39+F45 -> -1709760 | G47: =-G34+G39+G45 -> 93190 | H47: =-H34+H39+H45 -> 188649.02 | I47: =-I34+I39+I45 -> 192307.64 | J47: =-J34+J39+J45 -> 138049.73 | K47: =-K34+K39+K45 -> 141702.18 | L47: =-L34+L39+L45 -> 145349.61 | M47: =-M34+M39+M45 -> 148991.2 | ... P47: =-P34+P39+P45 -> 2547937.6
B48: Levered IRR | F48: =IRR(F47:P47) -> 0.11151217
...

Sheet Partnership Returns
B2: PARTNERSHIP-LEVEL RETURNS
B3: PARTNERSHIP ASSUMPTIONS
B4: OWNERSHIP SHARE | E4: Amount | F4: Pct
B5: General Partner | E5: =F22 -> 170976 | F5: 0.1
B6: Limited Partner | E6: =F15 -> 1538784 | F6: =1-F5 -> 0.9
B7: Total | E7: =SUM(E5:E6) -> 1709760 | F7: =SUM(F5:F6) -> 1
B9: DISTRIBUTION STRUCTURE | G9: GP Promote | H9: IRR Hurdle | I9: % GP | J9: % LP
B10: Tier 1 | G10: 0 | H10: 0.08 | I10: =G10+(1-G10)*$F$5 -> 0.1 | J10: =1-I10 -> 0.9
B11: Tier 2 | G11: 0.15 | I11: =G11+(1-G11)*$F$5 -> 0.235 | J11: =1-I11 -> 0.765
B13: PARTNERSHIP CASH FLOW AND RETURN SUMMARY | H13: 0 | I13: =H13+1 -> 1 | J13: =I13+1 -> 2 | K13: =J13+1 -> 3 | L13: =K13+1 -> 4 | M13: =L13+1 -> 5 | N13: =M13+1 -> 6 | O13: =N13+1 -> 7 | P13: =O13+1 -> 8 | ... R13: =Q13+1 -> 10
B14: LP RETURNS
B15: Contributions | F15: =SUM(H15:R15) -> 1538784 | H15: =H35 -> 1538784 | I15: =I35 -> 0 | J15: =J35 -> 0 | K15: =K35 -> 0 | L15: =L35 -> 0 | M15: =M35 -> 0 | N15: =N35 -> 0 | O15: =O35 -> 0 | ... R15: =R35 -> 0
B16: Distributions | F16: =SUM(H16:R16) -> 3395577.4 | H16: =H36+H45 -> 0 | I16: =I36+I45 -> 83871 | J16: =J36+J45 -> 169784.12 | K16: =K36+K45 -> 173076.88 | L16: =L36+L45 -> 124244.76 | M16: =M36+M45 -> 127531.96 | N16: =N36+N45 -> 130814.65 | O16: =O36+O45 -> 134092.08 | ... R16: =R36+R45 -> 2174180.4
B17: Net Profit | F17: =SUM(H18:R18) -> 1856793.4
B18: IRR | F18: =IRR(H18:R18) -> 0.10733889 | H18: =-H15+H16 -> -1538784 | I18: =-I15+I16 -> 83871 | J18: =-J15+J16 -> 169784.12 | K18: =-K15+K16 -> 173076.88 | L18: =-L15+L16 -> 124244.76 | M18: =-M15+M16 -> 127531.96 | N18: =-N15+N16 -> 130814.65 | O18: =-O15+O16 -> 134092.08 | ... R18: =-R15+R16 -> 2174180.4
B19: Equity Multiple | F19: =SUMIF(H18:R18,">0")/-SUMIF(H18:R18,"<0") -> 2.2066628
B21: GP RETURNS
B22: Contributions | F22: =SUM(H22:R22) -> 170976 | H22: =H40 -> 170976 | I22: =I40 -> 0 | J22: =J40 -> 0 | K22: =K40 -> 0 | L22: =L40 -> 0 | M22: =M40 -> 0 | N22: =N40 -> 0 | O22: =O40 -> 0 | ... R22: =R40 -> 0
B23: Distributions | F23: =SUM(H23:R23) -> 509467.94 | H23: =H41+H46 -> 0 | I23: =I41+I46 -> 9319 | J23: =J41+J46 -> 18864.902 | K23: =K41+K46 -> 19230.764 | L23: =L41+L46 -> 13804.973 | M23: =M41+M46 -> 14170.218 | N23: =N41+N46 -> 14534.961 | O23: =O41+O46 -> 14899.12 | ... R23: =R41+R46 -> 373757.16
B24: Net Profit | F24: =SUM(H25:R25) -> 338491.94
B25: IRR | F25: =IRR(H25:R25) -> 0.14330673 | H25: =-H22+H23 -> -170976 | I25: =-I22+I23 -> 9319 | J25: =-J22+J23 -> 18864.902 | K25: =-K22+K23 -> 19230.764 | L25: =-L22+L23 -> 13804.973 | M25: =-M22+M23 -> 14170.218 | N25: =-N22+N23 -> 14534.961 | O25: =-O22+O23 -> 14899.12 | ... R25: =-R22+R23 -> 373757.16
B26: Equity Multiple | F26: =SUMIF(H25:R25,">0")/-SUMIF(H25:R25,"<0") -> 2.9797629
B27: PROPERTY CASH FLOW AND RETURNS | H27: 0 | I27: =H27+1 -> 1 | J27: =I27+1 -> 2 | K27: =J27+1 -> 3 | L27: =K27+1 -> 4 | M27: =L27+1 -> 5 | N27: =M27+1 -> 6 | O27: =N27+1 -> 7 | P27: =O27+1 -> 8 | ... R27: =Q27+1 -> 10
B28: Net Levered Cash Flow | H28: ='Property Returns'!F47 -> -1709760 | I28: ='Property Returns'!G47 -> 93190 | J28: ='Property Returns'!H47 -> 188649.02 | K28: ='Property Returns'!I47 -> 192307.64 | L28: ='Property Returns'!J47 -> 138049.73 | M28: ='Property Returns'!K47 -> 141702.18 | N28: ='Property Returns'!L47 -> 145349.61 | O28: ='Property Returns'!M47 -> 148991.2 | ... R28: ='Property Returns'!P47 -> 2547937.6
B29: Levered IRR | H29: =IRR(H28:R28) -> 0.11151217
B30: Levered Equity Multiple | H30: =SUMIF(H28:R28,">0")/-SUMIF(H28:R28,"<0") -> 2.2839728
B32: TIER 1 - PREFERRED RETURN AND RETURN OF CAPITAL | H32: 0 | I32: =H32+1 -> 1 | J32: =I32+1 -> 2 | K32: =J32+1 -> 3 | L32: =K32+1 -> 4 | M32: =L32+1 -> 5 | N32: =M32+1 -> 6 | O32: =N32+1 -> 7 | P32: =O32+1 -> 8 | ... R32: =Q32+1 -> 10
B33: LP Starting Balance | H33: =G37 -> 0 | I33: =H37 -> 1538784 | J33: =I37 -> 1578015.7 | K33: =J37 -> 1534472.9 | L33: =K37 -> 1484153.8 | M33: =L37 -> 1478641.4 | N33: =M37 -> 1469400.7 | O33: =N37 -> 1456138.1 | ... R33: =Q37 -> 1388939.3
B34: LP Required Return | H34: =H33*$H$10 -> 0 | I34: =I33*$H$10 -> 123102.72 | J34: =J33*$H$10 -> 126241.26 | K34: =K33*$H$10 -> 122757.83 | L34: =L33*$H$10 -> 118732.3 | M34: =M33*$H$10 -> 118291.31 | N34: =N33*$H$10 -> 117552.06 | O34: =O33*$H$10 -> 116491.05 | ... R34: =R33*$H$10 -> 111115.14
B35: LP Contribution | H35: =MIN(H28,0)*-$F$6 -> 1538784 | I35: =MIN(I28,0)*-$F$6 -> 0 | J35: =MIN(J28,0)*-$F$6 -> 0 | K35: =MIN(K28,0)*-$F$6 -> 0 | L35: =MIN(L28,0)*-$F$6 -> 0 | M35: =MIN(M28,0)*-$F$6 -> 0 | N35: =MIN(N28,0)*-$F$6 -> 0 | O35: =MIN(O28,0)*-$F$6 -> 0 | ... R35: =MIN(R28,0)*-$F$6 -> 0
B36: LP Distribution- Tier 1 | H36: =MIN(H33+H34,MAX(H28,0)*$J$10) -> 0 | I36: =MIN(I33+I34,MAX(I28,0)*$J$10) -> 83871 | J36: =MIN(J33+J34,MAX(J28,0)*$J$10) -> 169784.12 | K36: =MIN(K33+K34,MAX(K28,0)*$J$10) -> 173076.88 | L36: =MIN(L33+L34,MAX(L28,0)*$J$10) -> 124244.76 | M36: =MIN(M33+M34,MAX(M28,0)*$J$10) -> 127531.96 | N36: =MIN(N33+N34,MAX(N28,0)*$J$10) -> 130814.65 | O36: =MIN(O33+O34,MAX(O28,0)*$J$10) -> 134092.08 | ... R36: =MIN(R33+R34,MAX(R28,0)*$J$10) -> 1500054.4
B37: LP Ending Balance | H37: =H33+H34+H35-H36 -> 1538784 | I37: =I33+I34+I35-I36 -> 1578015.7 | J37: =J33+J34+J35-J36 -> 1534472.9 | K37: =K33+K34+K35-K36 -> 1484153.8 | L37: =L33+L34+L35-L36 -> 1478641.4 | M37: =M33+M34+M35-M36 -> 1469400.7 | N37: =N33+N34+N35-N36 -> 1456138.1 | O37: =O33+O34+O35-O36 -> 1438537.1 | ... R37: =R33+R34+R35-R36 -> 0
B38: LP IRR | G38: =IRR(H38:R38) -> 0.08 | H38: =-H35+H36 -> -1538784 | I38: =-I35+I36 -> 83871 | J38: =-J35+J36 -> 169784.12 | K38: =-K35+K36 -> 173076.88 | L38: =-L35+L36 -> 124244.76 | M38: =-M35+M36 -> 127531.96 | N38: =-N35+N36 -> 130814.65 | O38: =-O35+O36 -> 134092.08 | ... R38: =-R35+R36 -> 1500054.4
B40: GP Contribution | H40: =-MIN(H28,0)-H35 -> 170976 | I40: =-MIN(I28,0)-I35 -> 0 | J40: =-MIN(J28,0)-J35 -> 0 | K40: =-MIN(K28,0)-K35 -> 0 | L40: =-MIN(L28,0)-L35 -> 0 | M40: =-MIN(M28,0)-M35 -> 0 | N40: =-MIN(N28,0)-N35 -> 0 | O40: =-MIN(O28,0)-O35 -> 0 | ... R40: =-MIN(R28,0)-R35 -> 0
B41: GP Distribution | H41: =H36/$J$10*$I$10 -> 0 | I41: =I36/$J$10*$I$10 -> 9319 | J41: =J36/$J$10*$I$10 -> 18864.902 | K41: =K36/$J$10*$I$10 -> 19230.764 | L41: =L36/$J$10*$I$10 -> 13804.973 | M41: =M36/$J$10*$I$10 -> 14170.218 | N41: =N36/$J$10*$I$10 -> 14534.961 | O41: =O36/$J$10*$I$10 -> 14899.12 | ... R41: =R36/$J$10*$I$10 -> 166672.71
B42: GP IRR | G42: =IRR(H42:R42) -> 0.08 | H42: =-H40+H41 -> -170976 | I42: =-I40+I41 -> 9319 | J42: =-J40+J41 -> 18864.902 | K42: =-K40+K41 -> 19230.764 | L42: =-L40+L41 -> 13804.973 | M42: =-M40+M41 -> 14170.218 | N42: =-N40+N41 -> 14534.961 | O42: =-O40+O41 -> 14899.12 | ... R42: =-R40+R41 -> 166672.71
B43: TIER 2 - PROMOTE | H43: 0 | I43: =H43+1 -> 1 | J43: =I43+1 -> 2 | K43: =J43+1 -> 3 | L43: =K43+1 -> 4 | M43: =L43+1 -> 5 | N43: =M43+1 -> 6 | O43: =N43+1 -> 7 | P43: =O43+1 -> 8 | ... R43: =Q43+1 -> 10
B44: Remaining Cash Flow | H44: =MAX(H28-H36-H41,0) -> 0 | I44: =MAX(I28-I36-I41,0) -> 0 | J44: =MAX(J28-J36-J41,0) -> 3.6379788e-12 | K44: =MAX(K28-K36-K41,0) -> 3.6379788e-12 | L44: =MAX(L28-L36-L41,0) -> 0 | M44: =MAX(M28-M36-M41,0) -> 0 | N44: =MAX(N28-N36-N41,0) -> 0 | O44: =MAX(O28-O36-O41,0) -> 0 | ... R44: =MAX(R28-R36-R41,0) -> 881210.44
B45: LP Distribution | H45: =H44*$J$11 -> 0 | I45: =I44*$J$11 -> 0 | J45: =J44*$J$11 -> 2.7830538e-12 | K45: =K44*$J$11 -> 2.7830538e-12 | L45: =L44*$J$11 -> 0 | M45: =M44*$J$11 -> 0 | N45: =N44*$J$11 -> 0 | O45: =O44*$J$11 -> 0 | ... R45: =R44*$J$11 -> 674125.99
B46: GP Distribution | H46: =H44*$I$11 -> 0 | I46: =I44*$I$11 -> 0 | J46: =J44*$I$11 -> 8.5492502e-13 | K46: =K44*$I$11 -> 8.5492502e-13 | L46: =L44*$I$11 -> 0 | M46: =M44*$I$11 -> 0 | N46: =N44*$I$11 -> 0 | O46: =O44*$I$11 -> 0 | ... R46: =R44*$I$11 -> 207084.45
...
