Workbook

Sheet Cover Page
B6: A.CRE Accelerator - Capstone Development Template

Sheet Summary
B6: Summary
B8: General Summary | I8: Project Returns | J8: Stabilized Development Yield - Over 5 Years | K8: Profit | L8: IRR | M8: Equity Multiple
B9: Project | G9: Sixteen 17th St | I9: Total Project Unlevered | J9: =SUMIF(OpProj!J13:EK13,"<=5",OpProj!$J$27:$EK$27)/5/K13 -> 0.055892663 | K9: =MonthlyCF!C73 -> 1.0572237e+08 | L9: =MonthlyCF!C74 -> 0.14834549 | M9: =MonthlyCF!C75 -> 1.3705118
B10: Location | G10: Anytown, XX | I10: Total Project Levered | K10: =MonthlyCF!C78 -> 92860525 | L10: =MonthlyCF!C79 -> 0.18754198 | M10: =MonthlyCF!C80 -> 1.7743876
B11: Model Version | G11: 1
I12: Sources & Uses | J12: % | K12: Total | L12: Per GSF | M12: Per RSF
B13: Timing | C13: Start Month | D13: Duration (months) | E13: End month | F13: Start Date | G13: End Date | I13: Sources | J13: =K13/$K$13 -> 1 | K13: =SUM(K14:K15) -> 2.9978702e+08 | L13: =SUM(L14:L15) -> 972.98383 | M13: =SUM(M14:M15) -> 1253.7043
B14: Development | I14: Equity | K14: =M45 -> 1.1991479e+08 | L14: =K14/$M$32 -> 389.19349 | M14: =K14/$M$33 -> 501.48165
B15: Analysis Start | C15: 1 | D15: 1 | E15: =+C15+D15-1 -> 1 | F15: 43617 | G15: =EDATE(F15,D15-1) -> 43617 | I15: Debt | K15: =M47 -> 1.7987223e+08 | L15: =K15/$M$32 -> 583.79034 | M15: =K15/$M$33 -> 752.22263
B16: Acquisition | C16: 0 | D16: 1 | E16: =+C16+D16-1 -> 0 | F16: =EDATE(F15,-1) -> 43586 | G16: =EDATE(F16,D16-1) -> 43586 | I16: Uses | J16: =K16/$K$16 -> 1 | K16: =SUM(K17:K27) -> 2.9978702e+08 | L16: =SUM(L17:L27) -> 972.98383 | M16: =SUM(M17:M27) -> 1253.7043
B17: Entitlement Phase | I17: =Budget!B11 -> Land | J17: =Budget!D11 -> 0.22538915 | K17: =Budget!E11 -> 67568742 | L17: =Budget!F11 -> 219.3 | M17: =Budget!G11 -> 282.57134
B18: Design/Buyout | C18: 2 | D18: 11 | E18: =+C18+D18-1 -> 12 | F18: =EDATE($F$15,C18-$C$15) -> 43647 | G18: =EDATE($F$15,E18-$C$15) -> 43952 | I18: =Budget!B12 -> Entitlement Costs | J18: =Budget!D12 -> 0 | K18: =Budget!E12 -> 0 | L18: =Budget!F12 -> 0 | M18: =Budget!G12 -> 0
B19: Construction | C19: 13 | D19: 30 | E19: =+C19+D19-1 -> 42 | F19: =EDATE($F$15,C19-$C$15) -> 43983 | G19: =EDATE($F$15,E19-$C$15) -> 44866 | I19: =Budget!B13 -> A&E | J19: =Budget!D13 -> 0.015288024 | K19: =Budget!E13 -> 4583151.1 | L19: =Budget!F13 -> 14.875 | M19: =Budget!G13 -> 19.166661
B20: Lease Up and Exit | I20: =Budget!B14 -> Construction | J20: =Budget!D14 -> 0.55499381 | K20: =Budget!E14 -> 166379940 | L20: =Budget!F14 -> 540 | M20: =Budget!G14 -> 695.79811
B21: Occupancy | C21: 37 | D21: 1 | E21: =+C21+D21-1 -> 37 | F21: =EDATE($F$15,C21-$C$15) -> 44713 | G21: =EDATE($F$15,E21-$C$15) -> 44713 | I21: =Budget!B15 -> Tenant Improvements | J21: =Budget!D15 -> 0.051846357 | K21: =Budget!E15 -> 15542865 | L21: =Budget!F15 -> 50.445667 | M21: =Budget!G15 -> 65
B22: Exit | C22: =E19+6 -> 48 | D22: 1 | E22: =+C22+D22-1 -> 48 | F22: =EDATE($F$15,C22-$C$15) -> 45047 | G22: =EDATE($F$15,E22-$C$15) -> 45047 | I22: =Budget!B16 -> Permits | J22: =Budget!D16 -> 0.0054600085 | K22: =Budget!E16 -> 1636839.7 | L22: =Budget!F16 -> 5.3125 | M22: =Budget!G16 -> 6.845236
B23: Total | D23: =DATEDIF(F23,G23,"m")+1 -> 48 | F23: =F15 -> 43617 | G23: =MAX(G15:G22) -> 45047 | I23: =Budget!B17 -> Taxes | J23: =Budget!D17 -> 0.034900292 | K23: =Budget!E17 -> 10462655 | L23: =Budget!F17 -> 33.95742 | M23: =Budget!G17 -> 43.754646
I24: =Budget!B18 -> Leasing and Marketing | J24: =Budget!D18 -> 0.014694656 | K24: =Budget!E18 -> 4405267.2 | L24: =Budget!F18 -> 14.297663 | M24: =Budget!G18 -> 18.422753
B25: Revenue/Operating Assumptions | I25: =Budget!B19 -> G&A | J25: =Budget!D19 -> 0.020665277 | K25: =Budget!E19 -> 6195181.9 | L25: =Budget!F19 -> 20.106981 | M25: =Budget!G19 -> 25.908147
B26: Office Tenant Lease Assumptions | I26: =Budget!B20 -> Contingency | J26: =Budget!D20 -> 0.033859157 | K26: =Budget!E20 -> 10150536 | L26: =Budget!F20 -> 32.944413 | M26: =Budget!G20 -> 42.44937
B27: Month Start | C27: =C21 -> 37 | G27: =EDATE($F$15,C27-$C$15) -> 44713 | I27: =Budget!B21 -> Financing Costs | J27: =Budget!D21 -> 0.042903271 | K27: =Budget!E21 -> 12861844 | L27: =Budget!F21 -> 41.744189 | M27: =Budget!G21 -> 53.788014
B28: Month Expire | E28: =C27+(10*12)-1 -> 156 | G28: =EDATE($F$15,E28-$C$15) -> 48335
B29: Rent/SF | G29: 65.55 | I29: Area Summary
B30: Ann. Base Rent Increase (%) | G30: 0.03 | I30: =Area!B9 -> Lot Size | M30: =Area!C9 -> 22860
B31: Reimb. % | G31: 1 | I31: =Area!B10 -> FAR | M31: =Area!C10 -> 13.478171
B32: Free Rent (Months) | G32: 6 | I32: =Area!B11 -> GSF | M32: =Area!C11 -> 308111
B33: TIs/SF | G33: 65 | I33: =Area!B12 -> RSF | M33: =Area!C12 -> 239121
B34: TIs Total | G34: =G33*M33 -> 15542865 | I34: =Area!B13 -> Office | M34: =Area!C13 -> 222792
B35: LC (% of entire lease) | G35: 0.02 | I35: =Area!B14 -> MEP | M35: =Area!C14 -> 5603
B36: LC/SF | G36: =G37/M33 -> 16.422753 | I36: =Area!B15 -> BOH | M36: =Area!C15 -> 10726
B37: LC Total | G37: =SUMIF(OpProj!J16:EK16,"<="&Summary!E28,OpProj!J17:EK17)*Summary!G35 -> 3927025.2 | I37: =Area!B16 -> Efficiency Ratio - (Total Building) | M37: =Area!C16 -> 0.77608719
B38: Parking | I38: =Area!B18 -> Parking Stalls | M38: =Area!C18 -> 83
B39: Stalls | G39: =M38 -> 83
B40: Revenue/Month (today's value) | G40: 250 | I40: Financing Assumptions
B41: Ann. Increase (%) | G41: 0.025 | I41: Total Project Costs Pre-Interest Reserve | M41: =MonthlyCF!C39 -> 2.8692518e+08
B42: Exit Assumptions | I42: Total Project Costs | M42: =MonthlyCF!C42 -> 2.9978702e+08
B43: Exit Cap Rate | G43: 0.045 | I43: LTC Control | M43: 0.58206946
B44: Exit Price | G44: =OpProj!H29 -> 3.9718057e+08 | I44: LTC with Interest Reserve & Fee | M44: =M47/M42 -> 0.60000005
B45: Cost of Sales | F45: 0.03 | G45: =G44*-F45 -> -11915417 | I45: Equity | M45: =M41*(1-M43) -> 1.1991479e+08
B46: Net Proceeds | G46: =SUM(G44:G45) -> 3.8526516e+08 | I46: Debt Pre-Interest Reserve | M46: =M41*M43 -> 1.6701038e+08
...

Sheet Area
B6: Area
B8: Summary
B9: Lot Size | C9: 22860
B10: FAR | C10: =C11/C9 -> 13.478171
B11: GSF | C11: =SUM(C22:C38) -> 308111
B12: RSF | C12: =SUM(D22:D38) -> 239121
B13: Office | C13: =SUM(E22:E38) -> 222792
B14: MEP | C14: =SUM(G22:G38) -> 5603
B15: BOH | C15: =SUM(F22:F38) -> 10726
B16: Efficiency Ratio - (Total Building) | C16: {=SUM(D22:D39/SUM(C22:C39))} -> 0.77608719
B17: Efficiency Ratio - (Excluding Below Grade) | C17: {=SUM(D22:D36/SUM(C22:C36))} -> 0.87478136
B18: Parking Stalls | C18: 83
B20: Stacking Plan
B21: Level | C21: GSF | D21: RSF | E21: Office RSF | F21: BOH RSF | G21: MEP RSF | H21: Outdoor SF | I21: Parking/Loading | J21: Efficiency (%) | K21: Notes
B22: Roof | C22: 2985 | D22: =SUM(E22:G22) -> 1370 | G22: 1370 | J22: =D22/C22 -> 0.45896147
B23: 14 | C23: 11412 | D23: =SUM(E23:G23) -> 10380 | E23: 9776 | F23: 604 | H23: 114 | J23: =D23/C23 -> 0.90956887
B24: 13 | C24: 11412 | D24: =SUM(E24:G24) -> 10380 | E24: 9776 | F24: 604 | H24: 114 | J24: =D24/C24 -> 0.90956887
B25: 12 | C25: 20439 | D25: =SUM(E25:G25) -> 10380 | E25: 9776 | F25: 604 | H25: 9027 | J25: =D25/C25 -> 0.50785263
B26: 11 | C26: 19163 | D26: =SUM(E26:G26) -> 17780 | E26: 16553 | F26: 675 | G26: 552 | H26: 968 | J26: =D26/C26 -> 0.92782967
B27: 10 | C27: 20270 | D27: =SUM(E27:G27) -> 18714 | E27: 18011 | F27: 703 | J27: =D27/C27 -> 0.92323631
B28: 9 | C28: 20270 | D28: =SUM(E28:G28) -> 18714 | E28: 18011 | F28: 703 | J28: =D28/C28 -> 0.92323631
B29: 8 | C29: 20270 | D29: =SUM(E29:G29) -> 18714 | E29: 18011 | F29: 703 | J29: =D29/C29 -> 0.92323631
B30: 7 | C30: 20270 | D30: =SUM(E30:G30) -> 18714 | E30: 18011 | F30: 703 | J30: =D30/C30 -> 0.92323631
B31: 6 | C31: 20270 | D31: =SUM(E31:G31) -> 18714 | E31: 18011 | F31: 703 | J31: =D31/C31 -> 0.92323631
B32: 5 | C32: 20270 | D32: =SUM(E32:G32) -> 18714 | E32: 18011 | F32: 703 | J32: =D32/C32 -> 0.92323631
B33: 4 | C33: 20270 | D33: =SUM(E33:G33) -> 18714 | E33: 18011 | F33: 703 | J33: =D33/C33 -> 0.92323631
B34: 3 | C34: 20270 | D34: =SUM(E34:G34) -> 18714 | E34: 18011 | F34: 703 | J34: =D34/C34 -> 0.92323631
B35: 2 | C35: 20270 | D35: =SUM(E35:G35) -> 18714 | E35: 18011 | F35: 307 | G35: 396 | J35: =D35/C35 -> 0.92323631
B36: 1 | C36: 20290 | D36: =SUM(E36:G36) -> 15840 | E36: 14302 | F36: 1223 | G36: 315 | I36: 2124 | J36: =D36/C36 -> 0.78068014
B37: B1 | C37: 19690 | D37: =SUM(E37:G37) -> 2280 | E37: 255 | F37: 594 | G37: 1431 | I37: 15417 | J37: =D37/C37 -> 0.11579482
B38: B2 | C38: 20290 | D38: =SUM(E38:G38) -> 2285 | E38: 255 | F38: 491 | G38: 1539 | I38: 17639 | J38: =D38/C38 -> 0.11261705

Sheet Budget
B6: Budget
B8: Budget Summary
D9: % | E9: Total | F9: Per GSF | G9: Per RSF
B10: Total | E10: =SUM(E11:E21) -> 2.9978702e+08 | F10: =SUM(F11:F21) -> 972.98383 | G10: =SUM(G11:G21) -> 1253.7043
B11: Land | D11: =E11/$E$10 -> 0.22538915 | E11: =E28 -> 67568742 | F11: =F28 -> 219.3 | G11: =G28 -> 282.57134
B12: Entitlement Costs
B13: A&E | D13: =E13/$E$10 -> 0.015288024 | E13: =E37 -> 4583151.1 | F13: =F37 -> 14.875 | G13: =G37 -> 19.166661
B14: Construction | D14: =E14/$E$10 -> 0.55499381 | E14: =E41 -> 166379940 | F14: =F41 -> 540 | G14: =G41 -> 695.79811
B15: =B45 -> Tenant Improvements | D15: =E15/$E$10 -> 0.051846357 | E15: =E45 -> 15542865 | F15: =F45 -> 50.445667 | G15: =G45 -> 65
B16: Permits | D16: =E16/$E$10 -> 0.0054600085 | E16: =E47 -> 1636839.7 | F16: =F47 -> 5.3125 | G16: =G47 -> 6.845236
B17: Taxes | D17: =E17/$E$10 -> 0.034900292 | E17: =E49 -> 10462655 | F17: =F49 -> 33.95742 | G17: =G49 -> 43.754646
B18: Leasing and Marketing | D18: =E18/$E$10 -> 0.014694656 | E18: =E51 -> 4405267.2 | F18: =F51 -> 14.297663 | G18: =G51 -> 18.422753
B19: G&A | D19: =E19/$E$10 -> 0.020665277 | E19: =E56 -> 6195181.9 | F19: =F56 -> 20.106981 | G19: =G56 -> 25.908147
B20: Contingency | D20: =E20/$E$10 -> 0.033859157 | E20: =E59 -> 10150536 | F20: =F59 -> 32.944413 | G20: =G59 -> 42.44937
B21: Financing Costs | D21: =E21/$E$10 -> 0.042903271 | E21: =E62 -> 12861844 | F21: =F62 -> 41.744189 | G21: =G62 -> 53.788014
B23: Detailed Budget Summary
F24: =Area!C11 -> 308111 | G24: =Area!C12 -> 239121
C25: Inputs | D25: % | E25: Total | F25: Per GSF | G25: Per RSF
B28: Land | D28: =E28/$E$10 -> 0.22538915 | E28: =SUM(E29:E31) -> 67568742 | F28: =SUM(F29:F31) -> 219.3 | G28: =SUM(G29:G31) -> 282.57134
B29: Sale Price | D29: =E29/$E$10 -> 0.22096976 | E29: =F29*F24 -> 66243865 | F29: 215 | G29: =E29/G$24 -> 277.03073
B30: Transfer Taxes | C30: 0.01 | D30: =E30/$E$10 -> 0.0022096976 | E30: =$C30*E$29 -> 662438.65 | F30: =E30/F$24 -> 2.15 | G30: =E30/G$24 -> 2.7703073
B31: Other Closing costs | C31: 0.01 | D31: =E31/$E$10 -> 0.0022096976 | E31: =$C31*E$29 -> 662438.65 | F31: =E31/F$24 -> 2.15 | G31: =E31/G$24 -> 2.7703073
B33: Entitlement Costs
B34: Application Fees
B35: Legal Fees
B37: A&E | C37: 0.035 | D37: =E37/$E$10 -> 0.015288024 | E37: =E42*$C$37 -> 4583151.1 | F37: =F42*$C$37 -> 14.875 | G37: =G42*$C$37 -> 19.166661
B38: Design | C38: 0.8 | D38: =E38/$E$10 -> 0.012230419 | E38: =$C38*E$37 -> 3666520.9 | F38: =$C38*F$37 -> 11.9 | G38: =$C38*G$37 -> 15.333329
B39: Construction Monitoring | C39: 0.2 | D39: =E39/$E$10 -> 0.0030576048 | E39: =$C39*E$37 -> 916630.23 | F39: =$C39*F$37 -> 2.975 | G39: =$C39*G$37 -> 3.8333322
B41: Construction | D41: =E41/$E$10 -> 0.55499381 | E41: =SUM(E42:E43) -> 166379940 | F41: =SUM(F42:F43) -> 540 | G41: =SUM(G42:G43) -> 695.79811
B42: Hard Costs | D42: =E42/$E$10 -> 0.43680068 | E42: =F42*$F$24 -> 130947175 | F42: 425 | G42: =E42/$G$24 -> 547.61888
B43: Soft Costs | D43: =E43/$E$10 -> 0.11819313 | E43: =F43*$F$24 -> 35432765 | F43: 115 | G43: =E43/$G$24 -> 148.17923
B45: Tenant Improvements | D45: =E45/$E$10 -> 0.051846357 | E45: =Summary!G34 -> 15542865 | F45: =$E45/$F$24 -> 50.445667 | G45: =E45/$G$24 -> 65
B47: Permits & City Fees | C47: 0.0125 | D47: =E47/$E$10 -> 0.0054600085 | E47: =E42*$C$47 -> 1636839.7 | F47: =F42*$C$47 -> 5.3125 | G47: =G42*$C$47 -> 6.845236 | I47: typical permits and when they are paid for
B49: Taxes | C49: 0.01735 | D49: =E49/$E$10 -> 0.034900292 | E49: =MonthlyCF!C30 -> 10462655 | F49: =$E49/$F$24 -> 33.95742 | G49: =E49/$G$24 -> 43.754646
B51: Leasing and Marketing | D51: =E51/$E$10 -> 0.014694656 | E51: =SUM(E52:E53) -> 4405267.2 | F51: =SUM(F52:F53) -> 14.297663 | G51: =SUM(G52:G53) -> 18.422753
B52: Leasing Commissions | D52: =E52/$E$10 -> 0.013099384 | E52: =Summary!G37 -> 3927025.2 | F52: =$E52/$F$24 -> 12.745489 | G52: =E52/$G$24 -> 16.422753
B53: Marketing | D53: =E53/$E$10 -> 0.0015952725 | E53: =G53*G24 -> 478242 | F53: =E53/F24 -> 1.5521744 | G53: 2
B55: G&A
B56: Development Fee | C56: 0.035 | D56: =E56/$E$10 -> 0.020665277 | E56: =SUM(E51,E47,E41,E37)*$C$56 -> 6195181.9 | F56: =SUM(F51,F47,F41,F37)*$C$56 -> 20.106981 | G56: =SUM(G51,G47,G41,G37)*$C$56 -> 25.908147
C57: Less Land, TIs, Contingency, and Financing
...

Sheet MonthlyCF
B6: Monthly Cash Flow
B8: Fiscal Year | L8: =ROUNDUP(L9/12,0) -> 1 | M8: =ROUNDUP(M9/12,0) -> 1 | N8: =ROUNDUP(N9/12,0) -> 1 | O8: =ROUNDUP(O9/12,0) -> 1 | P8: =ROUNDUP(P9/12,0) -> 1 | Q8: =ROUNDUP(Q9/12,0) -> 1 | R8: =ROUNDUP(R9/12,0) -> 1 | S8: =ROUNDUP(S9/12,0) -> 1 | ... BS8: =ROUNDUP(BS9/12,0) -> 5
B9: Fiscal Month | H9: Standard Deviation | K9: =Summary!C16 -> 0 | L9: =K9+1 -> 1 | M9: =L9+1 -> 2 | N9: =M9+1 -> 3 | O9: =N9+1 -> 4 | P9: =O9+1 -> 5 | Q9: =P9+1 -> 6 | R9: =Q9+1 -> 7 | S9: =R9+1 -> 8 | ... BS9: =BR9+1 -> 60
B10: Date | C10: Budget | D10: Growth Projection Method | E10: Start Month | F10: End Month | G10: Duration | I10: Check | K10: =Summary!F16 -> 43586 | L10: =EDATE(K10,1) -> 43617 | M10: =EDATE(L10,1) -> 43647 | N10: =EDATE(M10,1) -> 43678 | O10: =EDATE(N10,1) -> 43709 | P10: =EDATE(O10,1) -> 43739 | Q10: =EDATE(P10,1) -> 43770 | R10: =EDATE(Q10,1) -> 43800 | S10: =EDATE(R10,1) -> 43831 | ... BS10: =EDATE(BR10,1) -> 45413
B11: Line Items
B13: Land | C13: =Budget!E11 -> 67568742 | I13: =IF(ROUND(C13,0)=ROUND(SUM(K13:BS13),0),"Ok","Error") -> Ok | K13: =C13 -> 67568742
B15: =Budget!B33 -> Entitlement Costs
B16: =Budget!B34 -> Application Fees
B17: =Budget!B35 -> Legal Fees
B19: =Budget!B37 -> A&E
B20: =Budget!B38 -> Design | C20: =Budget!E38 -> 3666520.9 | D20: Bell Curve - SD of 5 | E20: =Summary!C18 -> 2 | F20: =Summary!E18 -> 12 | G20: =F20-E20+1 -> 11 | H20: 5 | I20: =IF(ROUND(C20,0)=ROUND(SUM(L20:BS20),0),"Ok","Error") -> Ok | L20: =(_xlfn.NORM.DIST((AND(L$9>=$E20,L$9<=$F20)*(L$9-$E20+1)),$G20/2,$H20,TRUE)-_xlfn.NORM.DIST((AND(L$9>=$E20,L$9<=$F20)*(K$9-$E20+1)),$G20/2,$H20,TRUE))/(1-2*_xlfn.NORM.DIST(0,$G20/2,$H20,TRUE))*$C20 -> 0 | M20: =(_xlfn.NORM.DIST((AND(M$9>=$E20,M$9<=$F20)*(M$9-$E20+1)),$G20/2,$H20,TRUE)-_xlfn.NORM.DIST((AND(M$9>=$E20,M$9<=$F20)*(L$9-$E20+1)),$G20/2,$H20,TRUE))/(1-2*_xlfn.NORM.DIST(0,$G20/2,$H20,TRUE))*$C20 -> 243509.91 | N20: =(_xlfn.NORM.DIST((AND(N$9>=$E20,N$9<=$F20)*(N$9-$E20+1)),$G20/2,$H20,TRUE)-_xlfn.NORM.DIST((AND(N$9>=$E20,N$9<=$F20)*(M$9-$E20+1)),$G20/2,$H20,TRUE))/(1-2*_xlfn.NORM.DIST(0,$G20/2,$H20,TRUE))*$C20 -> 291359.75 | O20: =(_xlfn.NORM.DIST((AND(O$9>=$E20,O$9<=$F20)*(O$9-$E20+1)),$G20/2,$H20,TRUE)-_xlfn.NORM.DIST((AND(O$9>=$E20,O$9<=$F20)*(N$9-$E20+1)),$G20/2,$H20,TRUE))/(1-2*_xlfn.NORM.DIST(0,$G20/2,$H20,TRUE))*$C20 -> 334987.38 | P20: =(_xlfn.NORM.DIST((AND(P$9>=$E20,P$9<=$F20)*(P$9-$E20+1)),$G20/2,$H20,TRUE)-_xlfn.NORM.DIST((AND(P$9>=$E20,P$9<=$F20)*(O$9-$E20+1)),$G20/2,$H20,TRUE))/(1-2*_xlfn.NORM.DIST(0,$G20/2,$H20,TRUE))*$C20 -> 370095.11 | Q20: =(_xlfn.NORM.DIST((AND(Q$9>=$E20,Q$9<=$F20)*(Q$9-$E20+1)),$G20/2,$H20,TRUE)-_xlfn.NORM.DIST((AND(Q$9>=$E20,Q$9<=$F20)*(P$9-$E20+1)),$G20/2,$H20,TRUE))/(1-2*_xlfn.NORM.DIST(0,$G20/2,$H20,TRUE))*$C20 -> 392902.04 | R20: =(_xlfn.NORM.DIST((AND(R$9>=$E20,R$9<=$F20)*(R$9-$E20+1)),$G20/2,$H20,TRUE)-_xlfn.NORM.DIST((AND(R$9>=$E20,R$9<=$F20)*(Q$9-$E20+1)),$G20/2,$H20,TRUE))/(1-2*_xlfn.NORM.DIST(0,$G20/2,$H20,TRUE))*$C20 -> 400812.5 | S20: =(_xlfn.NORM.DIST((AND(S$9>=$E20,S$9<=$F20)*(S$9-$E20+1)),$G20/2,$H20,TRUE)-_xlfn.NORM.DIST((AND(S$9>=$E20,S$9<=$F20)*(R$9-$E20+1)),$G20/2,$H20,TRUE))/(1-2*_xlfn.NORM.DIST(0,$G20/2,$H20,TRUE))*$C20 -> 392902.04 | ... BS20: =(_xlfn.NORM.DIST((AND(BS$9>=$E20,BS$9<=$F20)*(BS$9-$E20+1)),$G20/2,$H20,TRUE)-_xlfn.NORM.DIST((AND(BS$9>=$E20,BS$9<=$F20)*(BR$9-$E20+1)),$G20/2,$H20,TRUE))/(1-2*_xlfn.NORM.DIST(0,$G20/2,$H20,TRUE))*$C20 -> 0
B21: =Budget!B39 -> Construction Monitoring | C21: =Budget!E39 -> 916630.23 | D21: Straight Line | E21: =Summary!C19 -> 13 | F21: =Summary!E19 -> 42 | G21: =F21-E21+1 -> 30 | H21: 1000000000 | I21: =IF(ROUND(C21,0)=ROUND(SUM(L21:BS21),0),"Ok","Error") -> Ok | L21: =(_xlfn.NORM.DIST((AND(L$9>=$E21,L$9<=$F21)*(L$9-$E21+1)),$G21/2,$H21,TRUE)-_xlfn.NORM.DIST((AND(L$9>=$E21,L$9<=$F21)*(K$9-$E21+1)),$G21/2,$H21,TRUE))/(1-2*_xlfn.NORM.DIST(0,$G21/2,$H21,TRUE))*$C21 -> 0 | M21: =(_xlfn.NORM.DIST((AND(M$9>=$E21,M$9<=$F21)*(M$9-$E21+1)),$G21/2,$H21,TRUE)-_xlfn.NORM.DIST((AND(M$9>=$E21,M$9<=$F21)*(L$9-$E21+1)),$G21/2,$H21,TRUE))/(1-2*_xlfn.NORM.DIST(0,$G21/2,$H21,TRUE))*$C21 -> 0 | N21: =(_xlfn.NORM.DIST((AND(N$9>=$E21,N$9<=$F21)*(N$9-$E21+1)),$G21/2,$H21,TRUE)-_xlfn.NORM.DIST((AND(N$9>=$E21,N$9<=$F21)*(M$9-$E21+1)),$G21/2,$H21,TRUE))/(1-2*_xlfn.NORM.DIST(0,$G21/2,$H21,TRUE))*$C21 -> 0 | O21: =(_xlfn.NORM.DIST((AND(O$9>=$E21,O$9<=$F21)*(O$9-$E21+1)),$G21/2,$H21,TRUE)-_xlfn.NORM.DIST((AND(O$9>=$E21,O$9<=$F21)*(N$9-$E21+1)),$G21/2,$H21,TRUE))/(1-2*_xlfn.NORM.DIST(0,$G21/2,$H21,TRUE))*$C21 -> 0 | P21: =(_xlfn.NORM.DIST((AND(P$9>=$E21,P$9<=$F21)*(P$9-$E21+1)),$G21/2,$H21,TRUE)-_xlfn.NORM.DIST((AND(P$9>=$E21,P$9<=$F21)*(O$9-$E21+1)),$G21/2,$H21,TRUE))/(1-2*_xlfn.NORM.DIST(0,$G21/2,$H21,TRUE))*$C21 -> 0 | Q21: =(_xlfn.NORM.DIST((AND(Q$9>=$E21,Q$9<=$F21)*(Q$9-$E21+1)),$G21/2,$H21,TRUE)-_xlfn.NORM.DIST((AND(Q$9>=$E21,Q$9<=$F21)*(P$9-$E21+1)),$G21/2,$H21,TRUE))/(1-2*_xlfn.NORM.DIST(0,$G21/2,$H21,TRUE))*$C21 -> 0 | R21: =(_xlfn.NORM.DIST((AND(R$9>=$E21,R$9<=$F21)*(R$9-$E21+1)),$G21/2,$H21,TRUE)-_xlfn.NORM.DIST((AND(R$9>=$E21,R$9<=$F21)*(Q$9-$E21+1)),$G21/2,$H21,TRUE))/(1-2*_xlfn.NORM.DIST(0,$G21/2,$H21,TRUE))*$C21 -> 0 | S21: =(_xlfn.NORM.DIST((AND(S$9>=$E21,S$9<=$F21)*(S$9-$E21+1)),$G21/2,$H21,TRUE)-_xlfn.NORM.DIST((AND(S$9>=$E21,S$9<=$F21)*(R$9-$E21+1)),$G21/2,$H21,TRUE))/(1-2*_xlfn.NORM.DIST(0,$G21/2,$H21,TRUE))*$C21 -> 0 | ... BS21: =(_xlfn.NORM.DIST((AND(BS$9>=$E21,BS$9<=$F21)*(BS$9-$E21+1)),$G21/2,$H21,TRUE)-_xlfn.NORM.DIST((AND(BS$9>=$E21,BS$9<=$F21)*(BR$9-$E21+1)),$G21/2,$H21,TRUE))/(1-2*_xlfn.NORM.DIST(0,$G21/2,$H21,TRUE))*$C21 -> 0
B23: =Budget!B41 -> Construction | C23: =Budget!E14 -> 166379940 | D23: Bell Curve - SD of 4 | E23: =Summary!C19 -> 13 | F23: =Summary!E19 -> 42 | G23: =F23-E23+1 -> 30 | H23: 4 | I23: =IF(ROUND(C23,0)=ROUND(SUM(L23:BS23),0),"Ok","Error") -> Ok | L23: =(_xlfn.NORM.DIST((AND(L$9>=$E23,L$9<=$F23)*(L$9-$E23+1)),$G23/2,$H23,TRUE)-_xlfn.NORM.DIST((AND(L$9>=$E23,L$9<=$F23)*(K$9-$E23+1)),$G23/2,$H23,TRUE))/(1-2*_xlfn.NORM.DIST(0,$G23/2,$H23,TRUE))*$C23 -> 0 | M23: =(_xlfn.NORM.DIST((AND(M$9>=$E23,M$9<=$F23)*(M$9-$E23+1)),$G23/2,$H23,TRUE)-_xlfn.NORM.DIST((AND(M$9>=$E23,M$9<=$F23)*(L$9-$E23+1)),$G23/2,$H23,TRUE))/(1-2*_xlfn.NORM.DIST(0,$G23/2,$H23,TRUE))*$C23 -> 0 | N23: =(_xlfn.NORM.DIST((AND(N$9>=$E23,N$9<=$F23)*(N$9-$E23+1)),$G23/2,$H23,TRUE)-_xlfn.NORM.DIST((AND(N$9>=$E23,N$9<=$F23)*(M$9-$E23+1)),$G23/2,$H23,TRUE))/(1-2*_xlfn.NORM.DIST(0,$G23/2,$H23,TRUE))*$C23 -> 0 | O23: =(_xlfn.NORM.DIST((AND(O$9>=$E23,O$9<=$F23)*(O$9-$E23+1)),$G23/2,$H23,TRUE)-_xlfn.NORM.DIST((AND(O$9>=$E23,O$9<=$F23)*(N$9-$E23+1)),$G23/2,$H23,TRUE))/(1-2*_xlfn.NORM.DIST(0,$G23/2,$H23,TRUE))*$C23 -> 0 | P23: =(_xlfn.NORM.DIST((AND(P$9>=$E23,P$9<=$F23)*(P$9-$E23+1)),$G23/2,$H23,TRUE)-_xlfn.NORM.DIST((AND(P$9>=$E23,P$9<=$F23)*(O$9-$E23+1)),$G23/2,$H23,TRUE))/(1-2*_xlfn.NORM.DIST(0,$G23/2,$H23,TRUE))*$C23 -> 0 | Q23: =(_xlfn.NORM.DIST((AND(Q$9>=$E23,Q$9<=$F23)*(Q$9-$E23+1)),$G23/2,$H23,TRUE)-_xlfn.NORM.DIST((AND(Q$9>=$E23,Q$9<=$F23)*(P$9-$E23+1)),$G23/2,$H23,TRUE))/(1-2*_xlfn.NORM.DIST(0,$G23/2,$H23,TRUE))*$C23 -> 0 | R23: =(_xlfn.NORM.DIST((AND(R$9>=$E23,R$9<=$F23)*(R$9-$E23+1)),$G23/2,$H23,TRUE)-_xlfn.NORM.DIST((AND(R$9>=$E23,R$9<=$F23)*(Q$9-$E23+1)),$G23/2,$H23,TRUE))/(1-2*_xlfn.NORM.DIST(0,$G23/2,$H23,TRUE))*$C23 -> 0 | S23: =(_xlfn.NORM.DIST((AND(S$9>=$E23,S$9<=$F23)*(S$9-$E23+1)),$G23/2,$H23,TRUE)-_xlfn.NORM.DIST((AND(S$9>=$E23,S$9<=$F23)*(R$9-$E23+1)),$G23/2,$H23,TRUE))/(1-2*_xlfn.NORM.DIST(0,$G23/2,$H23,TRUE))*$C23 -> 0 | ... BS23: =(_xlfn.NORM.DIST((AND(BS$9>=$E23,BS$9<=$F23)*(BS$9-$E23+1)),$G23/2,$H23,TRUE)-_xlfn.NORM.DIST((AND(BS$9>=$E23,BS$9<=$F23)*(BR$9-$E23+1)),$G23/2,$H23,TRUE))/(1-2*_xlfn.NORM.DIST(0,$G23/2,$H23,TRUE))*$C23 -> 0
B25: =Budget!B45 -> Tenant Improvements | C25: =Budget!E15 -> 15542865 | D25: Start of Lease | E25: =Summary!C21 -> 37 | I25: =IF(ROUND(C25,0)=ROUND(SUM(L25:BS25),0),"Ok","Error") -> Ok | L25: =(L$9=$E25)*$C25 -> 0 | M25: =(M$9=$E25)*$C25 -> 0 | N25: =(N$9=$E25)*$C25 -> 0 | O25: =(O$9=$E25)*$C25 -> 0 | P25: =(P$9=$E25)*$C25 -> 0 | Q25: =(Q$9=$E25)*$C25 -> 0 | R25: =(R$9=$E25)*$C25 -> 0 | S25: =(S$9=$E25)*$C25 -> 0 | ... BS25: =(BS$9=$E25)*$C25 -> 0
B27: =Budget!B47 -> Permits & City Fees | C27: =Budget!E16 -> 1636839.7 | D27: Custom | E27: 4 | F27: =E27+8 -> 12 | I27: =IF(ROUND(C27,0)=ROUND(SUM(L27:BS27),0),"Ok","Error") -> Ok | L27: =(L9=$E$27)*($C$27*$E$28)+(L9=$F$27)*($C$27*$F$28) -> 0 | M27: =(M9=$E$27)*($C$27*$E$28)+(M9=$F$27)*($C$27*$F$28) -> 0 | N27: =(N9=$E$27)*($C$27*$E$28)+(N9=$F$27)*($C$27*$F$28) -> 0 | O27: =(O9=$E$27)*($C$27*$E$28)+(O9=$F$27)*($C$27*$F$28) -> 982103.81 | P27: =(P9=$E$27)*($C$27*$E$28)+(P9=$F$27)*($C$27*$F$28) -> 0 | Q27: =(Q9=$E$27)*($C$27*$E$28)+(Q9=$F$27)*($C$27*$F$28) -> 0 | R27: =(R9=$E$27)*($C$27*$E$28)+(R9=$F$27)*($C$27*$F$28) -> 0 | S27: =(S9=$E$27)*($C$27*$E$28)+(S9=$F$27)*($C$27*$F$28) -> 0 | ... BS27: =(BS9=$E$27)*($C$27*$E$28)+(BS9=$F$27)*($C$27*$F$28) -> 0
E28: 0.6 | F28: =1-E28 -> 0.4
B30: =Budget!B49 -> Taxes | C30: =SUM(L30:BS30) -> 10462655 | D30: Custom | E30: =Budget!C49 -> 0.01735 | I30: =IF(ROUND(C30,0)=ROUND(SUM(L30:BS30),0),"Ok","Error") -> Ok | L30: =AND(MONTH(L10)=3,L9<=Summary!$C$22)*(($K$13+SUM(MonthlyCF!$K$23:K23))*MonthlyCF!$E$30) -> 0 | M30: =AND(MONTH(M10)=3,M9<=Summary!$C$22)*(($K$13+SUM(MonthlyCF!$K$23:L23))*MonthlyCF!$E$30) -> 0 | N30: =AND(MONTH(N10)=3,N9<=Summary!$C$22)*(($K$13+SUM(MonthlyCF!$K$23:M23))*MonthlyCF!$E$30) -> 0 | O30: =AND(MONTH(O10)=3,O9<=Summary!$C$22)*(($K$13+SUM(MonthlyCF!$K$23:N23))*MonthlyCF!$E$30) -> 0 | P30: =AND(MONTH(P10)=3,P9<=Summary!$C$22)*(($K$13+SUM(MonthlyCF!$K$23:O23))*MonthlyCF!$E$30) -> 0 | Q30: =AND(MONTH(Q10)=3,Q9<=Summary!$C$22)*(($K$13+SUM(MonthlyCF!$K$23:P23))*MonthlyCF!$E$30) -> 0 | R30: =AND(MONTH(R10)=3,R9<=Summary!$C$22)*(($K$13+SUM(MonthlyCF!$K$23:Q23))*MonthlyCF!$E$30) -> 0 | S30: =AND(MONTH(S10)=3,S9<=Summary!$C$22)*(($K$13+SUM(MonthlyCF!$K$23:R23))*MonthlyCF!$E$30) -> 0 | ... BS30: =AND(MONTH(BS10)=3,BS9<=Summary!$C$22)*(($K$13+SUM(MonthlyCF!$K$23:BR23))*MonthlyCF!$E$30) -> 0
B32: =Budget!B51 -> Leasing and Marketing
B33: =Budget!B52 -> Leasing Commissions | C33: =Budget!E52 -> 3927025.2 | D33: Start of Lease | E33: =E25 -> 37 | I33: =IF(ROUND(C33,0)=ROUND(SUM(L33:BS33),0),"Ok","Error") -> Ok | L33: =(L$9=$E33)*$C33 -> 0 | M33: =(M$9=$E33)*$C33 -> 0 | N33: =(N$9=$E33)*$C33 -> 0 | O33: =(O$9=$E33)*$C33 -> 0 | P33: =(P$9=$E33)*$C33 -> 0 | Q33: =(Q$9=$E33)*$C33 -> 0 | R33: =(R$9=$E33)*$C33 -> 0 | S33: =(S$9=$E33)*$C33 -> 0 | ... BS33: =(BS$9=$E33)*$C33 -> 0
B34: =Budget!B53 -> Marketing | C34: =Budget!E53 -> 478242 | D34: Straight Line | E34: =E23 -> 13 | F34: =F23 -> 42 | G34: =F34-E34+1 -> 30 | H34: 1000000000 | I34: =IF(ROUND(C34,0)=ROUND(SUM(L34:BS34),0),"Ok","Error") -> Ok | L34: =(_xlfn.NORM.DIST((AND(L$9>=$E34,L$9<=$F34)*(L$9-$E34+1)),$G34/2,$H34,TRUE)-_xlfn.NORM.DIST((AND(L$9>=$E34,L$9<=$F34)*(K$9-$E34+1)),$G34/2,$H34,TRUE))/(1-2*_xlfn.NORM.DIST(0,$G34/2,$H34,TRUE))*$C34 -> 0 | M34: =(_xlfn.NORM.DIST((AND(M$9>=$E34,M$9<=$F34)*(M$9-$E34+1)),$G34/2,$H34,TRUE)-_xlfn.NORM.DIST((AND(M$9>=$E34,M$9<=$F34)*(L$9-$E34+1)),$G34/2,$H34,TRUE))/(1-2*_xlfn.NORM.DIST(0,$G34/2,$H34,TRUE))*$C34 -> 0 | N34: =(_xlfn.NORM.DIST((AND(N$9>=$E34,N$9<=$F34)*(N$9-$E34+1)),$G34/2,$H34,TRUE)-_xlfn.NORM.DIST((AND(N$9>=$E34,N$9<=$F34)*(M$9-$E34+1)),$G34/2,$H34,TRUE))/(1-2*_xlfn.NORM.DIST(0,$G34/2,$H34,TRUE))*$C34 -> 0 | O34: =(_xlfn.NORM.DIST((AND(O$9>=$E34,O$9<=$F34)*(O$9-$E34+1)),$G34/2,$H34,TRUE)-_xlfn.NORM.DIST((AND(O$9>=$E34,O$9<=$F34)*(N$9-$E34+1)),$G34/2,$H34,TRUE))/(1-2*_xlfn.NORM.DIST(0,$G34/2,$H34,TRUE))*$C34 -> 0 | P34: =(_xlfn.NORM.DIST((AND(P$9>=$E34,P$9<=$F34)*(P$9-$E34+1)),$G34/2,$H34,TRUE)-_xlfn.NORM.DIST((AND(P$9>=$E34,P$9<=$F34)*(O$9-$E34+1)),$G34/2,$H34,TRUE))/(1-2*_xlfn.NORM.DIST(0,$G34/2,$H34,TRUE))*$C34 -> 0 | Q34: =(_xlfn.NORM.DIST((AND(Q$9>=$E34,Q$9<=$F34)*(Q$9-$E34+1)),$G34/2,$H34,TRUE)-_xlfn.NORM.DIST((AND(Q$9>=$E34,Q$9<=$F34)*(P$9-$E34+1)),$G34/2,$H34,TRUE))/(1-2*_xlfn.NORM.DIST(0,$G34/2,$H34,TRUE))*$C34 -> 0 | R34: =(_xlfn.NORM.DIST((AND(R$9>=$E34,R$9<=$F34)*(R$9-$E34+1)),$G34/2,$H34,TRUE)-_xlfn.NORM.DIST((AND(R$9>=$E34,R$9<=$F34)*(Q$9-$E34+1)),$G34/2,$H34,TRUE))/(1-2*_xlfn.NORM.DIST(0,$G34/2,$H34,TRUE))*$C34 -> 0 | S34: =(_xlfn.NORM.DIST((AND(S$9>=$E34,S$9<=$F34)*(S$9-$E34+1)),$G34/2,$H34,TRUE)-_xlfn.NORM.DIST((AND(S$9>=$E34,S$9<=$F34)*(R$9-$E34+1)),$G34/2,$H34,TRUE))/(1-2*_xlfn.NORM.DIST(0,$G34/2,$H34,TRUE))*$C34 -> 0 | ... BS34: =(_xlfn.NORM.DIST((AND(BS$9>=$E34,BS$9<=$F34)*(BS$9-$E34+1)),$G34/2,$H34,TRUE)-_xlfn.NORM.DIST((AND(BS$9>=$E34,BS$9<=$F34)*(BR$9-$E34+1)),$G34/2,$H34,TRUE))/(1-2*_xlfn.NORM.DIST(0,$G34/2,$H34,TRUE))*$C34 -> 0
B36: =Budget!B56 -> Development Fee | C36: =Budget!E19 -> 6195181.9 | D36: Straight Line | E36: 1 | F36: =Summary!E19 -> 42 | G36: =F36-E36+1 -> 42 | H36: 1000000000 | I36: =IF(ROUND(C36,0)=ROUND(SUM(L36:BS36),0),"Ok","Error") -> Ok | L36: =(_xlfn.NORM.DIST((AND(L$9>=$E36,L$9<=$F36)*(L$9-$E36+1)),$G36/2,$H36,TRUE)-_xlfn.NORM.DIST((AND(L$9>=$E36,L$9<=$F36)*(K$9-$E36+1)),$G36/2,$H36,TRUE))/(1-2*_xlfn.NORM.DIST(0,$G36/2,$H36,TRUE))*$C36 -> 147504.35 | M36: =(_xlfn.NORM.DIST((AND(M$9>=$E36,M$9<=$F36)*(M$9-$E36+1)),$G36/2,$H36,TRUE)-_xlfn.NORM.DIST((AND(M$9>=$E36,M$9<=$F36)*(L$9-$E36+1)),$G36/2,$H36,TRUE))/(1-2*_xlfn.NORM.DIST(0,$G36/2,$H36,TRUE))*$C36 -> 147504.33 | N36: =(_xlfn.NORM.DIST((AND(N$9>=$E36,N$9<=$F36)*(N$9-$E36+1)),$G36/2,$H36,TRUE)-_xlfn.NORM.DIST((AND(N$9>=$E36,N$9<=$F36)*(M$9-$E36+1)),$G36/2,$H36,TRUE))/(1-2*_xlfn.NORM.DIST(0,$G36/2,$H36,TRUE))*$C36 -> 147504.33 | O36: =(_xlfn.NORM.DIST((AND(O$9>=$E36,O$9<=$F36)*(O$9-$E36+1)),$G36/2,$H36,TRUE)-_xlfn.NORM.DIST((AND(O$9>=$E36,O$9<=$F36)*(N$9-$E36+1)),$G36/2,$H36,TRUE))/(1-2*_xlfn.NORM.DIST(0,$G36/2,$H36,TRUE))*$C36 -> 147504.33 | P36: =(_xlfn.NORM.DIST((AND(P$9>=$E36,P$9<=$F36)*(P$9-$E36+1)),$G36/2,$H36,TRUE)-_xlfn.NORM.DIST((AND(P$9>=$E36,P$9<=$F36)*(O$9-$E36+1)),$G36/2,$H36,TRUE))/(1-2*_xlfn.NORM.DIST(0,$G36/2,$H36,TRUE))*$C36 -> 147504.33 | Q36: =(_xlfn.NORM.DIST((AND(Q$9>=$E36,Q$9<=$F36)*(Q$9-$E36+1)),$G36/2,$H36,TRUE)-_xlfn.NORM.DIST((AND(Q$9>=$E36,Q$9<=$F36)*(P$9-$E36+1)),$G36/2,$H36,TRUE))/(1-2*_xlfn.NORM.DIST(0,$G36/2,$H36,TRUE))*$C36 -> 147504.35 | R36: =(_xlfn.NORM.DIST((AND(R$9>=$E36,R$9<=$F36)*(R$9-$E36+1)),$G36/2,$H36,TRUE)-_xlfn.NORM.DIST((AND(R$9>=$E36,R$9<=$F36)*(Q$9-$E36+1)),$G36/2,$H36,TRUE))/(1-2*_xlfn.NORM.DIST(0,$G36/2,$H36,TRUE))*$C36 -> 147504.33 | S36: =(_xlfn.NORM.DIST((AND(S$9>=$E36,S$9<=$F36)*(S$9-$E36+1)),$G36/2,$H36,TRUE)-_xlfn.NORM.DIST((AND(S$9>=$E36,S$9<=$F36)*(R$9-$E36+1)),$G36/2,$H36,TRUE))/(1-2*_xlfn.NORM.DIST(0,$G36/2,$H36,TRUE))*$C36 -> 147504.33 | ... BS36: =(_xlfn.NORM.DIST((AND(BS$9>=$E36,BS$9<=$F36)*(BS$9-$E36+1)),$G36/2,$H36,TRUE)-_xlfn.NORM.DIST((AND(BS$9>=$E36,BS$9<=$F36)*(BR$9-$E36+1)),$G36/2,$H36,TRUE))/(1-2*_xlfn.NORM.DIST(0,$G36/2,$H36,TRUE))*$C36 -> 0
C38: =Budget!E20 -> 10150536 | D38: Steady Growth Formula | E38: =F38-10+1 -> 33 | F38: =F36 -> 42 | G38: =F38-E38+1 -> 10 | I38: =IF(ROUND(C38,0)=ROUND(SUM(L38:BS38),0),"Ok","Error") -> Ok | L38: =AND(L$9>=$E38,L$9<=$F38)*((L$9-$E38+1)/($G38*($G38+1)/2)*$C38) -> 0 | M38: =AND(M$9>=$E38,M$9<=$F38)*((M$9-$E38+1)/($G38*($G38+1)/2)*$C38) -> 0 | N38: =AND(N$9>=$E38,N$9<=$F38)*((N$9-$E38+1)/($G38*($G38+1)/2)*$C38) -> 0 | O38: =AND(O$9>=$E38,O$9<=$F38)*((O$9-$E38+1)/($G38*($G38+1)/2)*$C38) -> 0 | P38: =AND(P$9>=$E38,P$9<=$F38)*((P$9-$E38+1)/($G38*($G38+1)/2)*$C38) -> 0 | Q38: =AND(Q$9>=$E38,Q$9<=$F38)*((Q$9-$E38+1)/($G38*($G38+1)/2)*$C38) -> 0 | R38: =AND(R$9>=$E38,R$9<=$F38)*((R$9-$E38+1)/($G38*($G38+1)/2)*$C38) -> 0 | S38: =AND(S$9>=$E38,S$9<=$F38)*((S$9-$E38+1)/($G38*($G38+1)/2)*$C38) -> 0 | ... BS38: =AND(BS$9>=$E38,BS$9<=$F38)*((BS$9-$E38+1)/($G38*($G38+1)/2)*$C38) -> 0
B39: Total Development Costs - Pre-Financing | C39: =SUM(C13:C38) -> 2.8692518e+08 | I39: =IF(ROUND(C39,0)=ROUND(SUM(K39:BS39),0),"Ok","Error") -> Ok | K39: =SUM(K13:K38) -> 67568742 | L39: =SUM(L13:L38) -> 147504.35 | M39: =SUM(M13:M38) -> 391014.24 | N39: =SUM(N13:N38) -> 438864.08 | O39: =SUM(O13:O38) -> 1464595.5 | P39: =SUM(P13:P38) -> 517599.44 | Q39: =SUM(Q13:Q38) -> 540406.39 | R39: =SUM(R13:R38) -> 548316.83 | ... BS39: =SUM(BS13:BS38) -> 0
B40: Fees | C40: =SUM(K40:BS40) -> 1745641 | K40: =K62 -> 0 | L40: =L62 -> 0 | M40: =M62 -> 0 | N40: =N62 -> 0 | O40: =O62 -> 0 | P40: =P62 -> 0 | Q40: =Q62 -> 0 | R40: =R62 -> 0 | ... BS40: =BS62 -> 0
B41: Interest Reserve | C41: =SUM(K41:BS41) -> 11116203 | K41: =K63 -> 0 | L41: =L63 -> 0 | M41: =M63 -> 0 | N41: =N63 -> 0 | O41: =O63 -> 0 | P41: =P63 -> 0 | Q41: =Q63 -> 0 | R41: =R63 -> 0 | ... BS41: =BS63 -> -8.841753e-11
B42: Total Development Costs - W/ Interest Reserve and Fees | C42: =SUM(K42:BS42) -> 2.9978702e+08 | K42: =SUM(K39:K41) -> 67568742 | L42: =SUM(L39:L41) -> 147504.35 | M42: =SUM(M39:M41) -> 391014.24 | N42: =SUM(N39:N41) -> 438864.08 | O42: =SUM(O39:O41) -> 1464595.5 | P42: =SUM(P39:P41) -> 517599.44 | Q42: =SUM(Q39:Q41) -> 540406.39 | R42: =SUM(R39:R41) -> 548316.83 | ... BS42: =SUM(BS39:BS41) -> -8.841753e-11
B44: Draw Schedule
B45: Equity
C46: Beginning Balance | K46: =Summary!M45 -> 1.1991479e+08 | L46: =K48 -> 52346053 | M46: =L48 -> 52198548 | N46: =M48 -> 51807534 | O46: =N48 -> 51368670 | P46: =O48 -> 49904074 | Q46: =P48 -> 49386475 | R46: =Q48 -> 48846068 | S46: =R48 -> 48297752 | ... BS46: =BR48 -> 0
C47: Equity Required | I47: =IF(ROUND(Summary!M45,0)=ROUND(SUM(K47:BS47),0),"Ok","Error") -> Ok | K47: =MIN(K39,K46) -> 67568742 | L47: =MIN(L39,L46) -> 147504.35 | M47: =MIN(M39,M46) -> 391014.24 | N47: =MIN(N39,N46) -> 438864.08 | O47: =MIN(O39,O46) -> 1464595.5 | P47: =MIN(P39,P46) -> 517599.44 | Q47: =MIN(Q39,Q46) -> 540406.39 | R47: =MIN(R39,R46) -> 548316.83 | ... BS47: =MIN(BS39,BS46) -> 0
C48: Ending Balance | K48: =K46-K47 -> 52346053 | L48: =L46-L47 -> 52198548 | M48: =M46-M47 -> 51807534 | N48: =N46-N47 -> 51368670 | O48: =O46-O47 -> 49904074 | P48: =P46-P47 -> 49386475 | Q48: =Q46-Q47 -> 48846068 | R48: =R46-R47 -> 48297752 | ... BS48: =BS46-BS47 -> 0
C49: Cumulative Costs | K49: =SUM($K$47:K47) -> 67568742 | L49: =SUM($K$47:L47) -> 67716247 | M49: =SUM($K$47:M47) -> 68107261 | N49: =SUM($K$47:N47) -> 68546125 | O49: =SUM($K$47:O47) -> 70010720 | P49: =SUM($K$47:P47) -> 70528320 | Q49: =SUM($K$47:Q47) -> 71068726 | R49: =SUM($K$47:R47) -> 71617043 | ... BS49: =SUM($K$47:BS47) -> 1.1991479e+08
B50: Debt
B51: Debt Pre-Interest Reserve | C51: Beginning Balance | K51: =Summary!M46 -> 1.6701038e+08 | L51: =K53 -> 1.6701038e+08 | M51: =L53 -> 1.6701038e+08 | N51: =M53 -> 1.6701038e+08 | O51: =N53 -> 1.6701038e+08 | P51: =O53 -> 1.6701038e+08 | Q51: =P53 -> 1.6701038e+08 | R51: =Q53 -> 1.6701038e+08 | S51: =R53 -> 1.6701038e+08 | ... BS51: =BR53 -> 1.7695129e-08
C52: Debt Funded | I52: =IF(ROUND(Summary!M46,0)=ROUND(SUM(K52:BS52),0),"Ok","Error") -> Ok | K52: =MIN(K39-K47,K51) -> 0 | L52: =MIN(L39-L47,L51) -> 0 | M52: =MIN(M39-M47,M51) -> 0 | N52: =MIN(N39-N47,N51) -> 0 | O52: =MIN(O39-O47,O51) -> 0 | P52: =MIN(P39-P47,P51) -> 0 | Q52: =MIN(Q39-Q47,Q51) -> 0 | R52: =MIN(R39-R47,R51) -> 0 | ... BS52: =MIN(BS39-BS47,BS51) -> 0
C53: Ending Balance | K53: =K51-K52 -> 1.6701038e+08 | L53: =L51-L52 -> 1.6701038e+08 | M53: =M51-M52 -> 1.6701038e+08 | N53: =N51-N52 -> 1.6701038e+08 | O53: =O51-O52 -> 1.6701038e+08 | P53: =P51-P52 -> 1.6701038e+08 | Q53: =Q51-Q52 -> 1.6701038e+08 | R53: =R51-R52 -> 1.6701038e+08 | ... BS53: =BS51-BS52 -> 1.7695129e-08
C54: Loan Repayment | K54: =(K68>0)*MIN(K70,J55+K52+J63+K63) -> 0 | L54: =(L68>0)*MIN(L70,K55+L52+K63+L63) -> 0 | M54: =(M68>0)*MIN(M70,L55+M52+L63+M63) -> 0 | N54: =(N68>0)*MIN(N70,M55+N52+M63+N63) -> 0 | O54: =(O68>0)*MIN(O70,N55+O52+N63+O63) -> 0 | P54: =(P68>0)*MIN(P70,O55+P52+O63+P63) -> 0 | Q54: =(Q68>0)*MIN(Q70,P55+Q52+P63+Q63) -> 0 | R54: =(R68>0)*MIN(R70,Q55+R52+Q63+R63) -> 0 | ... BS54: =(BS68>0)*MIN(BS70,BR55+BS52+BR63+BS63) -> 0
B55: Debt w/ Interest Reserve & Fees | C55: Cumulative Balance | K55: =SUM($K$52:K52)-SUM($K$54:K54)+SUM($J$62:J63)+(K54>0)*K63 -> 0 | L55: =SUM($K$52:L52)-SUM($K$54:L54)+SUM($J$62:K63)+(L54>0)*L63 -> 0 | M55: =SUM($K$52:M52)-SUM($K$54:M54)+SUM($J$62:L63)+(M54>0)*M63 -> 0 | N55: =SUM($K$52:N52)-SUM($K$54:N54)+SUM($J$62:M63)+(N54>0)*N63 -> 0 | O55: =SUM($K$52:O52)-SUM($K$54:O54)+SUM($J$62:N63)+(O54>0)*O63 -> 0 | P55: =SUM($K$52:P52)-SUM($K$54:P54)+SUM($J$62:O63)+(P54>0)*P63 -> 0 | Q55: =SUM($K$52:Q52)-SUM($K$54:Q54)+SUM($J$62:P63)+(Q54>0)*Q63 -> 0 | R55: =SUM($K$52:R52)-SUM($K$54:R54)+SUM($J$62:Q63)+(R54>0)*R63 -> 0 | ... BS55: =SUM($K$52:BS52)-SUM($K$54:BS54)+SUM($J$62:BR63)+(BS54>0)*BS63 -> -2.2351742e-08
B56: Interest Rate Details | C56: Ceiling | K56: =Summary!$M$52 -> 0.065 | L56: =Summary!$M$52 -> 0.065 | M56: =Summary!$M$52 -> 0.065 | N56: =Summary!$M$52 -> 0.065 | O56: =Summary!$M$52 -> 0.065 | P56: =Summary!$M$52 -> 0.065 | Q56: =Summary!$M$52 -> 0.065 | R56: =Summary!$M$52 -> 0.065 | ... BS56: =Summary!$M$52 -> 0.065
C57: 1-Month USD LIBOR | K57: 0.02477 | L57: 0.0245929 | M57: 0.0243668 | N57: 0.024065 | O57: 0.0237817 | P57: 0.0234701 | Q57: 0.0231968 | R57: 0.0229124 | S57: 0.0225658 | T57: 0.0222239 | U57: 0.0218995 | V57: 0.021546 | W57: 0.0212191 | X57: 0.0209753 | Y57: 0.0207156 | Z57: 0.0205182 | AA57: 0.0203591 | AB57: 0.020223 | AC57: 0.0201385 | AD57: 0.0200874 | AE57: 0.020049 | AF57: 0.0200386 | AG57: 0.020046 | AH57: 0.0200414 | AI57: 0.0200471 | AJ57: 0.0200626 | AK57: 0.0200657 | AL57: 0.0200808 | AM57: 0.0201112 | AN57: 0.0201374 | AO57: 0.0201718 | AP57: 0.0202325 | AQ57: 0.0202816 | AR57: 0.0203446 | AS57: 0.0204194 | AT57: 0.0204793 | AU57: 0.0205449 | AV57: 0.0206213 | AW57: 0.0206855 | AX57: 0.0207474 | AY57: 0.0208178 | AZ57: 0.0208713 | BA57: 0.0209279 | BB57: 0.0209924 | BC57: 0.021034 | BD57: 0.0210828 | BE57: 0.0211441 | BF57: 0.0211988 | BG57: 0.0212621 | BH57: 0.0213458 | BI57: 0.0214177 | BJ57: 0.021515 | BK57: 0.0216204 | BL57: 0.0217117 | BM57: 0.0218183 | BN57: 0.021946 | BO57: 0.0220422 | BP57: 0.0221525 | BQ57: 0.022275 | BR57: 0.0223605 | BS57: 0.0224688 | BU57: 0.0226564 | BV57: 0.0227491 | BW57: 0.0228406 | BX57: 0.022917 | BY57: 0.0229929 | BZ57: 0.0230763 | CA57: 0.0231428 | CB57: 0.0232118 | CC57: 0.0232863 | CD57: 0.0233467 | CE57: 0.023418 | CF57: 0.023494 | CG57: 0.02356 | CH57: 0.023639 | CI57: 0.0237142 | CJ57: 0.0237852 | CK57: 0.0238608 | CL57: 0.023948 | CM57: 0.0240168 | CN57: 0.0240915 | CO57: 0.0241719 | CP57: 0.0242414 | CQ57: 0.0243233 | CR57: 0.0244006 | CS57: 0.0244731 | CT57: 0.0245504 | CU57: 0.0246405 | CV57: 0.0247123 | CW57: 0.024788 | CX57: 0.0248804 | CY57: 0.0249491 | CZ57: 0.025025 | DA57: 0.0251138 | DB57: 0.0251812 | DC57: 0.0252547 | DD57: 0.0253402 | DE57: 0.0254087 | DF57: 0.0254839 | DG57: 0.0255726 | DH57: 0.0256496 | DI57: 0.0257186 | DJ57: 0.0258146 | DK57: 0.0258852 | DL57: 0.0259631 | DM57: 0.0260475 | DN57: 0.026115 | DO57: 0.0261781 | DP57: 0.0262483 | DQ57: 0.0262966 | DR57: 0.026352 | DS57: 0.0264031 | DT57: 0.0264301 | DU57: 0.0264563 | DV57: 0.0264802 | DW57: 0.0264791 | DX57: 0.0264807
...

Sheet OpProj
B6: Operating Projections
C9: MODELING LONG-TERM LEASES
C11: INCOME
C12: Parking Growth | E12: =Summary!G41 -> 0.025
C13: OpEx Growth | E13: 0.02 | J13: 1 | K13: 1 | L13: 1 | M13: 1 | N13: 1 | O13: 1 | P13: 1 | Q13: 1 | R13: 1 | S13: 1 | T13: 1 | U13: 1 | V13: 2 | W13: 2 | X13: 2 | Y13: 2 | Z13: 2 | AA13: 2 | AB13: 2 | AC13: 2 | AD13: 2 | AE13: 2 | AF13: 2 | AG13: 2 | AH13: 3 | AI13: 3 | AJ13: 3 | AK13: 3 | AL13: 3 | AM13: 3 | AN13: 3 | AO13: 3 | AP13: 3 | AQ13: 3 | AR13: 3 | AS13: 3 | AT13: 4 | AU13: 4 | AV13: 4 | AW13: 4 | AX13: 4 | AY13: 4 | AZ13: 4 | BA13: 4 | BB13: 4 | BC13: 4 | BD13: 4 | BE13: 4 | BF13: 5 | BG13: 5 | BH13: 5 | BI13: 5 | BJ13: 5 | BK13: 5 | BL13: 5 | BM13: 5 | BN13: 5 | BO13: 5 | BP13: 5 | BQ13: 5 | BR13: 6 | BS13: 6 | BT13: 6 | BU13: 6 | BV13: 6 | BW13: 6 | BX13: 6 | BY13: 6 | BZ13: 6 | CA13: 6 | CB13: 6 | CC13: 6 | CD13: 7 | CE13: 7 | CF13: 7 | CG13: 7 | CH13: 7 | CI13: 7 | CJ13: 7 | CK13: 7 | CL13: 7 | CM13: 7 | CN13: 7 | CO13: 7 | CP13: 8 | CQ13: 8 | CR13: 8 | CS13: 8 | CT13: 8 | CU13: 8 | CV13: 8 | CW13: 8 | CX13: 8 | CY13: 8 | CZ13: 8 | DA13: 8 | DB13: 9 | DC13: 9 | DD13: 9 | DE13: 9 | DF13: 9 | DG13: 9 | DH13: 9 | DI13: 9 | DJ13: 9 | DK13: 9 | DL13: 9 | DM13: 9 | DN13: 10 | DO13: 10 | DP13: 10 | DQ13: 10 | DR13: 10 | DS13: 10 | DT13: 10 | DU13: 10 | DV13: 10 | DW13: 10 | DX13: 10 | DY13: 10 | DZ13: 11 | EA13: 11 | EB13: 11 | EC13: 11 | ED13: 11 | EE13: 11 | EF13: 11 | EG13: 11 | EH13: 11 | EI13: 11 | EJ13: 11 | EK13: 11
J14: =Summary!F21 -> 44713 | K14: =EDATE(J14,1) -> 44743 | L14: =EDATE(K14,1) -> 44774 | M14: =EDATE(L14,1) -> 44805 | N14: =EDATE(M14,1) -> 44835 | O14: =EDATE(N14,1) -> 44866 | P14: =EDATE(O14,1) -> 44896 | Q14: =EDATE(P14,1) -> 44927 | R14: =EDATE(Q14,1) -> 44958 | ... EK14: =EDATE(EJ14,1) -> 48700
J15: =ROUNDUP(J16/12,0) -> 4 | K15: =ROUNDUP(K16/12,0) -> 4 | L15: =ROUNDUP(L16/12,0) -> 4 | M15: =ROUNDUP(M16/12,0) -> 4 | N15: =ROUNDUP(N16/12,0) -> 4 | O15: =ROUNDUP(O16/12,0) -> 4 | P15: =ROUNDUP(P16/12,0) -> 4 | Q15: =ROUNDUP(Q16/12,0) -> 4 | ... EK15: =ROUNDUP(EK16/12,0) -> 14
H16: Pro Forma | J16: =Summary!C21 -> 37 | K16: =J16+1 -> 38 | L16: =K16+1 -> 39 | M16: =L16+1 -> 40 | N16: =M16+1 -> 41 | O16: =N16+1 -> 42 | P16: =O16+1 -> 43 | Q16: =P16+1 -> 44 | R16: =Q16+1 -> 45 | ... EK16: =EJ16+1 -> 168
C17: Potential Base Rent | H17: =SUM(J17:U17) -> 17127820 | J17: =(Summary!$G$29*Summary!$M$33)/12*(1+Summary!$G$30)^(OpProj!J15-1) -> 1427318.3 | K17: =(Summary!$G$29*Summary!$M$33)/12*(1+Summary!$G$30)^(OpProj!K15-1) -> 1427318.3 | L17: =(Summary!$G$29*Summary!$M$33)/12*(1+Summary!$G$30)^(OpProj!L15-1) -> 1427318.3 | M17: =(Summary!$G$29*Summary!$M$33)/12*(1+Summary!$G$30)^(OpProj!M15-1) -> 1427318.3 | N17: =(Summary!$G$29*Summary!$M$33)/12*(1+Summary!$G$30)^(OpProj!N15-1) -> 1427318.3 | O17: =(Summary!$G$29*Summary!$M$33)/12*(1+Summary!$G$30)^(OpProj!O15-1) -> 1427318.3 | P17: =(Summary!$G$29*Summary!$M$33)/12*(1+Summary!$G$30)^(OpProj!P15-1) -> 1427318.3 | Q17: =(Summary!$G$29*Summary!$M$33)/12*(1+Summary!$G$30)^(OpProj!Q15-1) -> 1427318.3 | ... EK17: =(Summary!$G$29*Summary!$M$33)/12*(1+Summary!$G$30)^(OpProj!EK15-1) -> 1918196.5
C18: - Concessions | H18: =SUM(J18:M18) -> -5709273.3 | J18: =(J16<Summary!$G$32+Summary!$C$27)*-OpProj!J17 -> -1427318.3 | K18: =(K16<Summary!$G$32+Summary!$C$27)*-OpProj!K17 -> -1427318.3 | L18: =(L16<Summary!$G$32+Summary!$C$27)*-OpProj!L17 -> -1427318.3 | M18: =(M16<Summary!$G$32+Summary!$C$27)*-OpProj!M17 -> -1427318.3 | N18: =(N16<Summary!$G$32+Summary!$C$27)*-OpProj!N17 -> -1427318.3 | O18: =(O16<Summary!$G$32+Summary!$C$27)*-OpProj!O17 -> -1427318.3 | P18: =(P16<Summary!$G$32+Summary!$C$27)*-OpProj!P17 -> 0 | Q18: =(Q16<Summary!$G$32+Summary!$C$27)*-OpProj!Q17 -> 0 | ... EK18: =(EK16<Summary!$G$32+Summary!$C$27)*-OpProj!EK17 -> 0
C19: Total Rental Revenue | H19: =SUM(H17:H18) -> 11418547 | J19: =SUM(J17:J18) -> 0 | K19: =SUM(K17:K18) -> 0 | L19: =SUM(L17:L18) -> 0 | M19: =SUM(M17:M18) -> 0 | N19: =SUM(N17:N18) -> 0 | O19: =SUM(O17:O18) -> 0 | P19: =SUM(P17:P18) -> 1427318.3 | Q19: =SUM(Q17:Q18) -> 1427318.3 | ... EK19: =SUM(EK17:EK18) -> 1918196.5
C20: Reimbursement Income | G20: 1 | H20: =+G20*H26 -> 1780240 | J20: =J26*$G$20 -> 157433.74 | K20: =K26*$G$20 -> 157433.74 | L20: =L26*$G$20 -> 157433.74 | M20: =M26*$G$20 -> 157433.74 | N20: =N26*$G$20 -> 157433.74 | O20: =O26*$G$20 -> 157433.74 | P20: =P26*$G$20 -> 157433.74 | Q20: =Q26*$G$20 -> 157433.74 | ... EK20: =EK26*$G$20 -> 191910.86
C21: Parking Income | H21: =Summary!G39*Summary!G40*12 -> 249000 | J21: =$H$21/12*(1+$E$12)^(J$15-1) -> 22345.48 | K21: =$H$21/12*(1+$E$12)^(K$15-1) -> 22345.48 | L21: =$H$21/12*(1+$E$12)^(L$15-1) -> 22345.48 | M21: =$H$21/12*(1+$E$12)^(M$15-1) -> 22345.48 | N21: =$H$21/12*(1+$E$12)^(N$15-1) -> 22345.48 | O21: =$H$21/12*(1+$E$12)^(O$15-1) -> 22345.48 | P21: =$H$21/12*(1+$E$12)^(P$15-1) -> 22345.48 | Q21: =$H$21/12*(1+$E$12)^(Q$15-1) -> 22345.48 | ... EK21: =$H$21/12*(1+$E$12)^(EK$15-1) -> 28604.104
C22: Gross Revenue | H22: =SUM(H18:H21) -> 7738513.3 | J22: =SUM(J19:J21) -> 179779.22 | K22: =SUM(K19:K21) -> 179779.22 | L22: =SUM(L19:L21) -> 179779.22 | M22: =SUM(M19:M21) -> 179779.22 | N22: =SUM(N19:N21) -> 179779.22 | O22: =SUM(O19:O21) -> 179779.22 | P22: =SUM(P19:P21) -> 1607097.6 | Q22: =SUM(Q19:Q21) -> 1607097.6 | ... EK22: =SUM(EK19:EK21) -> 2138711.4
C23: - General Vacancy and Credit Loss | G23: 0 | H23: =+-G23*H22 -> 0 | J23: =-$G$23*J22 -> 0 | K23: =-$G$23*K22 -> 0 | L23: =-$G$23*L22 -> 0 | M23: =-$G$23*M22 -> 0 | N23: =-$G$23*N22 -> 0 | O23: =-$G$23*O22 -> 0 | P23: =-$G$23*P22 -> 0 | Q23: =-$G$23*Q22 -> 0 | ... EK23: =-$G$23*EK22 -> 0
C24: Total Effective Gross Revenue | H24: =SUM(H22:H23) -> 7738513.3 | J24: =SUM(J22:J23) -> 179779.22 | K24: =SUM(K22:K23) -> 179779.22 | L24: =SUM(L22:L23) -> 179779.22 | M24: =SUM(M22:M23) -> 179779.22 | N24: =SUM(N22:N23) -> 179779.22 | O24: =SUM(O22:O23) -> 179779.22 | P24: =SUM(P22:P23) -> 1607097.6 | Q24: =SUM(Q22:Q23) -> 1607097.6 | ... EK24: =SUM(EK22:EK23) -> 2138711.4
C26: Operating Expenses | H26: 1780240 | J26: =$H$26/12*(1+$E$13)^(J$15-1) -> 157433.74 | K26: =$H$26/12*(1+$E$13)^(K$15-1) -> 157433.74 | L26: =$H$26/12*(1+$E$13)^(L$15-1) -> 157433.74 | M26: =$H$26/12*(1+$E$13)^(M$15-1) -> 157433.74 | N26: =$H$26/12*(1+$E$13)^(N$15-1) -> 157433.74 | O26: =$H$26/12*(1+$E$13)^(O$15-1) -> 157433.74 | P26: =$H$26/12*(1+$E$13)^(P$15-1) -> 157433.74 | Q26: =$H$26/12*(1+$E$13)^(Q$15-1) -> 157433.74 | ... EK26: =$H$26/12*(1+$E$13)^(EK$15-1) -> 191910.86
C27: Net Operating Income | H27: =H24-H26 -> 5958273.3 | J27: =+J24-J26 -> 22345.48 | K27: =+K24-K26 -> 22345.48 | L27: =+L24-L26 -> 22345.48 | M27: =+M24-M26 -> 22345.48 | N27: =+N24-N26 -> 22345.48 | O27: =+O24-O26 -> 22345.48 | P27: =+P24-P26 -> 1449663.8 | Q27: =+Q24-Q26 -> 1449663.8 | ... EK27: =+EK24-EK26 -> 1946800.6
C29: Sale Price | H29: =SUM(J29:EK29) -> 3.9718057e+08 | J29: =(J16=Summary!$C$22)*SUM(OpProj!J27:U27)/Summary!$G$43 -> 0 | K29: =(K16=Summary!$C$22)*SUM(OpProj!K27:V27)/Summary!$G$43 -> 0 | L29: =(L16=Summary!$C$22)*SUM(OpProj!L27:W27)/Summary!$G$43 -> 0 | M29: =(M16=Summary!$C$22)*SUM(OpProj!M27:X27)/Summary!$G$43 -> 0 | N29: =(N16=Summary!$C$22)*SUM(OpProj!N27:Y27)/Summary!$G$43 -> 0 | O29: =(O16=Summary!$C$22)*SUM(OpProj!O27:Z27)/Summary!$G$43 -> 0 | P29: =(P16=Summary!$C$22)*SUM(OpProj!P27:AA27)/Summary!$G$43 -> 0 | Q29: =(Q16=Summary!$C$22)*SUM(OpProj!Q27:AB27)/Summary!$G$43 -> 0 | ... EK29: =(EK16=Summary!$C$22)*SUM(OpProj!EK27:EV27)/Summary!$G$43 -> 0
C31: [Note: Leasing Commissions and Tenant Improvements are part of the development budget and so we are accounting for that there.]
