Workbook

Sheet Cover Page
B6: A.CRE Accelerator - Development Model Template

Sheet Summary
B6: Summary
B8: General Summary | I8: Project Returns | J8: Average Development Yield - 5 Years | K8: Profit | L8: IRR | M8: Equity Multiple
B9: Project | G9: Parcel 32 | I9: Total Project Unlevered | J9: =SUMIF(OpProj!$J$12:$EK$12,"<="&5,OpProj!$J$27:$EK$27)/5/K13 -> 0.071713305 | K9: =MonthlyCF!C77 -> 57767053 | L9: =MonthlyCF!C78 -> 0.17884137 | M9: =MonthlyCF!C79 -> 1.4355907
B10: Location | G10: Anytown, XX | I10: Total Project Levered
B11: Model Version | G11: 1
I12: Sources & Uses | J12: % | K12: Total | L12: Per GSF | M12: Per RSF
B13: Timing | C13: Start Month | D13: Duration (months) | E13: End month | F13: Start Date | G13: End Date | I13: Sources | J13: =K13/$K$13 -> 1 | K13: =SUM(K14:K15) -> 1.3264161e+08 | L13: =SUM(L14:L15) -> 638.43673 | M13: =SUM(M14:M15) -> 1026.7205
B14: Development | I14: Equity | J14: =K14/$K$13 -> 1 | K14: =M45 -> 1.3264161e+08 | L14: =K14/M32 -> 638.43673 | M14: =K14/M33 -> 1026.7205
B15: Analysis Start | C15: 1 | D15: 1 | E15: =C15+D15-1 -> 1 | F15: 43497 | G15: =EDATE(F15,D15-1) -> 43497 | I15: Debt
B16: Acquisition | C16: 0 | D16: 1 | E16: =C16+D16-1 -> 0 | F16: =EDATE(F15,-1) -> 43466 | G16: =EDATE(F16,D16-1) -> 43466 | I16: Uses | J16: =K16/$K$16 -> 1 | K16: =SUM(K17:K27) -> 1.3264161e+08 | L16: =SUM(L17:L27) -> 638.43673 | M16: =SUM(M17:M27) -> 1026.7205
B17: Entitlement Phase | C17: 2 | D17: 9 | E17: =C17+D17-1 -> 10 | F17: =INDEX(MonthlyCF!$J$10:$BR$10,MATCH(Summary!C17,MonthlyCF!$J$9:$BR$9,0)) -> 43525 | G17: =EDATE(F17,D17-1) -> 43770 | I17: =Budget!B11 -> Land | J17: =Budget!D11 -> 0.23127321 | K17: =Budget!E11 -> 30676452 | L17: =Budget!F11 -> 147.65331 | M17: =Budget!G11 -> 237.45295
B18: Design/Buyout | C18: 2 | D18: 15 | E18: =C18+D18-1 -> 16 | F18: =INDEX(MonthlyCF!$J$10:$BR$10,MATCH(Summary!C18,MonthlyCF!$J$9:$BR$9,0)) -> 43525 | G18: =EDATE(F18,D18-1) -> 43952 | I18: =Budget!B12 -> Entitlement Costs | J18: =Budget!D12 -> 0.0022918901 | K18: =Budget!E12 -> 304000 | L18: =Budget!F12 -> 1.4632268 | M18: =Budget!G12 -> 2.3531306
B19: Construction | C19: 16 | D19: 24 | E19: =C19+D19-1 -> 39 | F19: =INDEX(MonthlyCF!$J$10:$BR$10,MATCH(Summary!C19,MonthlyCF!$J$9:$BR$9,0)) -> 43952 | G19: =EDATE(F19,D19-1) -> 44652 | I19: =Budget!B13 -> A&E | J19: =Budget!D13 -> 0.016446422 | K19: =Budget!E13 -> 2181480 | L19: =Budget!F13 -> 10.5 | M19: =Budget!G13 -> 16.885879
B20: Lease Up and Exit | I20: =Budget!B14 -> Construction | J20: =Budget!D14 -> 0.58737223 | K20: =Budget!E14 -> 77910000 | L20: =Budget!F14 -> 375 | M20: =Budget!G14 -> 603.06712
B21: Occupancy | C21: =E19 -> 39 | D21: 1 | E21: =C21+D21-1 -> 39 | F21: =INDEX(MonthlyCF!$J$10:$BR$10,MATCH(Summary!C21,MonthlyCF!$J$9:$BR$9,0)) -> 44652 | G21: =EDATE(F21,D21-1) -> 44652 | I21: =Budget!B15 -> Tenant Improvements | J21: =Budget!D15 -> 0.063308367 | K21: =Budget!E15 -> 8397324 | L21: =Budget!F15 -> 40.418387 | M21: =Budget!G15 -> 65
B22: Exit | C22: =C21+8 -> 47 | D22: 1 | E22: =C22+D22-1 -> 47 | F22: =INDEX(MonthlyCF!$J$10:$BR$10,MATCH(Summary!C22,MonthlyCF!$J$9:$BR$9,0)) -> 44896 | G22: =EDATE(F22,D22-1) -> 44896 | I22: =Budget!B16 -> Permits | J22: =Budget!D16 -> 0.0058737223 | K22: =Budget!E16 -> 779100 | L22: =Budget!F16 -> 3.75 | M22: =Budget!G16 -> 6.0306712
B23: Total | D23: =DATEDIF(F23,G23,"m")+1 -> 47 | F23: =F15 -> 43497 | G23: =MAX(G15:G22) -> 44896 | I23: =Budget!B17 -> Taxes | J23: =Budget!D17 -> 0.021779758 | K23: =Budget!E17 -> 2888902.2 | L23: =Budget!F17 -> 13.904997 | M23: =Budget!G17 -> 22.361724
I24: =Budget!B18 -> Leasing and Marketing | J24: =Budget!D18 -> 0.030549721 | K24: =Budget!E18 -> 4052164.4 | L24: =Budget!F18 -> 19.504064 | M24: =Budget!G18 -> 31.366026
B25: Revenue/Operating Assumptions | I25: =Budget!B19 -> G&A | J25: =Budget!D19 -> 0.019276019 | K25: =Budget!E19 -> 2556802.3 | L25: =Budget!F19 -> 12.306519 | M25: =Budget!G19 -> 19.791085
B26: Office Tenant Lease Assumptions | I26: =Budget!B20 -> Contingency | J26: =Budget!D20 -> 0.021828663 | K26: =Budget!E20 -> 2895389.1 | L26: =Budget!F20 -> 13.93622 | M26: =Budget!G20 -> 22.411937
B27: Month Start | F27: =C21 -> 39 | G27: =INDEX(MonthlyCF!$J$10:$BR$10,MATCH(Summary!F27,MonthlyCF!$J$9:$BR$9,0)) -> 44652 | I27: =Budget!B21 -> Financing Costs | J27: =K27/$K$16 -> 0 | K27: =Budget!E21 -> 0 | L27: =Budget!F21 -> 0 | M27: =Budget!G21 -> 0
B28: Month Expire | F28: =+F27+(10*12) -> 159 | G28: =EDATE(G27,F28-F27-1) -> 48274
B29: Rent/SF | G29: 65 | I29: Area Summary
B30: Ann. Base Rent Increase (%) | G30: 0.0275 | I30: =Area!B9 -> Lot Size | M30: =Area!C9 -> 26000
B31: Reimb. % | G31: 1 | I31: =Area!B10 -> FAR | M31: =Area!C10 -> 7.9907692
B32: Free Rent (Months) | G32: 3 | I32: =Area!B11 -> GSF | M32: =Area!C11 -> 207760
B33: TIs/SF | G33: 65 | I33: =Area!B12 -> RSF | M33: =Area!C12 -> 129189.6
B34: TIs Total | G34: =+G33*M33 -> 8397324 | I34: =Area!B13 -> Office | M34: =Area!C13 -> 111689.6
B35: LC (% of entire lease) | G35: 0.035 | I35: =Area!B14 -> MEP | M35: =Area!C14 -> 9500
B36: LC/SF | G36: =G37/M33 -> 28.366026 | I36: =Area!B15 -> Amenity | M36: =Area!C15 -> 8000
B37: LC Total | G37: =SUMIF(OpProj!J16:EK16,"<="&Summary!$F$28,OpProj!$J$17:$EK$17)*G35 -> 3664595.6 | I37: =Area!B16 -> Efficiency Ratio - (Total Building) | M37: =Area!C16 -> 0.62182133
B38: Parking | I38: =Area!B18 -> Parking Stalls | M38: =Area!C18 -> 100
B39: Stalls | G39: =Area!C18 -> 100
B40: Revenue/Month | G40: 225 | I40: Financing Assumptions
B41: Ann. Increase (%) | G41: 0.02 | I41: Total Project Costs Pre-Interest Reserve | M41: =MonthlyCF!C38 -> 1.3264161e+08
B42: Exit Assumptions | I42: Total Project Costs
B43: Exit Cap Rate | G43: 0.05 | I43: LTC Control
B44: Exit Price | G44: =OpProj!H29 -> 1.9218773e+08 | I44: LTC with Interest Reserve
B45: Cost of Sales | F45: 0.03 | G45: =G44*F45 -> 5765631.8 | I45: Equity | M45: =M41*(1-M43) -> 1.3264161e+08
B46: Net Proceeds | G46: =G44-G45 -> 1.864221e+08 | I46: Debt Pre-Interest Reserve
...

Sheet Area
B6: Area
B8: Summary
B9: Lot Size | C9: 26000
B10: FAR | C10: =C11/C9 -> 7.9907692
B11: GSF | C11: =SUM(C22:C30) -> 207760
B12: RSF | C12: =SUM(D22:D30) -> 129189.6
B13: Office | C13: =SUM(E22:E30) -> 111689.6
B14: MEP | C14: =SUM(F22:F30) -> 9500
B15: Amenity | C15: =SUM(G22:G30) -> 8000
B16: Efficiency Ratio - (Total Building) | C16: =SUM(D22:D30)/SUM(C22:C30) -> 0.62182133
B17: Efficiency Ratio - (Excluding Below Grade) | C17: =SUM(D22:D28)/SUM(C22:C28) -> 0.78442142
B18: Parking Stalls | C18: 100
B20: Stacking Plan
B21: Level | C21: GSF | D21: RSF | E21: Office RSF | F21: MEP RSF | G21: Amenity RSF | H21: Parking | I21: Efficiency (%) | J21: Notes
B22: Roof | C22: 10000 | D22: =SUM(E22:G22) -> 8500 | F22: 4500 | G22: 4000 | I22: =SUM(F22:G22)/C22 -> 0.85
B23: 6 | C23: 24720 | D23: =SUM(E23:G23) -> 19281.6 | E23: =C23*I23 -> 19281.6 | I23: 0.78
B24: 5 | C24: 24720 | D24: =SUM(E24:G24) -> 19281.6 | E24: =C24*I24 -> 19281.6 | I24: 0.78
B25: 4 | C25: 24720 | D25: =SUM(E25:G25) -> 19281.6 | E25: =C25*I25 -> 19281.6 | I25: 0.78
B26: 3 | C26: 24720 | D26: =SUM(E26:G26) -> 19281.6 | E26: =C26*I26 -> 19281.6 | I26: 0.78
B27: 2 | C27: 24720 | D27: =SUM(E27:G27) -> 19281.6 | E27: =C27*I27 -> 19281.6 | I27: 0.78
B28: 1 | C28: 24720 | D28: =SUM(E28:G28) -> 19281.6 | E28: =C28*I28-G28 -> 15281.6 | G28: 4000 | I28: 0.78
B29: B1 | C29: 24720 | D29: =SUM(E29:G29) -> 5000 | F29: 5000 | H29: 14000
B30: B2 | C30: 24720 | D30: =SUM(E30:G30) -> 0 | H30: 19110

Sheet Budget
B6: Budget
B8: Budget Summary
D9: % | E9: Total | F9: Per GSF | G9: Per RSF
B10: Total | D10: =E10/$E$10 -> 1 | E10: =SUM(E11:E21) -> 1.3264161e+08 | F10: =SUM(F11:F21) -> 638.43673 | G10: =SUM(G11:G21) -> 1026.7205
B11: Land | D11: =E11/$E$10 -> 0.23127321 | E11: =E28 -> 30676452 | F11: =F28 -> 147.65331 | G11: =G28 -> 237.45295
B12: Entitlement Costs | D12: =E12/$E$10 -> 0.0022918901 | E12: =E33 -> 304000 | F12: =F33 -> 1.4632268 | G12: =G33 -> 2.3531306
B13: A&E | D13: =E13/$E$10 -> 0.016446422 | E13: =E37 -> 2181480 | F13: =F37 -> 10.5 | G13: =G37 -> 16.885879
B14: Construction | D14: =E14/$E$10 -> 0.58737223 | E14: =E41 -> 77910000 | F14: =F41 -> 375 | G14: =G41 -> 603.06712
B15: =B45 -> Tenant Improvements | D15: =E15/$E$10 -> 0.063308367 | E15: =E45 -> 8397324 | F15: =F45 -> 40.418387 | G15: =G45 -> 65
B16: Permits | D16: =E16/$E$10 -> 0.0058737223 | E16: =E47 -> 779100 | F16: =F47 -> 3.75 | G16: =G47 -> 6.0306712
B17: Taxes | D17: =E17/$E$10 -> 0.021779758 | E17: =E49 -> 2888902.2 | F17: =F49 -> 13.904997 | G17: =G49 -> 22.361724
B18: Leasing and Marketing | D18: =E18/$E$10 -> 0.030549721 | E18: =E51 -> 4052164.4 | F18: =F51 -> 19.504064 | G18: =G51 -> 31.366026
B19: G&A | D19: =E19/$E$10 -> 0.019276019 | E19: =E56 -> 2556802.3 | F19: =F56 -> 12.306519 | G19: =G56 -> 19.791085
B20: Contingency | D20: =E20/$E$10 -> 0.021828663 | E20: =E59 -> 2895389.1 | F20: =F59 -> 13.93622 | G20: =G59 -> 22.411937
B21: Financing Costs | D21: =E21/$E$10 -> 0 | E21: =E62 -> 0 | F21: =F62 -> 0 | G21: =G62 -> 0
B23: Budget Summary
F24: =Area!C11 -> 207760 | G24: =Area!C12 -> 129189.6
C25: Inputs | D25: % | E25: Total | F25: Per GSF | G25: Per RSF
B28: Land | D28: =E28/$E$10 -> 0.23127321 | E28: =SUM(E29:E31) -> 30676452 | F28: =SUM(F29:F31) -> 147.65331 | G28: =SUM(G29:G31) -> 237.45295
B29: Sale Price | D29: =E29/$E$10 -> 0.22711726 | E29: =F29*F24 -> 30125200 | F29: 145 | G29: =E29/G$24 -> 233.18595
B30: Transfer Taxes | C30: 0.01 | D30: =E30/$E$10 -> 0.0022711726 | E30: =E29*$C$30 -> 301252 | F30: =E30/F$24 -> 1.45 | G30: =E30/G$24 -> 2.3318595
B31: Other Closing costs | D31: =E31/$E$10 -> 0.001884778 | E31: 250000 | F31: =E31/F$24 -> 1.2033115 | G31: =E31/G$24 -> 1.9351403
B33: Entitlement Costs | D33: =E33/$E$10 -> 0.0022918901 | E33: =SUM(E34:E35) -> 304000 | F33: =SUM(F34:F35) -> 1.4632268 | G33: =SUM(G34:G35) -> 2.3531306
B34: Application Fees | D34: =E34/$E$10 -> 0.001145945 | E34: 152000 | F34: =E34/F$24 -> 0.7316134 | G34: =E34/G$24 -> 1.1765653
B35: Legal Fees | D35: =E35/$E$10 -> 0.001145945 | E35: 152000 | F35: =E35/F$24 -> 0.7316134 | G35: =E35/G$24 -> 1.1765653
B37: A&E | C37: 0.035 | D37: =E37/$E$10 -> 0.016446422 | E37: =F37*F24 -> 2181480 | F37: =F42*C37 -> 10.5 | G37: =E37/G$24 -> 16.885879
B38: Design | C38: 0.8 | D38: =E38/$E$10 -> 0.013157138 | E38: =$C38*E$37 -> 1745184 | F38: =$C38*F$37 -> 8.4 | G38: =$C38*G$37 -> 13.508703
B39: Construction Monitoring | C39: =1-C38 -> 0.2 | D39: =E39/$E$10 -> 0.0032892845 | E39: =$C39*E$37 -> 436296 | F39: =$C39*F$37 -> 2.1 | G39: =$C39*G$37 -> 3.3771759
B41: Construction | D41: =E41/$E$10 -> 0.58737223 | E41: =SUM(E42:E43) -> 77910000 | F41: =SUM(F42:F43) -> 375 | G41: =SUM(G42:G43) -> 603.06712
B42: Hard Costs | D42: =E42/$E$10 -> 0.46989778 | E42: =F42*F24 -> 62328000 | F42: 300 | G42: =E42/G$24 -> 482.4537
B43: Soft Costs | C43: 0.25 | D43: =E43/$E$10 -> 0.11747445 | E43: =E$42*$C$43 -> 15582000 | F43: =F$42*$C$43 -> 75 | G43: =G$42*$C$43 -> 120.61342
B45: Tenant Improvements | D45: =E45/$E$10 -> 0.063308367 | E45: =G45*$G$24 -> 8397324 | F45: =E45/F$24 -> 40.418387 | G45: =Summary!G33 -> 65
B47: Permits & City Fees | C47: 0.0125 | D47: =E47/$E$10 -> 0.0058737223 | E47: =E42*$C$47 -> 779100 | F47: =F42*$C$47 -> 3.75 | G47: =G42*$C$47 -> 6.0306712 | I47: typical permits and when they are paid for
B49: Taxes | C49: 0.016 | D49: =E49/$E$10 -> 0.021779758 | E49: =MonthlyCF!C29 -> 2888902.2 | F49: =$E$49/F24 -> 13.904997 | G49: =$E$49/G24 -> 22.361724
B51: Leasing and Marketing | D51: =E51/$E$10 -> 0.030549721 | E51: =SUM(E52:E53) -> 4052164.4 | F51: =SUM(F52:F53) -> 19.504064 | G51: =SUM(G52:G53) -> 31.366026
B52: Leasing Commissions | D52: =E52/$E$10 -> 0.027627797 | E52: =G52*G24 -> 3664595.6 | F52: =E52/F$24 -> 17.6386 | G52: =Summary!G36 -> 28.366026
B53: Marketing | C53: 3 | D53: =E53/$E$10 -> 0.0029219246 | E53: =G53*G24 -> 387568.8 | F53: =E53/F$24 -> 1.865464 | G53: =C53 -> 3
B55: G&A
B56: Development Fee | C56: 0.03 | D56: =E56/$E$10 -> 0.019276019 | E56: =C56*SUM(E12:E14,E16,E18) -> 2556802.3 | F56: =$E56/F$24 -> 12.306519 | G56: =$E$56/G$24 -> 19.791085
C57: exc. Land, Taxes, TIs
...

Sheet MonthlyCF
B6: Monthly Cash Flow
B8: Fiscal Year | J8: 0 | K8: =ROUNDUP(K9/12,0) -> 1 | L8: =ROUNDUP(L9/12,0) -> 1 | M8: =ROUNDUP(M9/12,0) -> 1 | N8: =ROUNDUP(N9/12,0) -> 1 | O8: =ROUNDUP(O9/12,0) -> 1 | P8: =ROUNDUP(P9/12,0) -> 1 | Q8: =ROUNDUP(Q9/12,0) -> 1 | R8: =ROUNDUP(R9/12,0) -> 1 | ... BR8: =ROUNDUP(BR9/12,0) -> 5
B9: Fiscal Month | H9: Standard Deviation | J9: 0 | K9: =+J9+1 -> 1 | L9: =+K9+1 -> 2 | M9: =+L9+1 -> 3 | N9: =+M9+1 -> 4 | O9: =+N9+1 -> 5 | P9: =+O9+1 -> 6 | Q9: =+P9+1 -> 7 | R9: =+Q9+1 -> 8 | ... BR9: =+BQ9+1 -> 60
B10: Date | C10: Budget | D10: Growth Projection Method | E10: Start Month | F10: End Month | G10: Duration | I10: Check | J10: =EDATE(Summary!F15,-1) -> 43466 | K10: =EDATE(J10,1) -> 43497 | L10: =EDATE(K10,1) -> 43525 | M10: =EDATE(L10,1) -> 43556 | N10: =EDATE(M10,1) -> 43586 | O10: =EDATE(N10,1) -> 43617 | P10: =EDATE(O10,1) -> 43647 | Q10: =EDATE(P10,1) -> 43678 | R10: =EDATE(Q10,1) -> 43709 | ... BR10: =EDATE(BQ10,1) -> 45292
B11: Line Items
B13: Land | C13: =INDEX(Budget!$E$28:$E$59,MATCH(MonthlyCF!B13,Budget!$B$28:$B$59,0)) -> 30676452 | I13: =IF(ROUND(SUM($J13:$BR13),0)=ROUND(C13,0),"OK","error") -> OK | J13: =C13 -> 30676452
B15: =Budget!B33 -> Entitlement Costs
B16: =Budget!B34 -> Application Fees | C16: =INDEX(Budget!$E$28:$E$59,MATCH(MonthlyCF!B16,Budget!$B$28:$B$59,0)) -> 152000 | D16: Custom | E16: =Summary!C17 -> 2 | F16: =E16 -> 2 | G16: =F16-E16+1 -> 1 | I16: =IF(ROUND(SUM($J16:$BR16),0)=ROUND(C16,0),"OK","error") -> OK | K16: =(K9=$E$16)*$C$16 -> 0 | L16: =(L9=$E$16)*$C$16 -> 152000 | M16: =(M9=$E$16)*$C$16 -> 0 | N16: =(N9=$E$16)*$C$16 -> 0 | O16: =(O9=$E$16)*$C$16 -> 0 | P16: =(P9=$E$16)*$C$16 -> 0 | Q16: =(Q9=$E$16)*$C$16 -> 0 | R16: =(R9=$E$16)*$C$16 -> 0 | ... BR16: =(BR9=$E$16)*$C$16 -> 0
B17: =Budget!B35 -> Legal Fees | C17: =INDEX(Budget!$E$28:$E$59,MATCH(MonthlyCF!B17,Budget!$B$28:$B$59,0)) -> 152000 | D17: Steady Growth Formula | E17: =Summary!C17 -> 2 | F17: =Summary!E17 -> 10 | G17: =F17-E17+1 -> 9 | I17: =IF(ROUND(SUM($J17:$BR17),0)=ROUND(C17,0),"OK","error") -> OK | K17: =AND(K$9>=$E17,K$9<=$F17)*(K$9-$E17+1)/($G17*($G17+1)/2)*$C17 -> 0 | L17: =AND(L$9>=$E17,L$9<=$F17)*(L$9-$E17+1)/($G17*($G17+1)/2)*$C17 -> 3377.7778 | M17: =AND(M$9>=$E17,M$9<=$F17)*(M$9-$E17+1)/($G17*($G17+1)/2)*$C17 -> 6755.5556 | N17: =AND(N$9>=$E17,N$9<=$F17)*(N$9-$E17+1)/($G17*($G17+1)/2)*$C17 -> 10133.333 | O17: =AND(O$9>=$E17,O$9<=$F17)*(O$9-$E17+1)/($G17*($G17+1)/2)*$C17 -> 13511.111 | P17: =AND(P$9>=$E17,P$9<=$F17)*(P$9-$E17+1)/($G17*($G17+1)/2)*$C17 -> 16888.889 | Q17: =AND(Q$9>=$E17,Q$9<=$F17)*(Q$9-$E17+1)/($G17*($G17+1)/2)*$C17 -> 20266.667 | R17: =AND(R$9>=$E17,R$9<=$F17)*(R$9-$E17+1)/($G17*($G17+1)/2)*$C17 -> 23644.444 | ... BR17: =AND(BR$9>=$E17,BR$9<=$F17)*(BR$9-$E17+1)/($G17*($G17+1)/2)*$C17 -> 0
B19: =Budget!B37 -> A&E
B20: =Budget!B38 -> Design | C20: =INDEX(Budget!$E$28:$E$59,MATCH(MonthlyCF!B20,Budget!$B$28:$B$59,0)) -> 1745184 | D20: S-Curve - SD of 5 | E20: =Summary!C18 -> 2 | F20: =Summary!E18 -> 16 | G20: =F20-E20+1 -> 15 | H20: 5 | I20: =IF(ROUND(SUM($J20:$BR20),0)=ROUND(C20,0),"OK","error") -> OK | K20: =(_xlfn.NORM.DIST(AND(K$9>=$E20,K$9<=$F20)*(K$9-$E20+1),$G20/2,$H20,TRUE)-_xlfn.NORM.DIST(AND(K$9>=$E20,K$9<=$F20)*(J$9-$E20+1),$G20/2,$H20,TRUE))/(1-2*_xlfn.NORM.DIST(0,$G20/2,$H20,TRUE))*$C20 -> 0 | L20: =(_xlfn.NORM.DIST(AND(L$9>=$E20,L$9<=$F20)*(L$9-$E20+1),$G20/2,$H20,TRUE)-_xlfn.NORM.DIST(AND(L$9>=$E20,L$9<=$F20)*(K$9-$E20+1),$G20/2,$H20,TRUE))/(1-2*_xlfn.NORM.DIST(0,$G20/2,$H20,TRUE))*$C20 -> 60416.284 | M20: =(_xlfn.NORM.DIST(AND(M$9>=$E20,M$9<=$F20)*(M$9-$E20+1),$G20/2,$H20,TRUE)-_xlfn.NORM.DIST(AND(M$9>=$E20,M$9<=$F20)*(L$9-$E20+1),$G20/2,$H20,TRUE))/(1-2*_xlfn.NORM.DIST(0,$G20/2,$H20,TRUE))*$C20 -> 78287.984 | N20: =(_xlfn.NORM.DIST(AND(N$9>=$E20,N$9<=$F20)*(N$9-$E20+1),$G20/2,$H20,TRUE)-_xlfn.NORM.DIST(AND(N$9>=$E20,N$9<=$F20)*(M$9-$E20+1),$G20/2,$H20,TRUE))/(1-2*_xlfn.NORM.DIST(0,$G20/2,$H20,TRUE))*$C20 -> 97481.476 | O20: =(_xlfn.NORM.DIST(AND(O$9>=$E20,O$9<=$F20)*(O$9-$E20+1),$G20/2,$H20,TRUE)-_xlfn.NORM.DIST(AND(O$9>=$E20,O$9<=$F20)*(N$9-$E20+1),$G20/2,$H20,TRUE))/(1-2*_xlfn.NORM.DIST(0,$G20/2,$H20,TRUE))*$C20 -> 116636.64 | P20: =(_xlfn.NORM.DIST(AND(P$9>=$E20,P$9<=$F20)*(P$9-$E20+1),$G20/2,$H20,TRUE)-_xlfn.NORM.DIST(AND(P$9>=$E20,P$9<=$F20)*(O$9-$E20+1),$G20/2,$H20,TRUE))/(1-2*_xlfn.NORM.DIST(0,$G20/2,$H20,TRUE))*$C20 -> 134101.58 | Q20: =(_xlfn.NORM.DIST(AND(Q$9>=$E20,Q$9<=$F20)*(Q$9-$E20+1),$G20/2,$H20,TRUE)-_xlfn.NORM.DIST(AND(Q$9>=$E20,Q$9<=$F20)*(P$9-$E20+1),$G20/2,$H20,TRUE))/(1-2*_xlfn.NORM.DIST(0,$G20/2,$H20,TRUE))*$C20 -> 148155.85 | R20: =(_xlfn.NORM.DIST(AND(R$9>=$E20,R$9<=$F20)*(R$9-$E20+1),$G20/2,$H20,TRUE)-_xlfn.NORM.DIST(AND(R$9>=$E20,R$9<=$F20)*(Q$9-$E20+1),$G20/2,$H20,TRUE))/(1-2*_xlfn.NORM.DIST(0,$G20/2,$H20,TRUE))*$C20 -> 157285.88 | ... BR20: =(_xlfn.NORM.DIST(AND(BR$9>=$E20,BR$9<=$F20)*(BR$9-$E20+1),$G20/2,$H20,TRUE)-_xlfn.NORM.DIST(AND(BR$9>=$E20,BR$9<=$F20)*(BQ$9-$E20+1),$G20/2,$H20,TRUE))/(1-2*_xlfn.NORM.DIST(0,$G20/2,$H20,TRUE))*$C20 -> 0
B21: =Budget!B39 -> Construction Monitoring | C21: =INDEX(Budget!$E$28:$E$59,MATCH(MonthlyCF!B21,Budget!$B$28:$B$59,0)) -> 436296 | D21: Straight Line | E21: =Summary!$C$19 -> 16 | F21: =Summary!$E$19 -> 39 | G21: =F21-E21+1 -> 24 | H21: 10000000 | I21: =IF(ROUND(SUM($J21:$BR21),0)=ROUND(C21,0),"OK","error") -> OK | K21: =(_xlfn.NORM.DIST(AND(K$9>=$E21,K$9<=$F21)*(K$9-$E21+1),$G21/2,$H21,TRUE)-_xlfn.NORM.DIST(AND(K$9>=$E21,K$9<=$F21)*(J$9-$E21+1),$G21/2,$H21,TRUE))/(1-2*_xlfn.NORM.DIST(0,$G21/2,$H21,TRUE))*$C21 -> 0 | L21: =(_xlfn.NORM.DIST(AND(L$9>=$E21,L$9<=$F21)*(L$9-$E21+1),$G21/2,$H21,TRUE)-_xlfn.NORM.DIST(AND(L$9>=$E21,L$9<=$F21)*(K$9-$E21+1),$G21/2,$H21,TRUE))/(1-2*_xlfn.NORM.DIST(0,$G21/2,$H21,TRUE))*$C21 -> 0 | M21: =(_xlfn.NORM.DIST(AND(M$9>=$E21,M$9<=$F21)*(M$9-$E21+1),$G21/2,$H21,TRUE)-_xlfn.NORM.DIST(AND(M$9>=$E21,M$9<=$F21)*(L$9-$E21+1),$G21/2,$H21,TRUE))/(1-2*_xlfn.NORM.DIST(0,$G21/2,$H21,TRUE))*$C21 -> 0 | N21: =(_xlfn.NORM.DIST(AND(N$9>=$E21,N$9<=$F21)*(N$9-$E21+1),$G21/2,$H21,TRUE)-_xlfn.NORM.DIST(AND(N$9>=$E21,N$9<=$F21)*(M$9-$E21+1),$G21/2,$H21,TRUE))/(1-2*_xlfn.NORM.DIST(0,$G21/2,$H21,TRUE))*$C21 -> 0 | O21: =(_xlfn.NORM.DIST(AND(O$9>=$E21,O$9<=$F21)*(O$9-$E21+1),$G21/2,$H21,TRUE)-_xlfn.NORM.DIST(AND(O$9>=$E21,O$9<=$F21)*(N$9-$E21+1),$G21/2,$H21,TRUE))/(1-2*_xlfn.NORM.DIST(0,$G21/2,$H21,TRUE))*$C21 -> 0 | P21: =(_xlfn.NORM.DIST(AND(P$9>=$E21,P$9<=$F21)*(P$9-$E21+1),$G21/2,$H21,TRUE)-_xlfn.NORM.DIST(AND(P$9>=$E21,P$9<=$F21)*(O$9-$E21+1),$G21/2,$H21,TRUE))/(1-2*_xlfn.NORM.DIST(0,$G21/2,$H21,TRUE))*$C21 -> 0 | Q21: =(_xlfn.NORM.DIST(AND(Q$9>=$E21,Q$9<=$F21)*(Q$9-$E21+1),$G21/2,$H21,TRUE)-_xlfn.NORM.DIST(AND(Q$9>=$E21,Q$9<=$F21)*(P$9-$E21+1),$G21/2,$H21,TRUE))/(1-2*_xlfn.NORM.DIST(0,$G21/2,$H21,TRUE))*$C21 -> 0 | R21: =(_xlfn.NORM.DIST(AND(R$9>=$E21,R$9<=$F21)*(R$9-$E21+1),$G21/2,$H21,TRUE)-_xlfn.NORM.DIST(AND(R$9>=$E21,R$9<=$F21)*(Q$9-$E21+1),$G21/2,$H21,TRUE))/(1-2*_xlfn.NORM.DIST(0,$G21/2,$H21,TRUE))*$C21 -> 0 | ... BR21: =(_xlfn.NORM.DIST(AND(BR$9>=$E21,BR$9<=$F21)*(BR$9-$E21+1),$G21/2,$H21,TRUE)-_xlfn.NORM.DIST(AND(BR$9>=$E21,BR$9<=$F21)*(BQ$9-$E21+1),$G21/2,$H21,TRUE))/(1-2*_xlfn.NORM.DIST(0,$G21/2,$H21,TRUE))*$C21 -> 0
B23: =Budget!B41 -> Construction | C23: =INDEX(Budget!$E$28:$E$59,MATCH(MonthlyCF!B23,Budget!$B$28:$B$59,0)) -> 77910000 | D23: S-Curve - SD of 4 | E23: =Summary!$C$19 -> 16 | F23: =Summary!$E$19 -> 39 | G23: =F23-E23+1 -> 24 | H23: 4 | I23: =IF(ROUND(SUM($J23:$BR23),0)=ROUND(C23,0),"OK","error") -> OK | K23: =(_xlfn.NORM.DIST(AND(K$9>=$E23,K$9<=$F23)*(K$9-$E23+1),$G23/2,$H23,TRUE)-_xlfn.NORM.DIST(AND(K$9>=$E23,K$9<=$F23)*(J$9-$E23+1),$G23/2,$H23,TRUE))/(1-2*_xlfn.NORM.DIST(0,$G23/2,$H23,TRUE))*$C23 -> 0 | L23: =(_xlfn.NORM.DIST(AND(L$9>=$E23,L$9<=$F23)*(L$9-$E23+1),$G23/2,$H23,TRUE)-_xlfn.NORM.DIST(AND(L$9>=$E23,L$9<=$F23)*(K$9-$E23+1),$G23/2,$H23,TRUE))/(1-2*_xlfn.NORM.DIST(0,$G23/2,$H23,TRUE))*$C23 -> 0 | M23: =(_xlfn.NORM.DIST(AND(M$9>=$E23,M$9<=$F23)*(M$9-$E23+1),$G23/2,$H23,TRUE)-_xlfn.NORM.DIST(AND(M$9>=$E23,M$9<=$F23)*(L$9-$E23+1),$G23/2,$H23,TRUE))/(1-2*_xlfn.NORM.DIST(0,$G23/2,$H23,TRUE))*$C23 -> 0 | N23: =(_xlfn.NORM.DIST(AND(N$9>=$E23,N$9<=$F23)*(N$9-$E23+1),$G23/2,$H23,TRUE)-_xlfn.NORM.DIST(AND(N$9>=$E23,N$9<=$F23)*(M$9-$E23+1),$G23/2,$H23,TRUE))/(1-2*_xlfn.NORM.DIST(0,$G23/2,$H23,TRUE))*$C23 -> 0 | O23: =(_xlfn.NORM.DIST(AND(O$9>=$E23,O$9<=$F23)*(O$9-$E23+1),$G23/2,$H23,TRUE)-_xlfn.NORM.DIST(AND(O$9>=$E23,O$9<=$F23)*(N$9-$E23+1),$G23/2,$H23,TRUE))/(1-2*_xlfn.NORM.DIST(0,$G23/2,$H23,TRUE))*$C23 -> 0 | P23: =(_xlfn.NORM.DIST(AND(P$9>=$E23,P$9<=$F23)*(P$9-$E23+1),$G23/2,$H23,TRUE)-_xlfn.NORM.DIST(AND(P$9>=$E23,P$9<=$F23)*(O$9-$E23+1),$G23/2,$H23,TRUE))/(1-2*_xlfn.NORM.DIST(0,$G23/2,$H23,TRUE))*$C23 -> 0 | Q23: =(_xlfn.NORM.DIST(AND(Q$9>=$E23,Q$9<=$F23)*(Q$9-$E23+1),$G23/2,$H23,TRUE)-_xlfn.NORM.DIST(AND(Q$9>=$E23,Q$9<=$F23)*(P$9-$E23+1),$G23/2,$H23,TRUE))/(1-2*_xlfn.NORM.DIST(0,$G23/2,$H23,TRUE))*$C23 -> 0 | R23: =(_xlfn.NORM.DIST(AND(R$9>=$E23,R$9<=$F23)*(R$9-$E23+1),$G23/2,$H23,TRUE)-_xlfn.NORM.DIST(AND(R$9>=$E23,R$9<=$F23)*(Q$9-$E23+1),$G23/2,$H23,TRUE))/(1-2*_xlfn.NORM.DIST(0,$G23/2,$H23,TRUE))*$C23 -> 0 | ... BR23: =(_xlfn.NORM.DIST(AND(BR$9>=$E23,BR$9<=$F23)*(BR$9-$E23+1),$G23/2,$H23,TRUE)-_xlfn.NORM.DIST(AND(BR$9>=$E23,BR$9<=$F23)*(BQ$9-$E23+1),$G23/2,$H23,TRUE))/(1-2*_xlfn.NORM.DIST(0,$G23/2,$H23,TRUE))*$C23 -> 0
B25: =Budget!B45 -> Tenant Improvements | C25: =INDEX(Budget!$E$28:$E$59,MATCH(MonthlyCF!B25,Budget!$B$28:$B$59,0)) -> 8397324 | D25: Start of Lease | E25: =Summary!F27 -> 39 | I25: =IF(ROUND(SUM($J25:$BR25),0)=ROUND(C25,0),"OK","error") -> OK | K25: =(K$9=$E25)*$C25 -> 0 | L25: =(L$9=$E25)*$C25 -> 0 | M25: =(M$9=$E25)*$C25 -> 0 | N25: =(N$9=$E25)*$C25 -> 0 | O25: =(O$9=$E25)*$C25 -> 0 | P25: =(P$9=$E25)*$C25 -> 0 | Q25: =(Q$9=$E25)*$C25 -> 0 | R25: =(R$9=$E25)*$C25 -> 0 | ... BR25: =(BR$9=$E25)*$C25 -> 0
B27: =Budget!B47 -> Permits & City Fees | C27: =INDEX(Budget!$E$28:$E$59,MATCH(MonthlyCF!B27,Budget!$B$28:$B$59,0)) -> 779100 | D27: Custom | E27: =Summary!D17+1 -> 10 | F27: =E27+5 -> 15 | I27: =IF(ROUND(SUM($J27:$BR27),0)=ROUND(C27,0),"OK","error") -> OK | K27: =(K9=$E$27)*$C$27*$E$28+(K9=$F$27)*$C$27*$F$28 -> 0 | L27: =(L9=$E$27)*$C$27*$E$28+(L9=$F$27)*$C$27*$F$28 -> 0 | M27: =(M9=$E$27)*$C$27*$E$28+(M9=$F$27)*$C$27*$F$28 -> 0 | N27: =(N9=$E$27)*$C$27*$E$28+(N9=$F$27)*$C$27*$F$28 -> 0 | O27: =(O9=$E$27)*$C$27*$E$28+(O9=$F$27)*$C$27*$F$28 -> 0 | P27: =(P9=$E$27)*$C$27*$E$28+(P9=$F$27)*$C$27*$F$28 -> 0 | Q27: =(Q9=$E$27)*$C$27*$E$28+(Q9=$F$27)*$C$27*$F$28 -> 0 | R27: =(R9=$E$27)*$C$27*$E$28+(R9=$F$27)*$C$27*$F$28 -> 0 | ... BR27: =(BR9=$E$27)*$C$27*$E$28+(BR9=$F$27)*$C$27*$F$28 -> 0
E28: 0.6 | F28: =1-E28 -> 0.4
B29: =Budget!B49 -> Taxes | C29: =SUM(K29:BR29) -> 2888902.2 | D29: Custom | E29: =Budget!C49 -> 0.016 | I29: =IF(ROUND(SUM($J29:$BR29),0)=ROUND(C29,0),"OK","error") -> OK | K29: =AND(MONTH(K10)=1,K9<=Summary!$E$22)*SUM($J$23:J23,$J$13:J13)*$E$29 -> 0 | L29: =AND(MONTH(L10)=1,L9<=Summary!$E$22)*SUM($J$23:K23,$J$13:K13)*$E$29 -> 0 | M29: =AND(MONTH(M10)=1,M9<=Summary!$E$22)*SUM($J$23:L23,$J$13:L13)*$E$29 -> 0 | N29: =AND(MONTH(N10)=1,N9<=Summary!$E$22)*SUM($J$23:M23,$J$13:M13)*$E$29 -> 0 | O29: =AND(MONTH(O10)=1,O9<=Summary!$E$22)*SUM($J$23:N23,$J$13:N13)*$E$29 -> 0 | P29: =AND(MONTH(P10)=1,P9<=Summary!$E$22)*SUM($J$23:O23,$J$13:O13)*$E$29 -> 0 | Q29: =AND(MONTH(Q10)=1,Q9<=Summary!$E$22)*SUM($J$23:P23,$J$13:P13)*$E$29 -> 0 | R29: =AND(MONTH(R10)=1,R9<=Summary!$E$22)*SUM($J$23:Q23,$J$13:Q13)*$E$29 -> 0 | ... BR29: =AND(MONTH(BR10)=1,BR9<=Summary!$E$22)*SUM($J$23:BQ23,$J$13:BQ13)*$E$29 -> 0
E30: Every January multiply (land plus construction costs paid up until the previous month (December)) times the 1.6% Mill Rate
B31: =Budget!B51 -> Leasing and Marketing
B32: =Budget!B52 -> Leasing Commissions | C32: =INDEX(Budget!$E$28:$E$59,MATCH(MonthlyCF!B32,Budget!$B$28:$B$59,0)) -> 3664595.6 | D32: Start of Lease | E32: =E25 -> 39 | I32: =IF(ROUND(SUM($J32:$BR32),0)=ROUND(C32,0),"OK","error") -> OK | K32: =(K$9=$E32)*$C32 -> 0 | L32: =(L$9=$E32)*$C32 -> 0 | M32: =(M$9=$E32)*$C32 -> 0 | N32: =(N$9=$E32)*$C32 -> 0 | O32: =(O$9=$E32)*$C32 -> 0 | P32: =(P$9=$E32)*$C32 -> 0 | Q32: =(Q$9=$E32)*$C32 -> 0 | R32: =(R$9=$E32)*$C32 -> 0 | ... BR32: =(BR$9=$E32)*$C32 -> 0
B33: =Budget!B53 -> Marketing | C33: =INDEX(Budget!$E$28:$E$59,MATCH(MonthlyCF!B33,Budget!$B$28:$B$59,0)) -> 387568.8 | D33: Straight Line | E33: =Summary!$C$19 -> 16 | F33: 25 | G33: =F33-E33+1 -> 10 | H33: 10000000 | I33: =IF(ROUND(SUM($J33:$BR33),0)=ROUND(C33,0),"OK","error") -> OK | K33: =(_xlfn.NORM.DIST(AND(K$9>=$E33,K$9<=$F33)*(K$9-$E33+1),$G33/2,$H33,TRUE)-_xlfn.NORM.DIST(AND(K$9>=$E33,K$9<=$F33)*(J$9-$E33+1),$G33/2,$H33,TRUE))/(1-2*_xlfn.NORM.DIST(0,$G33/2,$H33,TRUE))*$C33 -> 0 | L33: =(_xlfn.NORM.DIST(AND(L$9>=$E33,L$9<=$F33)*(L$9-$E33+1),$G33/2,$H33,TRUE)-_xlfn.NORM.DIST(AND(L$9>=$E33,L$9<=$F33)*(K$9-$E33+1),$G33/2,$H33,TRUE))/(1-2*_xlfn.NORM.DIST(0,$G33/2,$H33,TRUE))*$C33 -> 0 | M33: =(_xlfn.NORM.DIST(AND(M$9>=$E33,M$9<=$F33)*(M$9-$E33+1),$G33/2,$H33,TRUE)-_xlfn.NORM.DIST(AND(M$9>=$E33,M$9<=$F33)*(L$9-$E33+1),$G33/2,$H33,TRUE))/(1-2*_xlfn.NORM.DIST(0,$G33/2,$H33,TRUE))*$C33 -> 0 | N33: =(_xlfn.NORM.DIST(AND(N$9>=$E33,N$9<=$F33)*(N$9-$E33+1),$G33/2,$H33,TRUE)-_xlfn.NORM.DIST(AND(N$9>=$E33,N$9<=$F33)*(M$9-$E33+1),$G33/2,$H33,TRUE))/(1-2*_xlfn.NORM.DIST(0,$G33/2,$H33,TRUE))*$C33 -> 0 | O33: =(_xlfn.NORM.DIST(AND(O$9>=$E33,O$9<=$F33)*(O$9-$E33+1),$G33/2,$H33,TRUE)-_xlfn.NORM.DIST(AND(O$9>=$E33,O$9<=$F33)*(N$9-$E33+1),$G33/2,$H33,TRUE))/(1-2*_xlfn.NORM.DIST(0,$G33/2,$H33,TRUE))*$C33 -> 0 | P33: =(_xlfn.NORM.DIST(AND(P$9>=$E33,P$9<=$F33)*(P$9-$E33+1),$G33/2,$H33,TRUE)-_xlfn.NORM.DIST(AND(P$9>=$E33,P$9<=$F33)*(O$9-$E33+1),$G33/2,$H33,TRUE))/(1-2*_xlfn.NORM.DIST(0,$G33/2,$H33,TRUE))*$C33 -> 0 | Q33: =(_xlfn.NORM.DIST(AND(Q$9>=$E33,Q$9<=$F33)*(Q$9-$E33+1),$G33/2,$H33,TRUE)-_xlfn.NORM.DIST(AND(Q$9>=$E33,Q$9<=$F33)*(P$9-$E33+1),$G33/2,$H33,TRUE))/(1-2*_xlfn.NORM.DIST(0,$G33/2,$H33,TRUE))*$C33 -> 0 | R33: =(_xlfn.NORM.DIST(AND(R$9>=$E33,R$9<=$F33)*(R$9-$E33+1),$G33/2,$H33,TRUE)-_xlfn.NORM.DIST(AND(R$9>=$E33,R$9<=$F33)*(Q$9-$E33+1),$G33/2,$H33,TRUE))/(1-2*_xlfn.NORM.DIST(0,$G33/2,$H33,TRUE))*$C33 -> 0 | ... BR33: =(_xlfn.NORM.DIST(AND(BR$9>=$E33,BR$9<=$F33)*(BR$9-$E33+1),$G33/2,$H33,TRUE)-_xlfn.NORM.DIST(AND(BR$9>=$E33,BR$9<=$F33)*(BQ$9-$E33+1),$G33/2,$H33,TRUE))/(1-2*_xlfn.NORM.DIST(0,$G33/2,$H33,TRUE))*$C33 -> 0
B35: =Budget!B56 -> Development Fee | C35: =INDEX(Budget!$E$28:$E$59,MATCH(MonthlyCF!B35,Budget!$B$28:$B$59,0)) -> 2556802.3 | D35: Straight Line | E35: =Summary!C15 -> 1 | F35: =Summary!E19 -> 39 | G35: =F35-E35+1 -> 39 | H35: 10000000 | I35: =IF(ROUND(SUM($J35:$BR35),0)=ROUND(C35,0),"OK","error") -> OK | K35: =(_xlfn.NORM.DIST(AND(K$9>=$E35,K$9<=$F35)*(K$9-$E35+1),$G35/2,$H35,TRUE)-_xlfn.NORM.DIST(AND(K$9>=$E35,K$9<=$F35)*(J$9-$E35+1),$G35/2,$H35,TRUE))/(1-2*_xlfn.NORM.DIST(0,$G35/2,$H35,TRUE))*$C35 -> 65559.034 | L35: =(_xlfn.NORM.DIST(AND(L$9>=$E35,L$9<=$F35)*(L$9-$E35+1),$G35/2,$H35,TRUE)-_xlfn.NORM.DIST(AND(L$9>=$E35,L$9<=$F35)*(K$9-$E35+1),$G35/2,$H35,TRUE))/(1-2*_xlfn.NORM.DIST(0,$G35/2,$H35,TRUE))*$C35 -> 65559.034 | M35: =(_xlfn.NORM.DIST(AND(M$9>=$E35,M$9<=$F35)*(M$9-$E35+1),$G35/2,$H35,TRUE)-_xlfn.NORM.DIST(AND(M$9>=$E35,M$9<=$F35)*(L$9-$E35+1),$G35/2,$H35,TRUE))/(1-2*_xlfn.NORM.DIST(0,$G35/2,$H35,TRUE))*$C35 -> 65559.034 | N35: =(_xlfn.NORM.DIST(AND(N$9>=$E35,N$9<=$F35)*(N$9-$E35+1),$G35/2,$H35,TRUE)-_xlfn.NORM.DIST(AND(N$9>=$E35,N$9<=$F35)*(M$9-$E35+1),$G35/2,$H35,TRUE))/(1-2*_xlfn.NORM.DIST(0,$G35/2,$H35,TRUE))*$C35 -> 65559.034 | O35: =(_xlfn.NORM.DIST(AND(O$9>=$E35,O$9<=$F35)*(O$9-$E35+1),$G35/2,$H35,TRUE)-_xlfn.NORM.DIST(AND(O$9>=$E35,O$9<=$F35)*(N$9-$E35+1),$G35/2,$H35,TRUE))/(1-2*_xlfn.NORM.DIST(0,$G35/2,$H35,TRUE))*$C35 -> 65559.034 | P35: =(_xlfn.NORM.DIST(AND(P$9>=$E35,P$9<=$F35)*(P$9-$E35+1),$G35/2,$H35,TRUE)-_xlfn.NORM.DIST(AND(P$9>=$E35,P$9<=$F35)*(O$9-$E35+1),$G35/2,$H35,TRUE))/(1-2*_xlfn.NORM.DIST(0,$G35/2,$H35,TRUE))*$C35 -> 65559.034 | Q35: =(_xlfn.NORM.DIST(AND(Q$9>=$E35,Q$9<=$F35)*(Q$9-$E35+1),$G35/2,$H35,TRUE)-_xlfn.NORM.DIST(AND(Q$9>=$E35,Q$9<=$F35)*(P$9-$E35+1),$G35/2,$H35,TRUE))/(1-2*_xlfn.NORM.DIST(0,$G35/2,$H35,TRUE))*$C35 -> 65559.034 | R35: =(_xlfn.NORM.DIST(AND(R$9>=$E35,R$9<=$F35)*(R$9-$E35+1),$G35/2,$H35,TRUE)-_xlfn.NORM.DIST(AND(R$9>=$E35,R$9<=$F35)*(Q$9-$E35+1),$G35/2,$H35,TRUE))/(1-2*_xlfn.NORM.DIST(0,$G35/2,$H35,TRUE))*$C35 -> 65559.034 | ... BR35: =(_xlfn.NORM.DIST(AND(BR$9>=$E35,BR$9<=$F35)*(BR$9-$E35+1),$G35/2,$H35,TRUE)-_xlfn.NORM.DIST(AND(BR$9>=$E35,BR$9<=$F35)*(BQ$9-$E35+1),$G35/2,$H35,TRUE))/(1-2*_xlfn.NORM.DIST(0,$G35/2,$H35,TRUE))*$C35 -> 0
B37: =Budget!B59 -> Contingency | C37: =INDEX(Budget!$E$28:$E$59,MATCH(MonthlyCF!B37,Budget!$B$28:$B$59,0)) -> 2895389.1 | D37: Steady Growth Formula | E37: 30 | F37: =F35 -> 39 | G37: =F37-E37+1 -> 10 | I37: =IF(ROUND(SUM($J37:$BR37),0)=ROUND(C37,0),"OK","error") -> OK | K37: =AND(K$9>=$E37,K$9<=$F37)*(K$9-$E37+1)/($G37*($G37+1)/2)*$C37 -> 0 | L37: =AND(L$9>=$E37,L$9<=$F37)*(L$9-$E37+1)/($G37*($G37+1)/2)*$C37 -> 0 | M37: =AND(M$9>=$E37,M$9<=$F37)*(M$9-$E37+1)/($G37*($G37+1)/2)*$C37 -> 0 | N37: =AND(N$9>=$E37,N$9<=$F37)*(N$9-$E37+1)/($G37*($G37+1)/2)*$C37 -> 0 | O37: =AND(O$9>=$E37,O$9<=$F37)*(O$9-$E37+1)/($G37*($G37+1)/2)*$C37 -> 0 | P37: =AND(P$9>=$E37,P$9<=$F37)*(P$9-$E37+1)/($G37*($G37+1)/2)*$C37 -> 0 | Q37: =AND(Q$9>=$E37,Q$9<=$F37)*(Q$9-$E37+1)/($G37*($G37+1)/2)*$C37 -> 0 | R37: =AND(R$9>=$E37,R$9<=$F37)*(R$9-$E37+1)/($G37*($G37+1)/2)*$C37 -> 0 | ... BR37: =AND(BR$9>=$E37,BR$9<=$F37)*(BR$9-$E37+1)/($G37*($G37+1)/2)*$C37 -> 0
B38: Total Development Costs - Pre-Financing | C38: =SUM(J38:BR38) -> 1.3264161e+08 | I38: =IF(ROUND(SUM($J38:$BR38),0)=ROUND(C38,0),"OK","error") -> OK | J38: =SUM(J13:J37) -> 30676452 | K38: =SUM(K13:K37) -> 65559.034 | L38: =SUM(L13:L37) -> 281353.1 | M38: =SUM(M13:M37) -> 150602.57 | N38: =SUM(N13:N37) -> 173173.84 | O38: =SUM(O13:O37) -> 195706.79 | P38: =SUM(P13:P37) -> 216549.51 | Q38: =SUM(Q13:Q37) -> 233981.55 | ... BR38: =SUM(BR13:BR37) -> 0
B39: Fees
B40: Interest Reserve
B41: Total Development Costs - W/ Interest Reserve and Fees | J41: =SUM(J38:J40) -> 30676452 | K41: =SUM(K38:K40) -> 65559.034 | L41: =SUM(L38:L40) -> 281353.1 | M41: =SUM(M38:M40) -> 150602.57 | N41: =SUM(N38:N40) -> 173173.84 | O41: =SUM(O38:O40) -> 195706.79 | P41: =SUM(P38:P40) -> 216549.51 | Q41: =SUM(Q38:Q40) -> 233981.55 | ... BR41: =SUM(BR38:BR40) -> 0
B43: Draw Schedule
B44: Total Construction costs Pre-Interest Reserve & Fees
B45: Fees
B46: Interest Reserve
B47: Total Construction Costs including Interest Reserve & Fees
B49: Equity
C50: Beginning Balance | J50: =Summary!M45 -> 1.3264161e+08 | K50: =J52 -> 1.0196516e+08 | L50: =K52 -> 1.018996e+08 | M50: =L52 -> 1.0161825e+08 | N50: =M52 -> 1.0146765e+08 | O50: =N52 -> 1.0129447e+08 | P50: =O52 -> 1.0109877e+08 | Q50: =P52 -> 1.0088222e+08 | R50: =Q52 -> 1.0064824e+08 | ... BR50: =BQ52 -> 0
C51: Equity Required | J51: =MIN(J50,J41) -> 30676452 | K51: =MIN(K50,K41) -> 65559.034 | L51: =MIN(L50,L41) -> 281353.1 | M51: =MIN(M50,M41) -> 150602.57 | N51: =MIN(N50,N41) -> 173173.84 | O51: =MIN(O50,O41) -> 195706.79 | P51: =MIN(P50,P41) -> 216549.51 | Q51: =MIN(Q50,Q41) -> 233981.55 | ... BR51: =MIN(BR50,BR41) -> 0
C52: Ending Balance | J52: =J50-J51 -> 1.0196516e+08 | K52: =K50-K51 -> 1.018996e+08 | L52: =L50-L51 -> 1.0161825e+08 | M52: =M50-M51 -> 1.0146765e+08 | N52: =N50-N51 -> 1.0129447e+08 | O52: =O50-O51 -> 1.0109877e+08 | P52: =P50-P51 -> 1.0088222e+08 | Q52: =Q50-Q51 -> 1.0064824e+08 | ... BR52: =BR50-BR51 -> 0
C53: Cumulative Costs | J53: =SUM($J$51:J51) -> 30676452 | K53: =SUM($J$51:K51) -> 30742011 | L53: =SUM($J$51:L51) -> 31023364 | M53: =SUM($J$51:M51) -> 31173967 | N53: =SUM($J$51:N51) -> 31347141 | O53: =SUM($J$51:O51) -> 31542847 | P53: =SUM($J$51:P51) -> 31759397 | Q53: =SUM($J$51:Q51) -> 31993378 | ... BR53: =SUM($J$51:BR51) -> 1.3264161e+08
B54: Debt
B55: Debt Pre-Interest Reserve | C55: Beginning Balance
C56: Debt Funded
...

Sheet OpProj
B6: Operating Projections
C9: MODELING LONG-TERM LEASES
C11: INCOME
C12: Parking Growth | E12: =Summary!G41 -> 0.02 | J12: =ROUNDUP(J13/12,0) -> 1 | K12: =ROUNDUP(K13/12,0) -> 1 | L12: =ROUNDUP(L13/12,0) -> 1 | M12: =ROUNDUP(M13/12,0) -> 1 | N12: =ROUNDUP(N13/12,0) -> 1 | O12: =ROUNDUP(O13/12,0) -> 1 | P12: =ROUNDUP(P13/12,0) -> 1 | Q12: =ROUNDUP(Q13/12,0) -> 1 | ... EK12: =ROUNDUP(EK13/12,0) -> 11
C13: OpEx Growth | E13: 0.02 | J13: 1 | K13: =+J13+1 -> 2 | L13: =+K13+1 -> 3 | M13: =+L13+1 -> 4 | N13: =+M13+1 -> 5 | O13: =+N13+1 -> 6 | P13: =+O13+1 -> 7 | Q13: =+P13+1 -> 8 | R13: =+Q13+1 -> 9 | ... EK13: =+EJ13+1 -> 132
J14: =Summary!F21 -> 44652 | K14: =EDATE(J14,1) -> 44682 | L14: =EDATE(K14,1) -> 44713 | M14: =EDATE(L14,1) -> 44743 | N14: =EDATE(M14,1) -> 44774 | O14: =EDATE(N14,1) -> 44805 | P14: =EDATE(O14,1) -> 44835 | Q14: =EDATE(P14,1) -> 44866 | R14: =EDATE(Q14,1) -> 44896 | ... EK14: =EDATE(EJ14,1) -> 48639
J15: =ROUNDUP(J16/12,0) -> 4 | K15: =ROUNDUP(K16/12,0) -> 4 | L15: =ROUNDUP(L16/12,0) -> 4 | M15: =ROUNDUP(M16/12,0) -> 4 | N15: =ROUNDUP(N16/12,0) -> 4 | O15: =ROUNDUP(O16/12,0) -> 4 | P15: =ROUNDUP(P16/12,0) -> 4 | Q15: =ROUNDUP(Q16/12,0) -> 4 | ... EK15: =ROUNDUP(EK16/12,0) -> 15
H16: Pro Forma | J16: =INDEX(MonthlyCF!$J$9:$BR$9,MATCH(OpProj!J14,MonthlyCF!$J$10:$BR$10,0)) -> 39 | K16: =J16+1 -> 40 | L16: =K16+1 -> 41 | M16: =L16+1 -> 42 | N16: =M16+1 -> 43 | O16: =N16+1 -> 44 | P16: =O16+1 -> 45 | Q16: =P16+1 -> 46 | R16: =Q16+1 -> 47 | ... EK16: =EJ16+1 -> 170
C17: Potential Base Rent | H17: =SUM(J17:U17) -> 9151080.4 | J17: =(Summary!$G$29*Summary!$M$33)/12*(1+Summary!$G$30)^(OpProj!J15-1) -> 759110.77 | K17: =(Summary!$G$29*Summary!$M$33)/12*(1+Summary!$G$30)^(OpProj!K15-1) -> 759110.77 | L17: =(Summary!$G$29*Summary!$M$33)/12*(1+Summary!$G$30)^(OpProj!L15-1) -> 759110.77 | M17: =(Summary!$G$29*Summary!$M$33)/12*(1+Summary!$G$30)^(OpProj!M15-1) -> 759110.77 | N17: =(Summary!$G$29*Summary!$M$33)/12*(1+Summary!$G$30)^(OpProj!N15-1) -> 759110.77 | O17: =(Summary!$G$29*Summary!$M$33)/12*(1+Summary!$G$30)^(OpProj!O15-1) -> 759110.77 | P17: =(Summary!$G$29*Summary!$M$33)/12*(1+Summary!$G$30)^(OpProj!P15-1) -> 759110.77 | Q17: =(Summary!$G$29*Summary!$M$33)/12*(1+Summary!$G$30)^(OpProj!Q15-1) -> 759110.77 | ... EK17: =(Summary!$G$29*Summary!$M$33)/12*(1+Summary!$G$30)^(OpProj!EK15-1) -> 1023069.9
C18: - Concessions | H18: =SUM(J18:M18) -> -2277332.3 | J18: =(J16<Summary!$G$32+Summary!$F$27)*-OpProj!J17 -> -759110.77 | K18: =(K16<Summary!$G$32+Summary!$F$27)*-OpProj!K17 -> -759110.77 | L18: =(L16<Summary!$G$32+Summary!$F$27)*-OpProj!L17 -> -759110.77 | M18: =(M16<Summary!$G$32+Summary!$F$27)*-OpProj!M17 -> 0 | N18: =(N16<Summary!$G$32+Summary!$F$27)*-OpProj!N17 -> 0 | O18: =(O16<Summary!$G$32+Summary!$F$27)*-OpProj!O17 -> 0 | P18: =(P16<Summary!$G$32+Summary!$F$27)*-OpProj!P17 -> 0 | Q18: =(Q16<Summary!$G$32+Summary!$F$27)*-OpProj!Q17 -> 0 | ... EK18: =(EK16<Summary!$G$32+Summary!$F$27)*-OpProj!EK17 -> 0
C19: Total Rental Revenue | H19: =SUM(H17:H18) -> 6873748.1 | J19: =SUM(J17:J18) -> 0 | K19: =SUM(K17:K18) -> 0 | L19: =SUM(L17:L18) -> 0 | M19: =SUM(M17:M18) -> 759110.77 | N19: =SUM(N17:N18) -> 759110.77 | O19: =SUM(O17:O18) -> 759110.77 | P19: =SUM(P17:P18) -> 759110.77 | Q19: =SUM(Q17:Q18) -> 759110.77 | ... EK19: =SUM(EK17:EK18) -> 1023069.9
C20: Reimbursement Income | G20: 1 | H20: =+G20*H26 -> 1895502.3 | J20: =J26*$G$20 -> 157433.74 | K20: =K26*$G$20 -> 157433.74 | L20: =L26*$G$20 -> 157433.74 | M20: =M26*$G$20 -> 157433.74 | N20: =N26*$G$20 -> 157433.74 | O20: =O26*$G$20 -> 157433.74 | P20: =P26*$G$20 -> 157433.74 | Q20: =Q26*$G$20 -> 157433.74 | ... EK20: =EK26*$G$20 -> 195749.07
C21: Parking Income | H21: =SUM(J21:U21) -> 287481.25 | J21: =(Summary!$G$39*Summary!$G$40*12)/12*(1+$E$12)^(J$15-1) -> 23877.18 | K21: =(Summary!$G$39*Summary!$G$40*12)/12*(1+$E$12)^(K$15-1) -> 23877.18 | L21: =(Summary!$G$39*Summary!$G$40*12)/12*(1+$E$12)^(L$15-1) -> 23877.18 | M21: =(Summary!$G$39*Summary!$G$40*12)/12*(1+$E$12)^(M$15-1) -> 23877.18 | N21: =(Summary!$G$39*Summary!$G$40*12)/12*(1+$E$12)^(N$15-1) -> 23877.18 | O21: =(Summary!$G$39*Summary!$G$40*12)/12*(1+$E$12)^(O$15-1) -> 23877.18 | P21: =(Summary!$G$39*Summary!$G$40*12)/12*(1+$E$12)^(P$15-1) -> 23877.18 | Q21: =(Summary!$G$39*Summary!$G$40*12)/12*(1+$E$12)^(Q$15-1) -> 23877.18 | ... EK21: =(Summary!$G$39*Summary!$G$40*12)/12*(1+$E$12)^(EK$15-1) -> 29688.272
C22: Gross Revenue | H22: =SUM(H19:H21) -> 9056731.6 | J22: =SUM(J19:J21) -> 181310.92 | K22: =SUM(K19:K21) -> 181310.92 | L22: =SUM(L19:L21) -> 181310.92 | M22: =SUM(M19:M21) -> 940421.7 | N22: =SUM(N19:N21) -> 940421.7 | O22: =SUM(O19:O21) -> 940421.7 | P22: =SUM(P19:P21) -> 940421.7 | Q22: =SUM(Q19:Q21) -> 940421.7 | ... EK22: =SUM(EK19:EK21) -> 1248507.2
C23: - General Vacancy and Credit Loss | G23: 0 | H23: =+-G23*H22 -> 0 | J23: =-$G$23*J22 -> 0 | K23: =-$G$23*K22 -> 0 | L23: =-$G$23*L22 -> 0 | M23: =-$G$23*M22 -> 0 | N23: =-$G$23*N22 -> 0 | O23: =-$G$23*O22 -> 0 | P23: =-$G$23*P22 -> 0 | Q23: =-$G$23*Q22 -> 0 | ... EK23: =-$G$23*EK22 -> 0
C24: Total Effective Gross Revenue | H24: =SUM(H22:H23) -> 9056731.6 | J24: =SUM(J22:J23) -> 181310.92 | K24: =SUM(K22:K23) -> 181310.92 | L24: =SUM(L22:L23) -> 181310.92 | M24: =SUM(M22:M23) -> 940421.7 | N24: =SUM(N22:N23) -> 940421.7 | O24: =SUM(O22:O23) -> 940421.7 | P24: =SUM(P22:P23) -> 940421.7 | Q24: =SUM(Q22:Q23) -> 940421.7 | ... EK24: =SUM(EK22:EK23) -> 1248507.2
C26: Operating Expenses | G26: 1780240 | H26: =SUM(J26:U26) -> 1895502.3 | J26: =$G$26/12*(1+$E$13)^(J$15-1) -> 157433.74 | K26: =$G$26/12*(1+$E$13)^(K$15-1) -> 157433.74 | L26: =$G$26/12*(1+$E$13)^(L$15-1) -> 157433.74 | M26: =$G$26/12*(1+$E$13)^(M$15-1) -> 157433.74 | N26: =$G$26/12*(1+$E$13)^(N$15-1) -> 157433.74 | O26: =$G$26/12*(1+$E$13)^(O$15-1) -> 157433.74 | P26: =$G$26/12*(1+$E$13)^(P$15-1) -> 157433.74 | Q26: =$G$26/12*(1+$E$13)^(Q$15-1) -> 157433.74 | ... EK26: =$G$26/12*(1+$E$13)^(EK$15-1) -> 195749.07
C27: Net Operating Income | H27: =H24-H26 -> 7161229.3 | J27: =+J24-J26 -> 23877.18 | K27: =+K24-K26 -> 23877.18 | L27: =+L24-L26 -> 23877.18 | M27: =+M24-M26 -> 782987.95 | N27: =+N24-N26 -> 782987.95 | O27: =+O24-O26 -> 782987.95 | P27: =+P24-P26 -> 782987.95 | Q27: =+Q24-Q26 -> 782987.95 | ... EK27: =+EK24-EK26 -> 1052758.1
C29: Sale Price | H29: =SUM(J29:EK29) -> 1.9218773e+08 | J29: =(J16=Summary!$C$22)*SUM(OpProj!J27:U27)/Summary!$G$43 -> 0 | K29: =(K16=Summary!$C$22)*SUM(OpProj!K27:V27)/Summary!$G$43 -> 0 | L29: =(L16=Summary!$C$22)*SUM(OpProj!L27:W27)/Summary!$G$43 -> 0 | M29: =(M16=Summary!$C$22)*SUM(OpProj!M27:X27)/Summary!$G$43 -> 0 | N29: =(N16=Summary!$C$22)*SUM(OpProj!N27:Y27)/Summary!$G$43 -> 0 | O29: =(O16=Summary!$C$22)*SUM(OpProj!O27:Z27)/Summary!$G$43 -> 0 | P29: =(P16=Summary!$C$22)*SUM(OpProj!P27:AA27)/Summary!$G$43 -> 0 | Q29: =(Q16=Summary!$C$22)*SUM(OpProj!Q27:AB27)/Summary!$G$43 -> 0 | ... EK29: =(EK16=Summary!$C$22)*SUM(OpProj!EK27:EV27)/Summary!$G$43 -> 0
C31: [Note: Leasing Commissions and Tenant Improvements are part of the development budget and so we are accounting for that there.]
